Workbook

Sheet ENERO
A4: Establecimiento de Salud informante: | B4: HOSPITAL REGIONAL DE LORETO | K4: Mes: | L4: ENERO
A6: Código Renaes: | B6: 3 | K6: Año: | L6: 2026
A9: PATOLOGÍA CLÍNICA | B9: TOTAL | J9: ANATOMÍA PATOLÓGICA | K9: TOTAL
B10: Hospitaliz | C10: Emergenc | D10: C. Externa | E10: Privado | F10: Convenio | G10: Insolvencia | H10: TOTAL | K10: Hospitaliz | L10: Emergenc | M10: C. Externa | N10: Privado | O10: Convenio | P10: Insolvencia | Q10: TOTAL
A11: TOTAL DE EXAMENES LABORATORIO | B11: =B12+B51+B69+B82+B95+K11+K28+K41 -> 15321 | C11: =C12+C51+C69+C82+C95+L11+L28+L41 -> 16807 | D11: =D12+D51+D69+D82+D95+M11+M28+M41 -> 15534 | E11: =E12+E51+E69+E82+E95+N11+N28+N41 -> 627 | F11: =F12+F51+F69+F82+F95+O11+O28+O41 -> 500 | G11: =G12+G51+G69+G82+G95+P11+P28+P41 -> 34 | H11: =SUM(B11:G11) -> 48823 | J11: TOTAL EXAMENES ANATOMIA PATOLOGICA | K11: =SUM(K12:K23) -> 994 | L11: =SUM(L12:L23) -> 0 | M11: =SUM(M12:M23) -> 976 | N11: =SUM(N12:N23) -> 1 | O11: =SUM(O12:O23) -> 1 | P11: =SUM(P12:P23) -> 0 | Q11: =SUM(K11:P11) -> 1972
A12: TOTAL EXAMENES BIOQUÍMICOS | B12: =SUM(B13:B50) -> 9011 | C12: =SUM(C13:C50) -> 9489 | D12: =SUM(D13:D50) -> 8246 | E12: =SUM(E13:E50) -> 416 | F12: =SUM(F13:F50) -> 329 | G12: =SUM(G13:G50) -> 20 | H12: =SUM(B12:G12) -> 27511 | J12: TOTAL EXAMENES CITOLÓGICOS (PAP) | K12: 0 | L12: 0 | M12: 18 | N12: 1 | O12: 0 | P12: 0 | Q12: =SUM(K12:P12) -> 19
A13: ACIDO URICO | B13: 17 | C13: 2 | D13: 109 | E13: 1 | F13: 8 | G13: 0 | H13: =SUM(B13:G13) -> 137 | J13: TOTAL BAAF | K13: 1 | L13: 0 | M13: 8 | N13: 0 | O13: 0 | P13: 0 | Q13: =SUM(K13:P13) -> 9
A14: CALCIO | B14: 30 | C14: 1 | D14: 39 | E14: 1 | F14: 0 | G14: 0 | H14: =SUM(B14:G14) -> 71 | J14: TOTAL EXAMENES HISTOPATOLÓGICOS (Biopsia) | K14: 15 | L14: 0 | M14: 127 | N14: 0 | O14: 1 | P14: 0 | Q14: =SUM(K14:P14) -> 143
A15: AMILASA | B15: 35 | C15: 131 | D15: 27 | E15: 2 | F15: 0 | G15: 0 | H15: =SUM(B15:G15) -> 195 | J15: TOTAL PIEZA QUIRURGICA (HISTOLOGIA) | K15: 71 | L15: 0 | M15: 16 | N15: 0 | O15: 0 | P15: 0 | Q15: =SUM(K15:P15) -> 87
A16: GLUCOSA | B16: 944 | C16: 1644 | D16: 1005 | E16: 82 | F16: 35 | G16: 5 | H16: =SUM(B16:G16) -> 3715 | J16: TOTAL CITOLOGIA ESPECIAL | K16: 5 | L16: 0 | M16: 3 | N16: 0 | O16: 0 | P16: 0 | Q16: =SUM(K16:P16) -> 8
A17: GLUCOSA POST PRANDIAL | B17: 0 | C17: 0 | D17: 45 | E17: 0 | F17: 3 | G17: 0 | H17: =SUM(B17:G17) -> 48 | J17: TOTAL DE TEJIDOS INCLUIDOS | K17: 300 | L17: 0 | M17: 268 | N17: 0 | O17: 0 | P17: 0 | Q17: =SUM(K17:P17) -> 568
A18: FOSFORO | B18: 9 | C18: 0 | D18: 9 | E18: 0 | F18: 0 | G18: 0 | H18: =SUM(B18:G18) -> 18 | J18: TOTAL DE CORTES DE TEJIDOS | K18: 300 | L18: 0 | M18: 268 | N18: 0 | O18: 0 | P18: 0 | Q18: =SUM(K18:P18) -> 568
A19: HEMOGLOBINA GLICOSILADA | B19: 59 | C19: 15 | D19: 192 | E19: 13 | F19: 10 | G19: 0 | H19: =SUM(B19:G19) -> 289 | J19: TOTAL DE LÁMINAS MONTADAS | K19: 300 | L19: 0 | M19: 268 | N19: 0 | O19: 0 | P19: 0 | Q19: =SUM(K19:P19) -> 568
A20: TOLERANCIA A LA GLUCOSA | B20: 5 | C20: 0 | D20: 40 | F20: 1 | G20: 0 | H20: =SUM(B20:G20) -> 46 | J20: TOTAL DE HISTOQUIMICA | K20: 2 | L20: 0 | M20: 0 | N20: 0 | O20: 0 | P20: 0 | Q20: =SUM(K20:P20) -> 2
A21: CREATININA | B21: 836 | C21: 1242 | D21: 803 | E21: 55 | F21: 33 | G21: 0 | H21: =SUM(B21:G21) -> 2969 | J21: TOTAL DE INMUNOHISTOQUIMICA | K21: 0 | L21: 0 | M21: 0 | N21: 0 | O21: 0 | P21: 0 | Q21: =SUM(K21:P21) -> 0
A22: DEPURACION DE CREATININA | B22: 3 | C22: 0 | D22: 9 | E22: 0 | F22: 0 | G22: 0 | H22: =SUM(B22:G22) -> 12 | J22: TOTAL AUTOPSIA MÉDICO LEGAL | K22: 0 | L22: 0 | M22: 0 | N22: 0 | O22: 0 | P22: 0 | Q22: =SUM(K22:P22) -> 0
A23: MICROALBUMINURIA | B23: 1 | C23: 0 | D23: 14 | E23: 0 | F23: 0 | G23: 0 | H23: =SUM(B23:G23) -> 15 | J23: TOTAL AUTOPSIA CLÍNICA | K23: 0 | L23: 0 | M23: 0 | N23: 0 | O23: 0 | P23: 0 | Q23: =SUM(K23:P23) -> 0
A24: UREA | B24: 850 | C24: 1318 | D24: 892 | E24: 62 | F24: 32 | G24: 1 | H24: =SUM(B24:G24) -> 3155
A25: PROTEINURIA 24 HORAS | B25: 21 | C25: 0 | D25: 50 | E25: 3 | F25: 2 | G25: 0 | H25: =SUM(B25:G25) -> 76
A26: BILIRRUBINA TOTAL | B26: 773 | C26: 524 | D26: 422 | E26: 4 | F26: 13 | G26: 0 | H26: =SUM(B26:G26) -> 1736 | J26: PROGRAMAS / METAXENICAS | K26: TOTAL
A27: BILIRRUBINA DIRECTA | B27: 648 | C27: 318 | D27: 472 | E27: 4 | F27: 13 | G27: 1 | H27: =SUM(B27:G27) -> 1456 | K27: Hospitaliz | L27: Emergenc | M27: C. Externa | N27: Privado | O27: Convenio | P27: Insolvencia | Q27: TOTAL
A28: PROTEINAS TOTAL | B28: 537 | C28: 321 | D28: 446 | E28: 15 | F28: 21 | G28: 0 | H28: =SUM(B28:G28) -> 1340 | J28: TOTAL DE EXAMENES | K28: =SUM(K29:K37) -> 66 | L28: =SUM(L29:L37) -> 209 | M28: =SUM(M29:M37) -> 130 | N28: =SUM(N29:N37) -> 0 | O28: =SUM(O29:O37) -> 0 | P28: =SUM(P29:P37) -> 0 | Q28: =SUM(K28:P28) -> 405
A29: ALBUMINA | B29: 653 | C29: 340 | D29: 529 | E29: 5 | F29: 21 | G29: 1 | H29: =SUM(B29:G29) -> 1549 | J29: TUBERCULOSIS | K29: 33 | L29: 0 | M29: 70 | N29: 0 | O29: 0 | P29: 0 | Q29: =SUM(K29:P29) -> 103
A30: TGO | B30: 772 | C30: 774 | D30: 689 | E30: 25 | F30: 24 | G30: 1 | H30: =SUM(B30:G30) -> 2285 | J30: LEISHMANIA | K30: 0 | L30: 0 | N30: 0 | O30: 0 | P30: 0 | Q30: =SUM(K30:P30) -> 0
A31: TGP | B31: 761 | C31: 722 | D31: 686 | E31: 26 | F31: 24 | G31: 1 | H31: =SUM(B31:G31) -> 2220 | J31: PROGRAMA LEPRAE | K31: 0 | L31: 0 | M31: 6 | N31: 0 | O31: 0 | P31: 0 | Q31: =SUM(K31:P31) -> 6
A32: GGTP | B32: 111 | C32: 0 | D32: 16 | E32: 1 | F32: 0 | G32: 0 | H32: =SUM(B32:G32) -> 128 | J32: MALARIA | K32: 29 | L32: 185 | M32: 6 | N32: 0 | O32: 0 | P32: 0 | Q32: =SUM(K32:P32) -> 220
A33: LACTATO DESHIDROGENASA (DHL) | B33: 259 | C33: 186 | D33: 52 | E33: 2 | F33: 3 | G33: 1 | H33: =SUM(B33:G33) -> 503 | J33: METAXENICAS (REFERENCIAL) | K33: 0 | L33: 0 | M33: 26 | N33: 0 | O33: 0 | P33: 0 | Q33: =SUM(K33:P33) -> 26
A34: PROTEINA C REACTIVA (CUANTITATIVO) | B34: 96 | C34: 82 | D34: 82 | E34: 3 | F34: 2 | G34: 0 | H34: =SUM(B34:G34) -> 265 | J34: CULTIVO DE TB (REFERENCIAL) | K34: 0 | L34: 0 | M34: 22 | N34: 0 | O34: 0 | P34: 0 | Q34: =SUM(K34:P34) -> 22
A35: FOSFATASA ALCALINA | B35: 619 | C35: 458 | D35: 466 | E35: 14 | F35: 11 | G35: 1 | H35: =SUM(B35:G35) -> 1569 | J35: PRUEBA RAPIDA DE DENGUE | K35: 0 | L35: 12 | M35: 0 | N35: 0 | O35: 0 | P35: 0 | Q35: =SUM(K35:P35) -> 12
A36: CPK TOTAL | B36: 0 | C36: 0 | D36: 0 | E36: 0 | F36: 0 | G36: 0 | H36: =SUM(B36:G36) -> 0 | J36: PRUEBA RÁPIDA DE LEPTOSPIRA | K36: 4 | L36: 12 | M36: 0 | N36: 0 | O36: 0 | P36: 0 | Q36: =SUM(K36:P36) -> 16
A37: CPK MB | B37: 13 | C37: 19 | D37: 0 | E37: 0 | F37: 0 | G37: 0 | H37: =SUM(B37:G37) -> 32 | J37: PRUEBA RAPIDA DE COVID + INFLUENZA | K37: 0 | L37: 0 | M37: 0 | N37: 0 | O37: 0 | P37: 0 | Q37: =SUM(K37:P37) -> 0
A38: COLESTEROL | B38: 95 | C38: 6 | D38: 360 | E38: 26 | F38: 22 | G38: 4 | H38: =SUM(B38:G38) -> 513
A39: TRIGLICERIDOS | B39: 96 | C39: 6 | D39: 371 | E39: 29 | F39: 22 | G39: 4 | H39: =SUM(B39:G39) -> 528 | J39: BANCO DE SANGRE | K39: TOTAL
A40: HDLc | B40: 22 | C40: 2 | D40: 177 | E40: 2 | F40: 11 | G40: 0 | H40: =SUM(B40:G40) -> 214 | K40: Hospitaliz | L40: Emergenc | M40: C. Externa | N40: Privado | O40: Convenio | P40: Insolvencia | Q40: TOTAL
A41: LDLc | B41: 10 | C41: 0 | D41: 80 | E41: 0 | F41: 11 | G41: 0 | H41: =SUM(B41:G41) -> 101 | J41: TOTAL DE UNIDADES ENTREGADAS | K41: =SUM(K42:K49) -> 649 | L41: =SUM(L42:L49) -> 291 | M41: =SUM(M42:M49) -> 2 | N41: =SUM(N42:N49) -> 0 | O41: =SUM(O42:O49) -> 0 | P41: =SUM(P42:P49) -> 0 | Q41: =SUM(K41:P41) -> 942
A42: ASO | B42: 0 | C42: 0 | D42: 2 | E42: 1 | F42: 0 | G42: 0 | H42: =SUM(B42:G42) -> 3 | J42: SANGRE TOTAL | K42: 0 | L42: 0 | M42: 0 | N42: 0 | O42: 0 | P42: 0 | Q42: =SUM(K42:P42) -> 0
A43: FACTOR REUMATOIDEO | B43: 7 | C43: 1 | D43: 25 | E43: 0 | F43: 1 | G43: 0 | H43: =SUM(B43:G43) -> 34 | J43: GLOBULOS ROJOS | K43: 168 | L43: 76 | M43: 1 | N43: 0 | O43: 0 | P43: 0 | Q43: =SUM(K43:P43) -> 245
A44: HIERRO | B44: 18 | C44: 0 | D44: 0 | E44: 15 | F44: 0 | G44: 0 | H44: =SUM(B44:G44) -> 33 | J44: PLASMA FRESCO CONGELADO | K44: 12 | L44: 15 | M44: 0 | N44: 0 | O44: 0 | P44: 0 | Q44: =SUM(K44:P44) -> 27
A45: LIPASA | B45: 0 | C45: 6 | D45: 0 | E45: 0 | F45: 0 | G45: 0 | H45: =SUM(B45:G45) -> 6 | J45: CRIOPRECIPITADO | K45: 8 | L45: 4 | M45: 0 | N45: 0 | O45: 0 | P45: 0 | Q45: =SUM(K45:P45) -> 12
A46: TRANSFERRINA | B46: 10 | C46: 0 | D46: 7 | E46: 0 | F46: 0 | G46: 0 | H46: =SUM(B46:G46) -> 17 | J46: PLAQUETAS | K46: 28 | L46: 13 | M46: 0 | N46: 0 | O46: 0 | P46: 0 | Q46: =SUM(K46:P46) -> 41
...

Sheet FEBRERO
A4: Establecimiento de Salud informante: | B4: HOSPITAL REGIONAL DE LORETO | K4: Mes: | L4: FEBRERO
A6: Código Renaes: | B6: 3 | K6: Año: | L6: 2026
A9: PATOLOGÍA CLÍNICA | B9: TOTAL | J9: ANATOMÍA PATOLÓGICA | K9: TOTAL
B10: Hospitaliz | C10: Emergenc | D10: C. Externa | E10: Privado | F10: Convenio | G10: Insolvencia | H10: TOTAL | K10: Hospitaliz | L10: Emergenc | M10: C. Externa | N10: Privado | O10: Convenio | P10: Insolvencia | Q10: TOTAL
A11: TOTAL DE EXAMENES LABORATORIO | B11: =B12+B51+B69+B82+B95+K11+K28+K41 -> 9423 | C11: =C12+C51+C69+C82+C95+L11+L28+L41 -> 13700 | D11: =D12+D51+D69+D82+D95+M11+M28+M41 -> 13989 | E11: =E12+E51+E69+E82+E95+N11+N28+N41 -> 646 | F11: =F12+F51+F69+F82+F95+O11+O28+O41 -> 410 | G11: =G12+G51+G69+G82+G95+P11+P28+P41 -> 11 | H11: =SUM(B11:G11) -> 38179 | J11: TOTAL EXAMENES ANATOMIA PATOLOGICA | K11: =SUM(K12:K23) -> 880 | L11: =SUM(L12:L23) -> 0 | M11: =SUM(M12:M23) -> 1035 | N11: =SUM(N12:N23) -> 3 | O11: =SUM(O12:O23) -> 7 | P11: =SUM(P12:P23) -> 0 | Q11: =SUM(K11:P11) -> 1925
A12: TOTAL EXAMENES BIOQUÍMICOS | B12: =SUM(B13:B50) -> 3988 | C12: =SUM(C13:C50) -> 6666 | D12: =SUM(D13:D50) -> 6278 | E12: =SUM(E13:E50) -> 425 | F12: =SUM(F13:F50) -> 220 | G12: =SUM(G13:G50) -> 0 | H12: =SUM(B12:G12) -> 17577 | J12: TOTAL EXAMENES CITOLÓGICOS (PAP) | K12: 0 | L12: 0 | M12: 46 | N12: 0 | O12: 0 | P12: 0 | Q12: =SUM(K12:P12) -> 46
A13: ACIDO URICO | B13: 15 | C13: 2 | D13: 35 | E13: 2 | F13: 1 | G13: 0 | H13: =SUM(B13:G13) -> 55 | J13: TOTAL BAAF | K13: 0 | L13: 0 | M13: 6 | N13: 0 | O13: 0 | P13: 0 | Q13: =SUM(K13:P13) -> 6
A14: CALCIO | B14: 15 | C14: 5 | D14: 112 | E14: 5 | F14: 1 | G14: 0 | H14: =SUM(B14:G14) -> 138 | J14: TOTAL EXAMENES HISTOPATOLÓGICOS (Biopsia) | K14: 19 | L14: 0 | M14: 70 | N14: 3 | O14: 4 | P14: 0 | Q14: =SUM(K14:P14) -> 96
A15: AMILASA | B15: 10 | C15: 64 | D15: 35 | E15: 7 | F15: 0 | G15: 0 | H15: =SUM(B15:G15) -> 116 | J15: TOTAL PIEZA QUIRURGICA (HISTOLOGIA) | K15: 21 | L15: 0 | M15: 8 | N15: 0 | O15: 3 | P15: 0 | Q15: =SUM(K15:P15) -> 32
A16: GLUCOSA | B16: 572 | C16: 1528 | D16: 1028 | E16: 107 | F16: 37 | G16: 0 | H16: =SUM(B16:G16) -> 3272 | J16: TOTAL CITOLOGIA ESPECIAL | K16: 5 | L16: 0 | M16: 2 | N16: 0 | O16: 0 | P16: 0 | Q16: =SUM(K16:P16) -> 7
A17: GLUCOSA POST PRANDIAL | B17: 0 | C17: 0 | D17: 14 | E17: 0 | F17: 1 | G17: 0 | H17: =SUM(B17:G17) -> 15 | J17: TOTAL DE TEJIDOS INCLUIDOS | K17: 277 | L17: 0 | M17: 300 | N17: 0 | O17: 0 | P17: 0 | Q17: =SUM(K17:P17) -> 577
A18: FOSFORO | B18: 15 | C18: 5 | D18: 68 | E18: 5 | F18: 0 | G18: 0 | H18: =SUM(B18:G18) -> 93 | J18: TOTAL DE CORTES DE TEJIDOS | K18: 279 | L18: 0 | M18: 300 | N18: 0 | O18: 0 | P18: 0 | Q18: =SUM(K18:P18) -> 579
A19: HEMOGLOBINA GLICOSILADA | B19: 79 | C19: 5 | D19: 219 | E19: 13 | F19: 9 | G19: 0 | H19: =SUM(B19:G19) -> 325 | J19: TOTAL DE LÁMINAS MONTADAS | K19: 279 | L19: 0 | M19: 300 | N19: 0 | O19: 0 | P19: 0 | Q19: =SUM(K19:P19) -> 579
A20: TOLERANCIA A LA GLUCOSA | B20: 9 | C20: 0 | D20: 56 | E20: 3 | F20: 1 | G20: 0 | H20: =SUM(B20:G20) -> 69 | J20: TOTAL DE HISTOQUIMICA | K20: 0 | L20: 0 | M20: 3 | N20: 0 | O20: 0 | P20: 0 | Q20: =SUM(K20:P20) -> 3
A21: CREATININA | B21: 0 | C21: 3 | D21: 0 | E21: 0 | F21: 13 | G21: 0 | H21: =SUM(B21:G21) -> 16 | J21: TOTAL DE INMUNOHISTOQUIMICA | K21: 0 | L21: 0 | M21: 0 | N21: 0 | O21: 0 | P21: 0 | Q21: =SUM(K21:P21) -> 0
A22: DEPURACION DE CREATININA | B22: 0 | C22: 0 | D22: 0 | E22: 0 | F22: 0 | G22: 0 | H22: =SUM(B22:G22) -> 0 | J22: TOTAL AUTOPSIA MÉDICO LEGAL | K22: 0 | L22: 0 | M22: 0 | N22: 0 | O22: 0 | P22: 0 | Q22: =SUM(K22:P22) -> 0
A23: MICROALBUMINURIA | B23: 0 | C23: 2 | D23: 3 | E23: 0 | F23: 0 | G23: 0 | H23: =SUM(B23:G23) -> 5 | J23: TOTAL AUTOPSIA CLÍNICA | K23: 0 | L23: 0 | M23: 0 | N23: 0 | O23: 0 | P23: 0 | Q23: =SUM(K23:P23) -> 0
A24: UREA | B24: 550 | C24: 1343 | D24: 875 | E24: 67 | F24: 17 | G24: 0 | H24: =SUM(B24:G24) -> 2852
A25: PROTEINURIA 24 HORAS | B25: 20 | C25: 2 | D25: 51 | E25: 1 | F25: 3 | G25: 0 | H25: =SUM(B25:G25) -> 77
A26: BILIRRUBINA TOTAL | B26: 562 | C26: 474 | D26: 485 | E26: 10 | F26: 18 | G26: 0 | H26: =SUM(B26:G26) -> 1549 | J26: PROGRAMAS / METAXENICAS | K26: TOTAL
A27: BILIRRUBINA DIRECTA | B27: 3 | C27: 260 | D27: 60 | E27: 2 | F27: 18 | G27: 0 | H27: =SUM(B27:G27) -> 343 | K27: Hospitaliz | L27: Emergenc | M27: Programa | N27: Privado | O27: Convenio | P27: Insolvencia | Q27: TOTAL
A28: PROTEINAS TOTAL | B28: 0 | C28: 0 | D28: 0 | E28: 0 | F28: 9 | G28: 0 | H28: =SUM(B28:G28) -> 9 | J28: TOTAL DE EXAMENES | K28: =SUM(K29:K37) -> 65 | L28: =SUM(L29:L37) -> 246 | M28: =SUM(M29:M37) -> 108 | N28: =SUM(N29:N37) -> 0 | O28: =SUM(O29:O37) -> 0 | P28: =SUM(P29:P37) -> 0 | Q28: =SUM(K28:P28) -> 419
A29: ALBUMINA | B29: 95 | C29: 0 | D29: 246 | E29: 1 | F29: 9 | G29: 0 | H29: =SUM(B29:G29) -> 351 | J29: TUBERCULOSIS | K29: 41 | L29: 3 | M29: 64 | N29: 0 | O29: 0 | P29: 0 | Q29: =SUM(K29:P29) -> 108
A30: TGO | B30: 220 | C30: 586 | D30: 490 | E30: 24 | F30: 10 | G30: 0 | H30: =SUM(B30:G30) -> 1330 | J30: LEISHMANIA | K30: 0 | L30: 0 | M30: 0 | N30: 0 | O30: 0 | P30: 0 | Q30: =SUM(K30:P30) -> 0
A31: TGP | B31: 320 | C31: 139 | D31: 590 | E31: 21 | F31: 10 | G31: 0 | H31: =SUM(B31:G31) -> 1080 | J31: PROGRAMA LEPRAE | K31: 0 | L31: 7 | M31: 12 | N31: 0 | O31: 0 | P31: 0 | Q31: =SUM(K31:P31) -> 19
A32: GGTP | B32: 102 | C32: 15 | D32: 235 | E32: 15 | F32: 0 | G32: 0 | H32: =SUM(B32:G32) -> 367 | J32: MALARIA | K32: 24 | L32: 197 | M32: 10 | N32: 0 | O32: 0 | P32: 0 | Q32: =SUM(K32:P32) -> 231
A33: LACTATO DESHIDROGENASA (DHL) | B33: 95 | C33: 58 | D33: 85 | E33: 0 | F33: 0 | G33: 0 | H33: =SUM(B33:G33) -> 238 | J33: METAXENICAS (REFERENCIAL) | K33: 0 | L33: 23 | M33: 0 | N33: 0 | O33: 0 | P33: 0 | Q33: =SUM(K33:P33) -> 23
A34: PROTEINA C REACTIVA (CUANTITATIVO) | B34: 602 | C34: 945 | D34: 85 | E34: 23 | F34: 1 | G34: 0 | H34: =SUM(B34:G34) -> 1656 | J34: CULTIVO DE TB (REFERENCIAL) | K34: 0 | L34: 0 | M34: 22 | N34: 0 | O34: 0 | P34: 0 | Q34: =SUM(K34:P34) -> 22
A35: FOSFATASA ALCALINA | B35: 0 | C35: 27 | D35: 0 | E35: 0 | F35: 4 | G35: 0 | H35: =SUM(B35:G35) -> 31 | J35: PRUEBA RAPIDA DE DENGUE | K35: 0 | L35: 7 | M35: 0 | N35: 0 | O35: 0 | P35: 0 | Q35: =SUM(K35:P35) -> 7
A36: CPK TOTAL | B36: 0 | C36: 0 | D36: 0 | E36: 0 | F36: 0 | G36: 0 | H36: =SUM(B36:G36) -> 0 | J36: PRUEBA RAPIDA DE LEPTOSPIRA | K36: 0 | L36: 9 | M36: 0 | N36: 0 | O36: 0 | P36: 0 | Q36: =SUM(K36:P36) -> 9
A37: CPK MB | B37: 13 | C37: 26 | D37: 1 | E37: 4 | F37: 0 | G37: 0 | H37: =SUM(B37:G37) -> 44 | J37: PRUEBA RAPIDA DE COVID + INFLUENZA | K37: 0 | L37: 0 | M37: 0 | N37: 0 | O37: 0 | P37: 0 | Q37: =SUM(K37:P37) -> 0
A38: COLESTEROL | B38: 92 | C38: 8 | D38: 382 | E38: 35 | F38: 17 | G38: 0 | H38: =SUM(B38:G38) -> 534
A39: TRIGLICERIDOS | B39: 93 | C39: 7 | D39: 382 | E39: 33 | F39: 17 | G39: 0 | H39: =SUM(B39:G39) -> 532 | J39: BANCO DE SANGRE | K39: TOTAL
A40: HDLc | B40: 83 | C40: 2 | D40: 231 | E40: 8 | F40: 11 | G40: 0 | H40: =SUM(B40:G40) -> 335 | K40: Hospitaliz | L40: Emergenc | M40: C. Externa | N40: Privado | O40: Convenio | P40: Insolvencia | Q40: TOTAL
A41: LDLc | B41: 83 | C41: 2 | D41: 231 | E41: 8 | F41: 11 | G41: 0 | H41: =SUM(B41:G41) -> 335 | J41: TOTAL DE UNIDADES ENTREGADAS | K41: =SUM(K42:K49) -> 732 | L41: =SUM(L42:L49) -> 173 | M41: =SUM(M42:M49) -> 5 | N41: =SUM(N42:N49) -> 5 | O41: =SUM(O42:O49) -> 9 | P41: =SUM(P42:P49) -> 0 | Q41: =SUM(K41:P41) -> 924
A42: ASO | B42: 2 | C42: 0 | D42: 2 | E42: 0 | F42: 0 | G42: 0 | H42: =SUM(B42:G42) -> 4 | J42: SANGRE TOTAL | K42: 0 | L42: 0 | M42: 0 | N42: 0 | O42: 0 | P42: 0 | Q42: =SUM(K42:P42) -> 0
A43: FACTOR REUMATOIDEO | B43: 15 | C43: 3 | D43: 41 | E43: 5 | F43: 0 | G43: 0 | H43: =SUM(B43:G43) -> 64 | J43: GLOBULOS ROJOS | K43: 176 | L43: 41 | M43: 1 | N43: 1 | O43: 3 | P43: 0 | Q43: =SUM(K43:P43) -> 222
A44: HIERRO | B44: 15 | C44: 5 | D44: 72 | E44: 2 | F44: 1 | G44: 0 | H44: =SUM(B44:G44) -> 95 | J44: PLASMA FRESCO CONGELADO | K44: 38 | L44: 4 | M44: 0 | N44: 0 | O44: 0 | P44: 0 | Q44: =SUM(K44:P44) -> 42
A45: LIPASA | B45: 0 | C45: 1 | D45: 0 | E45: 0 | F45: 0 | G45: 0 | H45: =SUM(B45:G45) -> 1 | J45: CRIOPRECIPITADO | K45: 17 | L45: 0 | M45: 0 | N45: 0 | O45: 0 | P45: 0 | Q45: =SUM(K45:P45) -> 17
A46: TRANSFERRINA | B46: 7 | C46: 7 | D46: 58 | E46: 4 | F46: 0 | G46: 0 | H46: =SUM(B46:G46) -> 76 | J46: PLAQUETAS | K46: 27 | L46: 2 | M46: 0 | N46: 0 | O46: 0 | P46: 0 | Q46: =SUM(K46:P46) -> 29
...

Sheet MARZO
A4: Establecimiento de Salud informante: | B4: HOSPITAL REGIONAL DE LORETO | K4: Mes: | L4: MARZO
A6: Código Renaes: | B6: 3 | K6: Año:
A9: PATOLOGÍA CLÍNICA | B9: TOTAL | J9: ANATOMÍA PATOLÓGICA | K9: TOTAL
B10: Hospitaliz | C10: Emergenc | D10: C. Externa | E10: Privado | F10: Convenio | G10: Insolvencia | H10: TOTAL | K10: Hospitaliz | L10: Emergenc | M10: C. Externa | N10: Privado | O10: Convenio | P10: Insolvencia | Q10: TOTAL
A11: TOTAL DE EXAMENES LABORATORIO | B11: =B12+B51+B69+B82+B95+K11+K28+K41 -> 0 | C11: =C12+C51+C69+C82+C95+L11+L28+L41 -> 0 | D11: =D12+D51+D69+D82+D95+M11+M28+M41 -> 0 | E11: =E12+E51+E69+E82+E95+N11+N28+N41 -> 0 | F11: =F12+F51+F69+F82+F95+O11+O28+O41 -> 0 | G11: =G12+G51+G69+G82+G95+P11+P28+P41 -> 0 | H11: =SUM(B11:G11) -> 0 | J11: TOTAL EXAMENES ANATOMIA PATOLOGICA | K11: =SUM(K12:K23) -> 0 | L11: =SUM(L12:L23) -> 0 | M11: =SUM(M12:M23) -> 0 | N11: =SUM(N12:N23) -> 0 | O11: =SUM(O12:O23) -> 0 | P11: =SUM(P12:P23) -> 0 | Q11: =SUM(K11:P11) -> 0
A12: TOTAL EXAMENES BIOQUÍMICOS | B12: =SUM(B13:B50) -> 0 | C12: =SUM(C13:C50) -> 0 | D12: =SUM(D13:D50) -> 0 | E12: =SUM(E13:E50) -> 0 | F12: =SUM(F13:F50) -> 0 | G12: =SUM(G13:G50) -> 0 | H12: =SUM(B12:G12) -> 0 | J12: TOTAL EXAMENES CITOLÓGICOS (PAP) | Q12: =SUM(K12:P12) -> 0
A13: ACIDO URICO | H13: =SUM(B13:G13) -> 0 | J13: TOTAL BAAF | Q13: =SUM(K13:P13) -> 0
A14: CALCIO | H14: =SUM(B14:G14) -> 0 | J14: TOTAL EXAMENES HISTOPATOLÓGICOS (Biopsia) | Q14: =SUM(K14:P14) -> 0
A15: AMILASA | H15: =SUM(B15:G15) -> 0 | J15: TOTAL PIEZA QUIRURGICA (HISTOLOGIA) | Q15: =SUM(K15:P15) -> 0
A16: GLUCOSA | H16: =SUM(B16:G16) -> 0 | J16: TOTAL CITOLOGIA ESPECIAL | Q16: =SUM(K16:P16) -> 0
A17: GLUCOSA POST PRANDIAL | H17: =SUM(B17:G17) -> 0 | J17: TOTAL DE TEJIDOS INCLUIDOS | Q17: =SUM(K17:P17) -> 0
A18: FOSFORO | H18: =SUM(B18:G18) -> 0 | J18: TOTAL DE CORTES DE TEJIDOS | Q18: =SUM(K18:P18) -> 0
A19: HEMOGLOBINA GLICOSILADA | H19: =SUM(B19:G19) -> 0 | J19: TOTAL DE LÁMINAS MONTADAS | Q19: =SUM(K19:P19) -> 0
A20: TOLERANCIA A LA GLUCOSA | H20: =SUM(B20:G20) -> 0 | J20: TOTAL DE HISTOQUIMICA | Q20: =SUM(K20:P20) -> 0
A21: CREATININA | H21: =SUM(B21:G21) -> 0 | J21: TOTAL DE INMUNOHISTOQUIMICA
A22: DEPURACION DE CREATININA | H22: =SUM(B22:G22) -> 0 | J22: TOTAL AUTOPSIA MÉDICO LEGAL | Q22: =SUM(K22:P22) -> 0
J23: TOTAL AUTOPSIA CLÍNICA | Q23: =SUM(K23:P23) -> 0
A24: UREA | H24: =SUM(B24:G24) -> 0
A25: PROTEINURIA 24 HORAS | H25: =SUM(B25:G25) -> 0
A26: BILIRRUBINA TOTAL | H26: =SUM(B26:G26) -> 0 | J26: PROGRAMAS / METAXENICAS | K26: TOTAL
A27: BILIRRUBINA DIRECTA | H27: =SUM(B27:G27) -> 0 | K27: Hospitaliz | L27: Emergenc | M27: Programa | N27: Privado | O27: Convenio | P27: Insolvencia | Q27: TOTAL
A28: PROTEINAS TOTAL | H28: =SUM(B28:G28) -> 0 | J28: TOTAL DE EXAMENES | K28: =SUM(K29:K37) -> 0 | L28: =SUM(L29:L37) -> 0 | M28: =SUM(M29:M37) -> 0 | N28: =SUM(N29:N37) -> 0 | O28: =SUM(O29:O37) -> 0 | P28: =SUM(P29:P37) -> 0 | Q28: =SUM(K28:P28) -> 0
A29: ALBUMINA | H29: =SUM(B29:G29) -> 0 | J29: TUBERCULOSIS | Q29: =SUM(K29:P29) -> 0
A30: TGO | H30: =SUM(B30:G30) -> 0 | J30: LEISHMANIA | Q30: =SUM(K30:P30) -> 0
A31: TGP | H31: =SUM(B31:G31) -> 0 | J31: PROGRAMA LEPRAE | Q31: =SUM(K31:P31) -> 0
A32: GGTP | H32: =SUM(B32:G32) -> 0 | J32: MALARIA | Q32: =SUM(K32:P32) -> 0
A33: LACTATO DESHIDROGENASA (DHL) | H33: =SUM(B33:G33) -> 0 | J33: METAXENICAS (REFERENCIAL) | Q33: =SUM(K33:P33) -> 0
A34: PROTEINA C REACTIVA (CUANTITATIVO) | H34: =SUM(B34:G34) -> 0 | J34: CULTIVO DE TB (REFERENCIAL) | Q34: =SUM(K34:P34) -> 0
A35: FOSFATASA ALCALINA | H35: =SUM(B35:G35) -> 0 | J35: PRUEBA RAPIDA DE DENGUE | Q35: =SUM(K35:P35) -> 0
A36: CPK TOTAL | H36: =SUM(B36:G36) -> 0 | J36: PRUEBA RAPIDA DE LEPTOSPIRA | Q36: =SUM(K36:P36) -> 0
A37: CPK MB | H37: =SUM(B37:G37) -> 0 | J37: PRUEBA RAPIDA DE COVID + INFLUENZA | Q37: =SUM(K37:P37) -> 0
A38: COLESTEROL | H38: =SUM(B38:G38) -> 0
A39: TRIGLICERIDOS | H39: =SUM(B39:G39) -> 0 | J39: BANCO DE SANGRE | K39: TOTAL
A40: HDLc | H40: =SUM(B40:G40) -> 0 | K40: Hospitaliz | L40: Emergenc | M40: C. Externa | N40: Privado | O40: Convenio | P40: Insolvencia | Q40: TOTAL
A41: LDLc | H41: =SUM(B41:G41) -> 0 | J41: TOTAL DE UNIDADES ENTREGADAS | K41: =SUM(K42:K49) -> 0 | L41: =SUM(L42:L49) -> 0 | M41: =SUM(M42:M49) -> 0 | N41: =SUM(N42:N49) -> 0 | O41: =SUM(O42:O49) -> 0 | P41: =SUM(P42:P49) -> 0 | Q41: =SUM(K41:P41) -> 0
A42: ASO | H42: =SUM(B42:G42) -> 0 | J42: SANGRE TOTAL | Q42: =SUM(K42:P42) -> 0
A43: FACTOR REUMATOIDEO | H43: =SUM(B43:G43) -> 0 | J43: GLOBULOS ROJOS | Q43: =SUM(K43:P43) -> 0
A44: HIERRO | H44: =SUM(B44:G44) -> 0 | J44: PLASMA FRESCO CONGELADO | Q44: =SUM(K44:P44) -> 0
A45: LIPASA | H45: =SUM(B45:G45) -> 0 | J45: CRIOPRECIPITADO | Q45: =SUM(K45:P45) -> 0
A46: TRANSFERRINA | H46: =SUM(B46:G46) -> 0 | J46: PLAQUETAS | Q46: =SUM(K46:P46) -> 0
...

Sheet ABRIL
A4: Establecimiento de Salud informante: | B4: HOSPITAL REGIONAL DE LORETO | K4: Mes: | L4: ABRIL
A6: Código Renaes: | B6: 3 | K6: Año:
A9: PATOLOGÍA CLÍNICA | B9: TOTAL | J9: ANATOMÍA PATOLÓGICA | K9: TOTAL
B10: Hospitaliz | C10: Emergenc | D10: C. Externa | E10: Privado | F10: Convenio | G10: Insolvencia | H10: TOTAL | K10: Hospitaliz | L10: Emergenc | M10: C. Externa | N10: Privado | O10: Convenio | P10: Insolvencia | Q10: TOTAL
A11: TOTAL DE EXAMENES LABORATORIO | B11: =B12+B51+B69+B82+B95 -> 0 | C11: =C12+C51+C69+C82+C95 -> 0 | D11: =D12+D51+D69+D82+D95 -> 0 | E11: =E12+E51+E69+E82+E95 -> 0 | F11: =F12+F51+F69+F82+F95 -> 0 | G11: =G12+G51+G69+G82+G95 -> 0 | H11: =SUM(B11:G11) -> 0 | J11: TOTAL EXAMENES ANATOMIA PATOLOGICA | K11: =SUM(K12:K23) -> 0 | L11: =SUM(L12:L23) -> 0 | M11: =SUM(M12:M23) -> 0 | N11: =SUM(N12:N23) -> 0 | O11: =SUM(O12:O23) -> 0 | P11: =SUM(P12:P23) -> 0 | Q11: =SUM(K11:P11) -> 0
A12: TOTAL EXAMENES BIOQUÍMICOS | B12: =SUM(B13:B50) -> 0 | C12: =SUM(C13:C50) -> 0 | D12: =SUM(D13:D50) -> 0 | E12: =SUM(E13:E50) -> 0 | F12: =SUM(F13:F50) -> 0 | G12: =SUM(G13:G50) -> 0 | H12: =SUM(B12:G12) -> 0 | J12: TOTAL EXAMENES CITOLÓGICOS (PAP) | Q12: =SUM(K12:P12) -> 0
A13: ACIDO URICO | H13: =SUM(B13:G13) -> 0 | J13: TOTAL BAAF | Q13: =SUM(K13:P13) -> 0
A14: CALCIO | H14: =SUM(B14:G14) -> 0 | J14: TOTAL EXAMENES HISTOPATOLÓGICOS (Biopsia) | Q14: =SUM(K14:P14) -> 0
A15: AMILASA | H15: =SUM(B15:G15) -> 0 | J15: TOTAL PIEZA QUIRURGICA (HISTOLOGIA) | Q15: =SUM(K15:P15) -> 0
A16: GLUCOSA | H16: =SUM(B16:G16) -> 0 | J16: TOTAL CITOLOGIA ESPECIAL | Q16: =SUM(K16:P16) -> 0
A17: GLUCOSA POST PRANDIAL | H17: =SUM(B17:G17) -> 0 | J17: TOTAL DE TEJIDOS INCLUIDOS | Q17: =SUM(K17:P17) -> 0
A18: FOSFORO | H18: =SUM(B18:G18) -> 0 | J18: TOTAL DE CORTES DE TEJIDOS | Q18: =SUM(K18:P18) -> 0
A19: HEMOGLOBINA GLICOSILADA | H19: =SUM(B19:G19) -> 0 | J19: TOTAL DE LÁMINAS MONTADAS | Q19: =SUM(K19:P19) -> 0
A20: TOLERANCIA A LA GLUCOSA | H20: =SUM(B20:G20) -> 0 | J20: TOTAL DE HISTOQUIMICA | Q20: =SUM(K20:P20) -> 0
A21: CREATININA | H21: =SUM(B21:G21) -> 0 | J21: TOTAL DE INMUNOHISTOQUIMICA
A22: DEPURACION DE CREATININA | H22: =SUM(B22:G22) -> 0 | J22: TOTAL AUTOPSIA MÉDICO LEGAL | Q22: =SUM(K22:P22) -> 0
A23: MICROALBUMINURIA | H23: =SUM(B23:G23) -> 0 | J23: TOTAL AUTOPSIA CLÍNICA | Q23: =SUM(K23:P23) -> 0
A24: UREA | H24: =SUM(B24:G24) -> 0
A25: PROTEINURIA 24 HORAS | H25: =SUM(B25:G25) -> 0
A26: BILIRRUBINA TOTAL | H26: =SUM(B26:G26) -> 0 | J26: PROGRAMAS / METAXENICAS | K26: TOTAL
A27: BILIRRUBINA DIRECTA | H27: =SUM(B27:G27) -> 0 | K27: Hospitaliz | L27: Emergenc | M27: Programa | N27: Privado | O27: Convenio | P27: Insolvencia | Q27: TOTAL
A28: PROTEINAS TOTAL | H28: =SUM(B28:G28) -> 0 | J28: TOTAL DE EXAMENES | K28: =SUM(K29:K37) -> 0 | L28: =SUM(L29:L37) -> 0 | M28: =SUM(M29:M37) -> 0 | N28: =SUM(N29:N37) -> 0 | O28: =SUM(O29:O37) -> 0 | P28: =SUM(P29:P37) -> 0 | Q28: =SUM(K28:P28) -> 0
A29: ALBUMINA | H29: =SUM(B29:G29) -> 0 | J29: TUBERCULOSIS | Q29: =SUM(K29:P29) -> 0
A30: TGO | H30: =SUM(B30:G30) -> 0 | J30: LEISHMANIA | Q30: =SUM(K30:P30) -> 0
A31: TGP | H31: =SUM(B31:G31) -> 0 | J31: PROGRAMA LEPRAE | Q31: =SUM(K31:P31) -> 0
A32: GGTP | H32: =SUM(B32:G32) -> 0 | J32: MALARIA | Q32: =SUM(K32:P32) -> 0
A33: LACTATO DESHIDROGENASA (DHL) | H33: =SUM(B33:G33) -> 0 | J33: METAXENICAS (REFERENCIAL) | Q33: =SUM(K33:P33) -> 0
A34: PROTEINA C REACTIVA (CUANTITATIVO) | H34: =SUM(B34:G34) -> 0 | J34: CULTIVO DE TB (REFERENCIAL) | Q34: =SUM(K34:P34) -> 0
A35: FOSFATASA ALCALINA | H35: =SUM(B35:G35) -> 0 | J35: PRUEBA RAPIDA DE DENGUE | Q35: =SUM(K35:P35) -> 0
A36: CPK TOTAL | H36: =SUM(B36:G36) -> 0 | J36: PRUEBA RAPIDA DE LEPTOSPIRA | Q36: =SUM(K36:P36) -> 0
A37: CPK MB | H37: =SUM(B37:G37) -> 0 | J37: PRUEBA RAPIDA DE COVID | Q37: =SUM(K37:P37) -> 0
A38: COLESTEROL | H38: =SUM(B38:G38) -> 0
A39: TRIGLICERIDOS | H39: =SUM(B39:G39) -> 0 | J39: BANCO DE SANGRE | K39: TOTAL
A40: HDLc | H40: =SUM(B40:G40) -> 0 | K40: Hospitaliz | L40: Emergenc | M40: C. Externa | N40: Privado | O40: Convenio | P40: Insolvencia | Q40: TOTAL
A41: LDLc | H41: =SUM(B41:G41) -> 0 | J41: TOTAL DE UNIDADES ENTREGADAS | K41: =SUM(K42:K49) -> 0 | L41: =SUM(L42:L49) -> 0 | M41: =SUM(M42:M49) -> 0 | N41: =SUM(N42:N49) -> 0 | O41: =SUM(O42:O49) -> 0 | P41: =SUM(P42:P49) -> 0 | Q41: =SUM(K41:P41) -> 0
A42: ASO | H42: =SUM(B42:G42) -> 0 | J42: SANGRE TOTAL | Q42: =SUM(K42:P42) -> 0
A43: FACTOR REUMATOIDEO | H43: =SUM(B43:G43) -> 0 | J43: GLOBULOS ROJOS | Q43: =SUM(K43:P43) -> 0
A44: HIERRO | H44: =SUM(B44:G44) -> 0 | J44: PLASMA FRESCO CONGELADO | Q44: =SUM(K44:P44) -> 0
A45: LIPASA | H45: =SUM(B45:G45) -> 0 | J45: CRIOPRECIPITADO | Q45: =SUM(K45:P45) -> 0
A46: TRANSFERRINA | H46: =SUM(B46:G46) -> 0 | J46: PLAQUETAS | Q46: =SUM(K46:P46) -> 0
...

Sheet MAYO
A4: Establecimiento de Salud informante: | B4: HOSPITAL REGIONAL DE LORETO | K4: Mes: | L4: MAYO
A6: Código Renaes: | B6: 3 | K6: Año:
A9: PATOLOGÍA CLÍNICA | B9: TOTAL | J9: ANATOMÍA PATOLÓGICA | K9: TOTAL
B10: Hospitaliz | C10: Emergenc | D10: C. Externa | E10: Privado | F10: Convenio | G10: Insolvencia | H10: TOTAL | K10: Hospitaliz | L10: Emergenc | M10: C. Externa | N10: Privado | O10: Convenio | P10: Insolvencia | Q10: TOTAL
A11: TOTAL DE EXAMENES LABORATORIO | B11: =B12+B51+B69+B82+B95 -> 0 | C11: =C12+C51+C69+C82+C95 -> 0 | D11: =D12+D51+D69+D82+D95 -> 0 | E11: =E12+E51+E69+E82+E95 -> 0 | F11: =F12+F51+F69+F82+F95 -> 0 | G11: =G12+G51+G69+G82+G95 -> 0 | H11: =SUM(B11:G11) -> 0 | J11: TOTAL EXAMENES ANATOMIA PATOLOGICA | K11: =SUM(K12:K23) -> 0 | L11: =SUM(L12:L23) -> 0 | M11: =SUM(M12:M23) -> 0 | N11: =SUM(N12:N23) -> 0 | O11: =SUM(O12:O23) -> 0 | P11: =SUM(P12:P23) -> 0 | Q11: =SUM(K11:P11) -> 0
A12: TOTAL EXAMENES BIOQUÍMICOS | B12: =SUM(B13:B50) -> 0 | C12: =SUM(C13:C50) -> 0 | D12: =SUM(D13:D50) -> 0 | E12: =SUM(E13:E50) -> 0 | F12: =SUM(F13:F50) -> 0 | G12: =SUM(G13:G50) -> 0 | H12: =SUM(B12:G12) -> 0 | J12: TOTAL EXAMENES CITOLÓGICOS (PAP) | Q12: =SUM(K12:P12) -> 0
A13: ACIDO URICO | H13: =SUM(B13:G13) -> 0 | J13: TOTAL BAAF | Q13: =SUM(K13:P13) -> 0
A14: CALCIO | H14: =SUM(B14:G14) -> 0 | J14: TOTAL EXAMENES HISTOPATOLÓGICOS (Biopsia) | Q14: =SUM(K14:P14) -> 0
A15: AMILASA | H15: =SUM(B15:G15) -> 0 | J15: TOTAL PIEZA QUIRURGICA (HISTOLOGIA) | Q15: =SUM(K15:P15) -> 0
A16: GLUCOSA | H16: =SUM(B16:G16) -> 0 | J16: TOTAL CITOLOGIA ESPECIAL | Q16: =SUM(K16:P16) -> 0
A17: GLUCOSA POST PRANDIAL | H17: =SUM(B17:G17) -> 0 | J17: TOTAL DE TEJIDOS INCLUIDOS | Q17: =SUM(K17:P17) -> 0
A18: FOSFORO | H18: =SUM(B18:G18) -> 0 | J18: TOTAL DE CORTES DE TEJIDOS | Q18: =SUM(K18:P18) -> 0
A19: HEMOGLOBINA GLICOSILADA | H19: =SUM(B19:G19) -> 0 | J19: TOTAL DE LÁMINAS MONTADAS | Q19: =SUM(K19:P19) -> 0
A20: TOLERANCIA A LA GLUCOSA | H20: =SUM(B20:G20) -> 0 | J20: TOTAL DE HISTOQUIMICA | Q20: =SUM(K20:P20) -> 0
A21: CREATININA | H21: =SUM(B21:G21) -> 0
A22: DEPURACION DE CREATININA | H22: =SUM(B22:G22) -> 0 | J22: TOTAL AUTOPSIA MÉDICO LEGAL | Q22: =SUM(K22:P22) -> 0
A23: MICROALBUMINURIA | H23: =SUM(B23:G23) -> 0 | J23: TOTAL AUTOPSIA CLÍNICA | Q23: =SUM(K23:P23) -> 0
A24: UREA | H24: =SUM(B24:G24) -> 0
A25: PROTEINURIA 24 HORAS | H25: =SUM(B25:G25) -> 0
A26: BILIRRUBINA TOTAL | H26: =SUM(B26:G26) -> 0 | J26: PROGRAMAS / METAXENICAS | K26: TOTAL
A27: BILIRRUBINA DIRECTA | H27: =SUM(B27:G27) -> 0 | K27: Hospitaliz | L27: Emergenc | M27: Programa | N27: Privado | O27: Convenio | P27: Insolvencia | Q27: TOTAL
A28: PROTEINAS TOTAL | H28: =SUM(B28:G28) -> 0 | J28: TOTAL DE EXAMENES | K28: =SUM(K29:K37) -> 0 | L28: =SUM(L29:L37) -> 0 | M28: =SUM(M29:M37) -> 0 | N28: =SUM(N29:N37) -> 0 | O28: =SUM(O29:O37) -> 0 | P28: =SUM(P29:P37) -> 0 | Q28: =SUM(K28:P28) -> 0
A29: ALBUMINA | H29: =SUM(B29:G29) -> 0 | J29: TUBERCULOSIS | Q29: =SUM(K29:P29) -> 0
A30: TGO | H30: =SUM(B30:G30) -> 0 | J30: LEISHMANIA | Q30: =SUM(K30:P30) -> 0
A31: TGP | H31: =SUM(B31:G31) -> 0 | J31: PROGRAMA LEPRAE | Q31: =SUM(K31:P31) -> 0
A32: GGTP | H32: =SUM(B32:G32) -> 0 | J32: MALARIA | Q32: =SUM(K32:P32) -> 0
A33: LACTATO DESHIDROGENASA (DHL) | H33: =SUM(B33:G33) -> 0 | J33: METAXENICAS (REFERENCIAL) | Q33: =SUM(K33:P33) -> 0
A34: PROTEINA C REACTIVA (CUANTITATIVO) | H34: =SUM(B34:G34) -> 0 | J34: CULTIVO DE TB (REFERENCIAL) | Q34: =SUM(K34:P34) -> 0
A35: FOSFATASA ALCALINA | H35: =SUM(B35:G35) -> 0 | J35: PRUEBA RAPIDA DE DENGUE | Q35: =SUM(K35:P35) -> 0
A36: CPK TOTAL | H36: =SUM(B36:G36) -> 0 | J36: PRUEBA RAPIDA DE LEPTOSPIRA | Q36: =SUM(K36:P36) -> 0
A37: CPK MB | H37: =SUM(B37:G37) -> 0 | J37: PRUEBA RAPIDA DE COVID | Q37: =SUM(K37:P37) -> 0
A38: COLESTEROL | H38: =SUM(B38:G38) -> 0
A39: TRIGLICERIDOS | H39: =SUM(B39:G39) -> 0 | J39: BANCO DE SANGRE | K39: TOTAL
A40: HDLc | H40: =SUM(B40:G40) -> 0 | K40: Hospitaliz | L40: Emergenc | M40: C. Externa | N40: Privado | O40: Convenio | P40: Insolvencia | Q40: TOTAL
A41: LDLc | H41: =SUM(B41:G41) -> 0 | J41: TOTAL DE UNIDADES ENTREGADAS | K41: =SUM(K42:K49) -> 0 | L41: =SUM(L42:L49) -> 0 | M41: =SUM(M42:M49) -> 0 | N41: =SUM(N42:N49) -> 0 | O41: =SUM(O42:O49) -> 0 | P41: =SUM(P42:P49) -> 0 | Q41: =SUM(K41:P41) -> 0
A42: ASO | H42: =SUM(B42:G42) -> 0 | J42: SANGRE TOTAL | Q42: =SUM(K42:P42) -> 0
A43: FACTOR REUMATOIDEO | H43: =SUM(B43:G43) -> 0 | J43: GLOBULOS ROJOS | Q43: =SUM(K43:P43) -> 0
A44: HIERRO | H44: =SUM(B44:G44) -> 0 | J44: PLASMA FRESCO CONGELADO | Q44: =SUM(K44:P44) -> 0
A45: LIPASA | H45: =SUM(B45:G45) -> 0 | J45: CRIOPRECIPITADO | Q45: =SUM(K45:P45) -> 0
A46: TRANSFERRINA | H46: =SUM(B46:G46) -> 0 | J46: PLAQUETAS | Q46: =SUM(K46:P46) -> 0
...

Sheet CONSOLIDADO
A4: Establecimiento de Salud informante: | B4: HOSPITAL REGIONAL DE LORETO | K4: Mes: | L4: ENERO A DICIEMBRE
A6: Código Renipress: | B6: 3 | K6: Año: | L6: 2025
A9: PATOLOGÍA CLÍNICA | B9: TOTAL | J9: ANATOMÍA PATOLÓGICA | K9: TOTAL
B10: Hospitaliz | C10: Emergenc | D10: C. Externa | E10: Privado | F10: Convenio | G10: Insolvencia | H10: TOTAL | K10: Hospitaliz | L10: Emergenc | M10: C. Externa | N10: Privado | O10: Convenio | P10: Insolvencia | Q10: TOTAL
A11: TOTAL DE EXAMENES LABORATORIO | B11: =B12+B51+B69+B82+B95+K11+K28+K41 -> #REF! | C11: =C12+C51+C69+C82+C95+L11+L28+L41 -> #REF! | D11: =D12+D51+D69+D82+D95+M11+M28+M41 -> #REF! | E11: =E12+E51+E69+E82+E95+N11+N28+N41 -> #REF! | F11: =F12+F51+F69+F82+F95+O11+O28+O41 -> #REF! | G11: =G12+G51+G69+G82+G95+P11+P28+P41 -> #REF! | H11: =SUM(B11:G11) -> #REF! | J11: TOTAL EXAMENES ANATOMIA PATOLOGICA | K11: =SUM(K12:K23) -> #REF! | L11: =SUM(L12:L23) -> #REF! | M11: =SUM(M12:M23) -> #REF! | N11: =SUM(N12:N23) -> #REF! | O11: =SUM(O12:O23) -> #REF! | P11: =SUM(P12:P23) -> #REF! | Q11: =SUM(K11:P11) -> #REF!
A12: TOTAL EXAMENES BIOQUÍMICOS | B12: =SUM(B13:B50) -> #REF! | C12: =SUM(C13:C50) -> #REF! | D12: =SUM(D13:D50) -> #REF! | E12: =SUM(E13:E50) -> #REF! | F12: =SUM(F13:F50) -> #REF! | G12: =SUM(G13:G50) -> #REF! | H12: =SUM(B12:G12) -> #REF! | J12: TOTAL EXAMENES CITOLÓGICOS (PAP) | K12: =SUM(ENERO!K12+FEBRERO!K12+MARZO!K12+ABRIL!K12+MAYO!K12+#REF!+#REF!+#REF!+#REF!+#REF!+#REF!+#REF!) -> #REF! | L12: =SUM(ENERO!L12+FEBRERO!L12+MARZO!L12+ABRIL!L12+MAYO!L12+#REF!+#REF!+#REF!+#REF!+#REF!+#REF!+#REF!) -> #REF! | M12: =SUM(ENERO!M12+FEBRERO!M12+MARZO!M12+ABRIL!M12+MAYO!M12+#REF!+#REF!+#REF!+#REF!+#REF!+#REF!+#REF!) -> #REF! | N12: =SUM(ENERO!N12+FEBRERO!N12+MARZO!N12+ABRIL!N12+MAYO!N12+#REF!+#REF!+#REF!+#REF!+#REF!+#REF!+#REF!) -> #REF! | O12: =SUM(ENERO!O12+FEBRERO!O12+MARZO!O12+ABRIL!O12+MAYO!O12+#REF!+#REF!+#REF!+#REF!+#REF!+#REF!+#REF!) -> #REF! | P12: =SUM(ENERO!P12+FEBRERO!P12+MARZO!P12+ABRIL!P12+MAYO!P12+#REF!+#REF!+#REF!+#REF!+#REF!+#REF!+#REF!) -> #REF! | Q12: =SUM(K12:P12) -> #REF!
A13: ACIDO URICO | B13: =SUM(ENERO!B13+FEBRERO!B13+MARZO!B13+ABRIL!B13+MAYO!B13+#REF!+#REF!+#REF!+#REF!+#REF!+#REF!+#REF!) -> #REF! | C13: =SUM(ENERO!C13+FEBRERO!C13+MARZO!C13+ABRIL!C13+MAYO!C13+#REF!+#REF!+#REF!+#REF!+#REF!+#REF!+#REF!) -> #REF! | D13: =SUM(ENERO!D13+FEBRERO!D13+MARZO!D13+ABRIL!D13+MAYO!D13+#REF!+#REF!+#REF!+#REF!+#REF!+#REF!+#REF!) -> #REF! | E13: =SUM(ENERO!E13+FEBRERO!E13+MARZO!E13+ABRIL!E13+MAYO!E13+#REF!+#REF!+#REF!+#REF!+#REF!+#REF!+#REF!) -> #REF! | F13: =SUM(ENERO!F13+FEBRERO!F13+MARZO!F13+ABRIL!F13+MAYO!F13+#REF!+#REF!+#REF!+#REF!+#REF!+#REF!+#REF!) -> #REF! | G13: =SUM(ENERO!G13+FEBRERO!G13+MARZO!G13+ABRIL!G13+MAYO!G13+#REF!+#REF!+#REF!+#REF!+#REF!+#REF!+#REF!) -> #REF! | H13: =SUM(B13:G13) -> #REF! | J13: TOTAL BAAF | K13: =SUM(ENERO!K13+FEBRERO!K13+MARZO!K13+ABRIL!K13+MAYO!K13+#REF!+#REF!+#REF!+#REF!+#REF!+#REF!+#REF!) -> #REF! | L13: =SUM(ENERO!L13+FEBRERO!L13+MARZO!L13+ABRIL!L13+MAYO!L13+#REF!+#REF!+#REF!+#REF!+#REF!+#REF!+#REF!) -> #REF! | M13: =SUM(ENERO!M13+FEBRERO!M13+MARZO!M13+ABRIL!M13+MAYO!M13+#REF!+#REF!+#REF!+#REF!+#REF!+#REF!+#REF!) -> #REF! | N13: =SUM(ENERO!N13+FEBRERO!N13+MARZO!N13+ABRIL!N13+MAYO!N13+#REF!+#REF!+#REF!+#REF!+#REF!+#REF!+#REF!) -> #REF! | O13: =SUM(ENERO!O13+FEBRERO!O13+MARZO!O13+ABRIL!O13+MAYO!O13+#REF!+#REF!+#REF!+#REF!+#REF!+#REF!+#REF!) -> #REF! | P13: =SUM(ENERO!P13+FEBRERO!P13+MARZO!P13+ABRIL!P13+MAYO!P13+#REF!+#REF!+#REF!+#REF!+#REF!+#REF!+#REF!) -> #REF! | Q13: =SUM(K13:P13) -> #REF!
A14: CALCIO | B14: =SUM(ENERO!B14+FEBRERO!B14+MARZO!B14+ABRIL!B14+MAYO!B14+#REF!+#REF!+#REF!+#REF!+#REF!+#REF!+#REF!) -> #REF! | C14: =SUM(ENERO!C14+FEBRERO!C14+MARZO!C14+ABRIL!C14+MAYO!C14+#REF!+#REF!+#REF!+#REF!+#REF!+#REF!+#REF!) -> #REF! | D14: =SUM(ENERO!D14+FEBRERO!D14+MARZO!D14+ABRIL!D14+MAYO!D14+#REF!+#REF!+#REF!+#REF!+#REF!+#REF!+#REF!) -> #REF! | E14: =SUM(ENERO!E14+FEBRERO!E14+MARZO!E14+ABRIL!E14+MAYO!E14+#REF!+#REF!+#REF!+#REF!+#REF!+#REF!+#REF!) -> #REF! | F14: =SUM(ENERO!F14+FEBRERO!F14+MARZO!F14+ABRIL!F14+MAYO!F14+#REF!+#REF!+#REF!+#REF!+#REF!+#REF!+#REF!) -> #REF! | G14: =SUM(ENERO!G14+FEBRERO!G14+MARZO!G14+ABRIL!G14+MAYO!G14+#REF!+#REF!+#REF!+#REF!+#REF!+#REF!+#REF!) -> #REF! | H14: =SUM(B14:G14) -> #REF! | J14: TOTAL EXAMENES HISTOPATOLÓGICOS (Biopsia) | K14: =SUM(ENERO!K14+FEBRERO!K14+MARZO!K14+ABRIL!K14+MAYO!K14+#REF!+#REF!+#REF!+#REF!+#REF!+#REF!+#REF!) -> #REF! | L14: =SUM(ENERO!L14+FEBRERO!L14+MARZO!L14+ABRIL!L14+MAYO!L14+#REF!+#REF!+#REF!+#REF!+#REF!+#REF!+#REF!) -> #REF! | M14: =SUM(ENERO!M14+FEBRERO!M14+MARZO!M14+ABRIL!M14+MAYO!M14+#REF!+#REF!+#REF!+#REF!+#REF!+#REF!+#REF!) -> #REF! | N14: =SUM(ENERO!N14+FEBRERO!N14+MARZO!N14+ABRIL!N14+MAYO!N14+#REF!+#REF!+#REF!+#REF!+#REF!+#REF!+#REF!) -> #REF! | O14: =SUM(ENERO!O14+FEBRERO!O14+MARZO!O14+ABRIL!O14+MAYO!O14+#REF!+#REF!+#REF!+#REF!+#REF!+#REF!+#REF!) -> #REF! | P14: =SUM(ENERO!P14+FEBRERO!P14+MARZO!P14+ABRIL!P14+MAYO!P14+#REF!+#REF!+#REF!+#REF!+#REF!+#REF!+#REF!) -> #REF! | Q14: =SUM(K14:P14) -> #REF!
A15: AMILASA | B15: =SUM(ENERO!B15+FEBRERO!B15+MARZO!B15+ABRIL!B15+MAYO!B15+#REF!+#REF!+#REF!+#REF!+#REF!+#REF!+#REF!) -> #REF! | C15: =SUM(ENERO!C15+FEBRERO!C15+MARZO!C15+ABRIL!C15+MAYO!C15+#REF!+#REF!+#REF!+#REF!+#REF!+#REF!+#REF!) -> #REF! | D15: =SUM(ENERO!D15+FEBRERO!D15+MARZO!D15+ABRIL!D15+MAYO!D15+#REF!+#REF!+#REF!+#REF!+#REF!+#REF!+#REF!) -> #REF! | E15: =SUM(ENERO!E15+FEBRERO!E15+MARZO!E15+ABRIL!E15+MAYO!E15+#REF!+#REF!+#REF!+#REF!+#REF!+#REF!+#REF!) -> #REF! | F15: =SUM(ENERO!F15+FEBRERO!F15+MARZO!F15+ABRIL!F15+MAYO!F15+#REF!+#REF!+#REF!+#REF!+#REF!+#REF!+#REF!) -> #REF! | G15: =SUM(ENERO!G15+FEBRERO!G15+MARZO!G15+ABRIL!G15+MAYO!G15+#REF!+#REF!+#REF!+#REF!+#REF!+#REF!+#REF!) -> #REF! | H15: =SUM(B15:G15) -> #REF! | J15: TOTAL PIEZA QUIRURGICA (HISTOLOGIA) | K15: =SUM(ENERO!K15+FEBRERO!K15+MARZO!K15+ABRIL!K15+MAYO!K15+#REF!+#REF!+#REF!+#REF!+#REF!+#REF!+#REF!) -> #REF! | L15: =SUM(ENERO!L15+FEBRERO!L15+MARZO!L15+ABRIL!L15+MAYO!L15+#REF!+#REF!+#REF!+#REF!+#REF!+#REF!+#REF!) -> #REF! | M15: =SUM(ENERO!M15+FEBRERO!M15+MARZO!M15+ABRIL!M15+MAYO!M15+#REF!+#REF!+#REF!+#REF!+#REF!+#REF!+#REF!) -> #REF! | N15: =SUM(ENERO!N15+FEBRERO!N15+MARZO!N15+ABRIL!N15+MAYO!N15+#REF!+#REF!+#REF!+#REF!+#REF!+#REF!+#REF!) -> #REF! | O15: =SUM(ENERO!O15+FEBRERO!O15+MARZO!O15+ABRIL!O15+MAYO!O15+#REF!+#REF!+#REF!+#REF!+#REF!+#REF!+#REF!) -> #REF! | P15: =SUM(ENERO!P15+FEBRERO!P15+MARZO!P15+ABRIL!P15+MAYO!P15+#REF!+#REF!+#REF!+#REF!+#REF!+#REF!+#REF!) -> #REF! | Q15: =SUM(K15:P15) -> #REF!
A16: GLUCOSA | B16: =SUM(ENERO!B16+FEBRERO!B16+MARZO!B16+ABRIL!B16+MAYO!B16+#REF!+#REF!+#REF!+#REF!+#REF!+#REF!+#REF!) -> #REF! | C16: =SUM(ENERO!C16+FEBRERO!C16+MARZO!C16+ABRIL!C16+MAYO!C16+#REF!+#REF!+#REF!+#REF!+#REF!+#REF!+#REF!) -> #REF! | D16: =SUM(ENERO!D16+FEBRERO!D16+MARZO!D16+ABRIL!D16+MAYO!D16+#REF!+#REF!+#REF!+#REF!+#REF!+#REF!+#REF!) -> #REF! | E16: =SUM(ENERO!E16+FEBRERO!E16+MARZO!E16+ABRIL!E16+MAYO!E16+#REF!+#REF!+#REF!+#REF!+#REF!+#REF!+#REF!) -> #REF! | F16: =SUM(ENERO!F16+FEBRERO!F16+MARZO!F16+ABRIL!F16+MAYO!F16+#REF!+#REF!+#REF!+#REF!+#REF!+#REF!+#REF!) -> #REF! | G16: =SUM(ENERO!G16+FEBRERO!G16+MARZO!G16+ABRIL!G16+MAYO!G16+#REF!+#REF!+#REF!+#REF!+#REF!+#REF!+#REF!) -> #REF! | H16: =SUM(B16:G16) -> #REF! | J16: TOTAL CITOLOGIA ESPECIAL | K16: =SUM(ENERO!K16+FEBRERO!K16+MARZO!K16+ABRIL!K16+MAYO!K16+#REF!+#REF!+#REF!+#REF!+#REF!+#REF!+#REF!) -> #REF! | L16: =SUM(ENERO!L16+FEBRERO!L16+MARZO!L16+ABRIL!L16+MAYO!L16+#REF!+#REF!+#REF!+#REF!+#REF!+#REF!+#REF!) -> #REF! | M16: =SUM(ENERO!M16+FEBRERO!M16+MARZO!M16+ABRIL!M16+MAYO!M16+#REF!+#REF!+#REF!+#REF!+#REF!+#REF!+#REF!) -> #REF! | N16: =SUM(ENERO!N16+FEBRERO!N16+MARZO!N16+ABRIL!N16+MAYO!N16+#REF!+#REF!+#REF!+#REF!+#REF!+#REF!+#REF!) -> #REF! | O16: =SUM(ENERO!O16+FEBRERO!O16+MARZO!O16+ABRIL!O16+MAYO!O16+#REF!+#REF!+#REF!+#REF!+#REF!+#REF!+#REF!) -> #REF! | P16: =SUM(ENERO!P16+FEBRERO!P16+MARZO!P16+ABRIL!P16+MAYO!P16+#REF!+#REF!+#REF!+#REF!+#REF!+#REF!+#REF!) -> #REF! | Q16: =SUM(K16:P16) -> #REF!
A17: GLUCOSA POST PRANDIAL | B17: =SUM(ENERO!B17+FEBRERO!B17+MARZO!B17+ABRIL!B17+MAYO!B17+#REF!+#REF!+#REF!+#REF!+#REF!+#REF!+#REF!) -> #REF! | C17: =SUM(ENERO!C17+FEBRERO!C17+MARZO!C17+ABRIL!C17+MAYO!C17+#REF!+#REF!+#REF!+#REF!+#REF!+#REF!+#REF!) -> #REF! | D17: =SUM(ENERO!D17+FEBRERO!D17+MARZO!D17+ABRIL!D17+MAYO!D17+#REF!+#REF!+#REF!+#REF!+#REF!+#REF!+#REF!) -> #REF! | E17: =SUM(ENERO!E17+FEBRERO!E17+MARZO!E17+ABRIL!E17+MAYO!E17+#REF!+#REF!+#REF!+#REF!+#REF!+#REF!+#REF!) -> #REF! | F17: =SUM(ENERO!F17+FEBRERO!F17+MARZO!F17+ABRIL!F17+MAYO!F17+#REF!+#REF!+#REF!+#REF!+#REF!+#REF!+#REF!) -> #REF! | G17: =SUM(ENERO!G17+FEBRERO!G17+MARZO!G17+ABRIL!G17+MAYO!G17+#REF!+#REF!+#REF!+#REF!+#REF!+#REF!+#REF!) -> #REF! | H17: =SUM(B17:G17) -> #REF! | J17: TOTAL DE TEJIDOS INCLUIDOS | K17: =SUM(ENERO!K17+FEBRERO!K17+MARZO!K17+ABRIL!K17+MAYO!K17+#REF!+#REF!+#REF!+#REF!+#REF!+#REF!+#REF!) -> #REF! | L17: =SUM(ENERO!L17+FEBRERO!L17+MARZO!L17+ABRIL!L17+MAYO!L17+#REF!+#REF!+#REF!+#REF!+#REF!+#REF!+#REF!) -> #REF! | M17: =SUM(ENERO!M17+FEBRERO!M17+MARZO!M17+ABRIL!M17+MAYO!M17+#REF!+#REF!+#REF!+#REF!+#REF!+#REF!+#REF!) -> #REF! | N17: =SUM(ENERO!N17+FEBRERO!N17+MARZO!N17+ABRIL!N17+MAYO!N17+#REF!+#REF!+#REF!+#REF!+#REF!+#REF!+#REF!) -> #REF! | O17: =SUM(ENERO!O17+FEBRERO!O17+MARZO!O17+ABRIL!O17+MAYO!O17+#REF!+#REF!+#REF!+#REF!+#REF!+#REF!+#REF!) -> #REF! | P17: =SUM(ENERO!P17+FEBRERO!P17+MARZO!P17+ABRIL!P17+MAYO!P17+#REF!+#REF!+#REF!+#REF!+#REF!+#REF!+#REF!) -> #REF! | Q17: =SUM(K17:P17) -> #REF!
A18: FOSFORO | B18: =SUM(ENERO!B18+FEBRERO!B18+MARZO!B18+ABRIL!B18+MAYO!B18+#REF!+#REF!+#REF!+#REF!+#REF!+#REF!+#REF!) -> #REF! | C18: =SUM(ENERO!C18+FEBRERO!C18+MARZO!C18+ABRIL!C18+MAYO!C18+#REF!+#REF!+#REF!+#REF!+#REF!+#REF!+#REF!) -> #REF! | D18: =SUM(ENERO!D18+FEBRERO!D18+MARZO!D18+ABRIL!D18+MAYO!D18+#REF!+#REF!+#REF!+#REF!+#REF!+#REF!+#REF!) -> #REF! | E18: =SUM(ENERO!E18+FEBRERO!E18+MARZO!E18+ABRIL!E18+MAYO!E18+#REF!+#REF!+#REF!+#REF!+#REF!+#REF!+#REF!) -> #REF! | F18: =SUM(ENERO!F18+FEBRERO!F18+MARZO!F18+ABRIL!F18+MAYO!F18+#REF!+#REF!+#REF!+#REF!+#REF!+#REF!+#REF!) -> #REF! | G18: =SUM(ENERO!G18+FEBRERO!G18+MARZO!G18+ABRIL!G18+MAYO!G18+#REF!+#REF!+#REF!+#REF!+#REF!+#REF!+#REF!) -> #REF! | H18: =SUM(B18:G18) -> #REF! | J18: TOTAL DE CORTES DE TEJIDOS | K18: =SUM(ENERO!K18+FEBRERO!K18+MARZO!K18+ABRIL!K18+MAYO!K18+#REF!+#REF!+#REF!+#REF!+#REF!+#REF!+#REF!) -> #REF! | L18: =SUM(ENERO!L18+FEBRERO!L18+MARZO!L18+ABRIL!L18+MAYO!L18+#REF!+#REF!+#REF!+#REF!+#REF!+#REF!+#REF!) -> #REF! | M18: =SUM(ENERO!M18+FEBRERO!M18+MARZO!M18+ABRIL!M18+MAYO!M18+#REF!+#REF!+#REF!+#REF!+#REF!+#REF!+#REF!) -> #REF! | N18: =SUM(ENERO!N18+FEBRERO!N18+MARZO!N18+ABRIL!N18+MAYO!N18+#REF!+#REF!+#REF!+#REF!+#REF!+#REF!+#REF!) -> #REF! | O18: =SUM(ENERO!O18+FEBRERO!O18+MARZO!O18+ABRIL!O18+MAYO!O18+#REF!+#REF!+#REF!+#REF!+#REF!+#REF!+#REF!) -> #REF! | P18: =SUM(ENERO!P18+FEBRERO!P18+MARZO!P18+ABRIL!P18+MAYO!P18+#REF!+#REF!+#REF!+#REF!+#REF!+#REF!+#REF!) -> #REF! | Q18: =SUM(K18:P18) -> #REF!
A19: HEMOGLOBINA GLICOSILADA | B19: =SUM(ENERO!B19+FEBRERO!B19+MARZO!B19+ABRIL!B19+MAYO!B19+#REF!+#REF!+#REF!+#REF!+#REF!+#REF!+#REF!) -> #REF! | C19: =SUM(ENERO!C19+FEBRERO!C19+MARZO!C19+ABRIL!C19+MAYO!C19+#REF!+#REF!+#REF!+#REF!+#REF!+#REF!+#REF!) -> #REF! | D19: =SUM(ENERO!D19+FEBRERO!D19+MARZO!D19+ABRIL!D19+MAYO!D19+#REF!+#REF!+#REF!+#REF!+#REF!+#REF!+#REF!) -> #REF! | E19: =SUM(ENERO!E19+FEBRERO!E19+MARZO!E19+ABRIL!E19+MAYO!E19+#REF!+#REF!+#REF!+#REF!+#REF!+#REF!+#REF!) -> #REF! | F19: =SUM(ENERO!F19+FEBRERO!F19+MARZO!F19+ABRIL!F19+MAYO!F19+#REF!+#REF!+#REF!+#REF!+#REF!+#REF!+#REF!) -> #REF! | G19: =SUM(ENERO!G19+FEBRERO!G19+MARZO!G19+ABRIL!G19+MAYO!G19+#REF!+#REF!+#REF!+#REF!+#REF!+#REF!+#REF!) -> #REF! | H19: =SUM(B19:G19) -> #REF! | J19: TOTAL DE LÁMINAS MONTADAS | K19: =SUM(ENERO!K19+FEBRERO!K19+MARZO!K19+ABRIL!K19+MAYO!K19+#REF!+#REF!+#REF!+#REF!+#REF!+#REF!+#REF!) -> #REF! | L19: =SUM(ENERO!L19+FEBRERO!L19+MARZO!L19+ABRIL!L19+MAYO!L19+#REF!+#REF!+#REF!+#REF!+#REF!+#REF!+#REF!) -> #REF! | M19: =SUM(ENERO!M19+FEBRERO!M19+MARZO!M19+ABRIL!M19+MAYO!M19+#REF!+#REF!+#REF!+#REF!+#REF!+#REF!+#REF!) -> #REF! | N19: =SUM(ENERO!N19+FEBRERO!N19+MARZO!N19+ABRIL!N19+MAYO!N19+#REF!+#REF!+#REF!+#REF!+#REF!+#REF!+#REF!) -> #REF! | O19: =SUM(ENERO!O19+FEBRERO!O19+MARZO!O19+ABRIL!O19+MAYO!O19+#REF!+#REF!+#REF!+#REF!+#REF!+#REF!+#REF!) -> #REF! | P19: =SUM(ENERO!P19+FEBRERO!P19+MARZO!P19+ABRIL!P19+MAYO!P19+#REF!+#REF!+#REF!+#REF!+#REF!+#REF!+#REF!) -> #REF! | Q19: =SUM(K19:P19) -> #REF!
A20: TOLERANCIA A LA GLUCOSA | B20: =SUM(ENERO!B20+FEBRERO!B20+MARZO!B20+ABRIL!B20+MAYO!B20+#REF!+#REF!+#REF!+#REF!+#REF!+#REF!+#REF!) -> #REF! | C20: =SUM(ENERO!C20+FEBRERO!C20+MARZO!C20+ABRIL!C20+MAYO!C20+#REF!+#REF!+#REF!+#REF!+#REF!+#REF!+#REF!) -> #REF! | D20: =SUM(ENERO!D20+FEBRERO!D20+MARZO!D20+ABRIL!D20+MAYO!D20+#REF!+#REF!+#REF!+#REF!+#REF!+#REF!+#REF!) -> #REF! | E20: =SUM(ENERO!E20+FEBRERO!E20+MARZO!E20+ABRIL!E20+MAYO!E20+#REF!+#REF!+#REF!+#REF!+#REF!+#REF!+#REF!) -> #REF! | F20: =SUM(ENERO!F20+FEBRERO!F20+MARZO!F20+ABRIL!F20+MAYO!F20+#REF!+#REF!+#REF!+#REF!+#REF!+#REF!+#REF!) -> #REF! | G20: =SUM(ENERO!G20+FEBRERO!G20+MARZO!G20+ABRIL!G20+MAYO!G20+#REF!+#REF!+#REF!+#REF!+#REF!+#REF!+#REF!) -> #REF! | H20: =SUM(B20:G20) -> #REF! | J20: TOTAL DE HISTOQUIMICA | K20: =SUM(ENERO!K20+FEBRERO!K20+MARZO!K20+ABRIL!K20+MAYO!K20+#REF!+#REF!+#REF!+#REF!+#REF!+#REF!+#REF!) -> #REF! | L20: =SUM(ENERO!L20+FEBRERO!L20+MARZO!L20+ABRIL!L20+MAYO!L20+#REF!+#REF!+#REF!+#REF!+#REF!+#REF!+#REF!) -> #REF! | M20: =SUM(ENERO!M20+FEBRERO!M20+MARZO!M20+ABRIL!M20+MAYO!M20+#REF!+#REF!+#REF!+#REF!+#REF!+#REF!+#REF!) -> #REF! | N20: =SUM(ENERO!N20+FEBRERO!N20+MARZO!N20+ABRIL!N20+MAYO!N20+#REF!+#REF!+#REF!+#REF!+#REF!+#REF!+#REF!) -> #REF! | O20: =SUM(ENERO!O20+FEBRERO!O20+MARZO!O20+ABRIL!O20+MAYO!O20+#REF!+#REF!+#REF!+#REF!+#REF!+#REF!+#REF!) -> #REF! | P20: =SUM(ENERO!P20+FEBRERO!P20+MARZO!P20+ABRIL!P20+MAYO!P20+#REF!+#REF!+#REF!+#REF!+#REF!+#REF!+#REF!) -> #REF! | Q20: =SUM(K20:P20) -> #REF!
A21: CREATININA | B21: =SUM(ENERO!B21+FEBRERO!B21+MARZO!B21+ABRIL!B21+MAYO!B21+#REF!+#REF!+#REF!+#REF!+#REF!+#REF!+#REF!) -> #REF! | C21: =SUM(ENERO!C21+FEBRERO!C21+MARZO!C21+ABRIL!C21+MAYO!C21+#REF!+#REF!+#REF!+#REF!+#REF!+#REF!+#REF!) -> #REF! | D21: =SUM(ENERO!D21+FEBRERO!D21+MARZO!D21+ABRIL!D21+MAYO!D21+#REF!+#REF!+#REF!+#REF!+#REF!+#REF!+#REF!) -> #REF! | E21: =SUM(ENERO!E21+FEBRERO!E21+MARZO!E21+ABRIL!E21+MAYO!E21+#REF!+#REF!+#REF!+#REF!+#REF!+#REF!+#REF!) -> #REF! | F21: =SUM(ENERO!F21+FEBRERO!F21+MARZO!F21+ABRIL!F21+MAYO!F21+#REF!+#REF!+#REF!+#REF!+#REF!+#REF!+#REF!) -> #REF! | G21: =SUM(ENERO!G21+FEBRERO!G21+MARZO!G21+ABRIL!G21+MAYO!G21+#REF!+#REF!+#REF!+#REF!+#REF!+#REF!+#REF!) -> #REF! | H21: =SUM(B21:G21) -> #REF! | J21: TOTAL DE INMUNOHISTOQUIMICA | K21: =SUM(ENERO!K21+FEBRERO!K21+MARZO!K21+ABRIL!K21+MAYO!K21+#REF!+#REF!+#REF!+#REF!+#REF!+#REF!+#REF!) -> #REF! | L21: =SUM(ENERO!L21+FEBRERO!L21+MARZO!L21+ABRIL!L21+MAYO!L21+#REF!+#REF!+#REF!+#REF!+#REF!+#REF!+#REF!) -> #REF! | M21: =SUM(ENERO!M21+FEBRERO!M21+MARZO!M21+ABRIL!M21+MAYO!M21+#REF!+#REF!+#REF!+#REF!+#REF!+#REF!+#REF!) -> #REF! | N21: =SUM(ENERO!N21+FEBRERO!N21+MARZO!N21+ABRIL!N21+MAYO!N21+#REF!+#REF!+#REF!+#REF!+#REF!+#REF!+#REF!) -> #REF! | O21: =SUM(ENERO!O21+FEBRERO!O21+MARZO!O21+ABRIL!O21+MAYO!O21+#REF!+#REF!+#REF!+#REF!+#REF!+#REF!+#REF!) -> #REF! | P21: =SUM(ENERO!P21+FEBRERO!P21+MARZO!P21+ABRIL!P21+MAYO!P21+#REF!+#REF!+#REF!+#REF!+#REF!+#REF!+#REF!) -> #REF! | Q21: =SUM(K21:P21) -> #REF!
A22: DEPURACION DE CREATININA | B22: =SUM(ENERO!B22+FEBRERO!B22+MARZO!B22+ABRIL!B22+MAYO!B22+#REF!+#REF!+#REF!+#REF!+#REF!+#REF!+#REF!) -> #REF! | C22: =SUM(ENERO!C22+FEBRERO!C22+MARZO!C22+ABRIL!C22+MAYO!C22+#REF!+#REF!+#REF!+#REF!+#REF!+#REF!+#REF!) -> #REF! | D22: =SUM(ENERO!D22+FEBRERO!D22+MARZO!D22+ABRIL!D22+MAYO!D22+#REF!+#REF!+#REF!+#REF!+#REF!+#REF!+#REF!) -> #REF! | E22: =SUM(ENERO!E22+FEBRERO!E22+MARZO!E22+ABRIL!E22+MAYO!E22+#REF!+#REF!+#REF!+#REF!+#REF!+#REF!+#REF!) -> #REF! | F22: =SUM(ENERO!F22+FEBRERO!F22+MARZO!F22+ABRIL!F22+MAYO!F22+#REF!+#REF!+#REF!+#REF!+#REF!+#REF!+#REF!) -> #REF! | G22: =SUM(ENERO!G22+FEBRERO!G22+MARZO!G22+ABRIL!G22+MAYO!G22+#REF!+#REF!+#REF!+#REF!+#REF!+#REF!+#REF!) -> #REF! | H22: =SUM(B22:G22) -> #REF! | J22: TOTAL AUTOPSIA MÉDICO LEGAL | K22: =SUM(ENERO!K22+FEBRERO!K22+MARZO!K22+ABRIL!K22+MAYO!K22+#REF!+#REF!+#REF!+#REF!+#REF!+#REF!+#REF!) -> #REF! | L22: =SUM(ENERO!L22+FEBRERO!L22+MARZO!L22+ABRIL!L22+MAYO!L22+#REF!+#REF!+#REF!+#REF!+#REF!+#REF!+#REF!) -> #REF! | M22: =SUM(ENERO!M22+FEBRERO!M22+MARZO!M22+ABRIL!M22+MAYO!M22+#REF!+#REF!+#REF!+#REF!+#REF!+#REF!+#REF!) -> #REF! | N22: =SUM(ENERO!N22+FEBRERO!N22+MARZO!N22+ABRIL!N22+MAYO!N22+#REF!+#REF!+#REF!+#REF!+#REF!+#REF!+#REF!) -> #REF! | O22: =SUM(ENERO!O22+FEBRERO!O22+MARZO!O22+ABRIL!O22+MAYO!O22+#REF!+#REF!+#REF!+#REF!+#REF!+#REF!+#REF!) -> #REF! | P22: =SUM(ENERO!P22+FEBRERO!P22+MARZO!P22+ABRIL!P22+MAYO!P22+#REF!+#REF!+#REF!+#REF!+#REF!+#REF!+#REF!) -> #REF! | Q22: =SUM(K22:P22) -> #REF!
A23: MICROALBUMINURIA | B23: =SUM(ENERO!B23+FEBRERO!B23+MARZO!B23+ABRIL!B23+MAYO!B23+#REF!+#REF!+#REF!+#REF!+#REF!+#REF!+#REF!) -> #REF! | C23: =SUM(ENERO!C23+FEBRERO!C23+MARZO!C23+ABRIL!C23+MAYO!C23+#REF!+#REF!+#REF!+#REF!+#REF!+#REF!+#REF!) -> #REF! | D23: =SUM(ENERO!D23+FEBRERO!D23+MARZO!D23+ABRIL!D23+MAYO!D23+#REF!+#REF!+#REF!+#REF!+#REF!+#REF!+#REF!) -> #REF! | E23: =SUM(ENERO!E23+FEBRERO!E23+MARZO!E23+ABRIL!E23+MAYO!E23+#REF!+#REF!+#REF!+#REF!+#REF!+#REF!+#REF!) -> #REF! | F23: =SUM(ENERO!F23+FEBRERO!F23+MARZO!F23+ABRIL!F23+MAYO!F23+#REF!+#REF!+#REF!+#REF!+#REF!+#REF!+#REF!) -> #REF! | G23: =SUM(ENERO!G23+FEBRERO!G23+MARZO!G23+ABRIL!G23+MAYO!G23+#REF!+#REF!+#REF!+#REF!+#REF!+#REF!+#REF!) -> #REF! | H23: =SUM(B23:G23) -> #REF! | J23: TOTAL AUTOPSIA CLÍNICA | K23: =SUM(ENERO!K23+FEBRERO!K23+MARZO!K23+ABRIL!K23+MAYO!K23+#REF!+#REF!+#REF!+#REF!+#REF!+#REF!+#REF!) -> #REF! | L23: =SUM(ENERO!L23+FEBRERO!L23+MARZO!L23+ABRIL!L23+MAYO!L23+#REF!+#REF!+#REF!+#REF!+#REF!+#REF!+#REF!) -> #REF! | M23: =SUM(ENERO!M23+FEBRERO!M23+MARZO!M23+ABRIL!M23+MAYO!M23+#REF!+#REF!+#REF!+#REF!+#REF!+#REF!+#REF!) -> #REF! | N23: =SUM(ENERO!N23+FEBRERO!N23+MARZO!N23+ABRIL!N23+MAYO!N23+#REF!+#REF!+#REF!+#REF!+#REF!+#REF!+#REF!) -> #REF! | O23: =SUM(ENERO!O23+FEBRERO!O23+MARZO!O23+ABRIL!O23+MAYO!O23+#REF!+#REF!+#REF!+#REF!+#REF!+#REF!+#REF!) -> #REF! | P23: =SUM(ENERO!P23+FEBRERO!P23+MARZO!P23+ABRIL!P23+MAYO!P23+#REF!+#REF!+#REF!+#REF!+#REF!+#REF!+#REF!) -> #REF! | Q23: =SUM(K23:P23) -> #REF!
A24: UREA | B24: =SUM(ENERO!B24+FEBRERO!B24+MARZO!B24+ABRIL!B24+MAYO!B24+#REF!+#REF!+#REF!+#REF!+#REF!+#REF!+#REF!) -> #REF! | C24: =SUM(ENERO!C24+FEBRERO!C24+MARZO!C24+ABRIL!C24+MAYO!C24+#REF!+#REF!+#REF!+#REF!+#REF!+#REF!+#REF!) -> #REF! | D24: =SUM(ENERO!D24+FEBRERO!D24+MARZO!D24+ABRIL!D24+MAYO!D24+#REF!+#REF!+#REF!+#REF!+#REF!+#REF!+#REF!) -> #REF! | E24: =SUM(ENERO!E24+FEBRERO!E24+MARZO!E24+ABRIL!E24+MAYO!E24+#REF!+#REF!+#REF!+#REF!+#REF!+#REF!+#REF!) -> #REF! | F24: =SUM(ENERO!F24+FEBRERO!F24+MARZO!F24+ABRIL!F24+MAYO!F24+#REF!+#REF!+#REF!+#REF!+#REF!+#REF!+#REF!) -> #REF! | G24: =SUM(ENERO!G24+FEBRERO!G24+MARZO!G24+ABRIL!G24+MAYO!G24+#REF!+#REF!+#REF!+#REF!+#REF!+#REF!+#REF!) -> #REF! | H24: =SUM(B24:G24) -> #REF!
A25: PROTEINURIA 24 HORAS | B25: =SUM(ENERO!B25+FEBRERO!B25+MARZO!B25+ABRIL!B25+MAYO!B25+#REF!+#REF!+#REF!+#REF!+#REF!+#REF!+#REF!) -> #REF! | C25: =SUM(ENERO!C25+FEBRERO!C25+MARZO!C25+ABRIL!C25+MAYO!C25+#REF!+#REF!+#REF!+#REF!+#REF!+#REF!+#REF!) -> #REF! | D25: =SUM(ENERO!D25+FEBRERO!D25+MARZO!D25+ABRIL!D25+MAYO!D25+#REF!+#REF!+#REF!+#REF!+#REF!+#REF!+#REF!) -> #REF! | E25: =SUM(ENERO!E25+FEBRERO!E25+MARZO!E25+ABRIL!E25+MAYO!E25+#REF!+#REF!+#REF!+#REF!+#REF!+#REF!+#REF!) -> #REF! | F25: =SUM(ENERO!F25+FEBRERO!F25+MARZO!F25+ABRIL!F25+MAYO!F25+#REF!+#REF!+#REF!+#REF!+#REF!+#REF!+#REF!) -> #REF! | G25: =SUM(ENERO!G25+FEBRERO!G25+MARZO!G25+ABRIL!G25+MAYO!G25+#REF!+#REF!+#REF!+#REF!+#REF!+#REF!+#REF!) -> #REF! | H25: =SUM(B25:G25) -> #REF!
A26: BILIRRUBINA TOTAL | B26: =SUM(ENERO!B26+FEBRERO!B26+MARZO!B26+ABRIL!B26+MAYO!B26+#REF!+#REF!+#REF!+#REF!+#REF!+#REF!+#REF!) -> #REF! | C26: =SUM(ENERO!C26+FEBRERO!C26+MARZO!C26+ABRIL!C26+MAYO!C26+#REF!+#REF!+#REF!+#REF!+#REF!+#REF!+#REF!) -> #REF! | D26: =SUM(ENERO!D26+FEBRERO!D26+MARZO!D26+ABRIL!D26+MAYO!D26+#REF!+#REF!+#REF!+#REF!+#REF!+#REF!+#REF!) -> #REF! | E26: =SUM(ENERO!E26+FEBRERO!E26+MARZO!E26+ABRIL!E26+MAYO!E26+#REF!+#REF!+#REF!+#REF!+#REF!+#REF!+#REF!) -> #REF! | F26: =SUM(ENERO!F26+FEBRERO!F26+MARZO!F26+ABRIL!F26+MAYO!F26+#REF!+#REF!+#REF!+#REF!+#REF!+#REF!+#REF!) -> #REF! | G26: =SUM(ENERO!G26+FEBRERO!G26+MARZO!G26+ABRIL!G26+MAYO!G26+#REF!+#REF!+#REF!+#REF!+#REF!+#REF!+#REF!) -> #REF! | H26: =SUM(B26:G26) -> #REF! | J26: PROGRAMAS / METAXENICAS | K26: TOTAL
A27: BILIRRUBINA DIRECTA | B27: =SUM(ENERO!B27+FEBRERO!B27+MARZO!B27+ABRIL!B27+MAYO!B27+#REF!+#REF!+#REF!+#REF!+#REF!+#REF!+#REF!) -> #REF! | C27: =SUM(ENERO!C27+FEBRERO!C27+MARZO!C27+ABRIL!C27+MAYO!C27+#REF!+#REF!+#REF!+#REF!+#REF!+#REF!+#REF!) -> #REF! | D27: =SUM(ENERO!D27+FEBRERO!D27+MARZO!D27+ABRIL!D27+MAYO!D27+#REF!+#REF!+#REF!+#REF!+#REF!+#REF!+#REF!) -> #REF! | E27: =SUM(ENERO!E27+FEBRERO!E27+MARZO!E27+ABRIL!E27+MAYO!E27+#REF!+#REF!+#REF!+#REF!+#REF!+#REF!+#REF!) -> #REF! | F27: =SUM(ENERO!F27+FEBRERO!F27+MARZO!F27+ABRIL!F27+MAYO!F27+#REF!+#REF!+#REF!+#REF!+#REF!+#REF!+#REF!) -> #REF! | G27: =SUM(ENERO!G27+FEBRERO!G27+MARZO!G27+ABRIL!G27+MAYO!G27+#REF!+#REF!+#REF!+#REF!+#REF!+#REF!+#REF!) -> #REF! | H27: =SUM(B27:G27) -> #REF! | K27: Hospitaliz | L27: Emergenc | M27: Programa | N27: Privado | O27: Convenio | P27: Insolvencia | Q27: TOTAL
A28: PROTEINAS TOTAL | B28: =SUM(ENERO!B28+FEBRERO!B28+MARZO!B28+ABRIL!B28+MAYO!B28+#REF!+#REF!+#REF!+#REF!+#REF!+#REF!+#REF!) -> #REF! | C28: =SUM(ENERO!C28+FEBRERO!C28+MARZO!C28+ABRIL!C28+MAYO!C28+#REF!+#REF!+#REF!+#REF!+#REF!+#REF!+#REF!) -> #REF! | D28: =SUM(ENERO!D28+FEBRERO!D28+MARZO!D28+ABRIL!D28+MAYO!D28+#REF!+#REF!+#REF!+#REF!+#REF!+#REF!+#REF!) -> #REF! | E28: =SUM(ENERO!E28+FEBRERO!E28+MARZO!E28+ABRIL!E28+MAYO!E28+#REF!+#REF!+#REF!+#REF!+#REF!+#REF!+#REF!) -> #REF! | F28: =SUM(ENERO!F28+FEBRERO!F28+MARZO!F28+ABRIL!F28+MAYO!F28+#REF!+#REF!+#REF!+#REF!+#REF!+#REF!+#REF!) -> #REF! | G28: =SUM(ENERO!G28+FEBRERO!G28+MARZO!G28+ABRIL!G28+MAYO!G28+#REF!+#REF!+#REF!+#REF!+#REF!+#REF!+#REF!) -> #REF! | H28: =SUM(B28:G28) -> #REF! | J28: TOTAL DE EXAMENES | K28: =SUM(K29:K37) -> #REF! | L28: =SUM(L29:L37) -> #REF! | M28: =SUM(M29:M37) -> #REF! | N28: =SUM(N29:N37) -> #REF! | O28: =SUM(O29:O37) -> #REF! | P28: =SUM(P29:P37) -> #REF! | Q28: =SUM(K28:P28) -> #REF!
A29: ALBUMINA | B29: =SUM(ENERO!B29+FEBRERO!B29+MARZO!B29+ABRIL!B29+MAYO!B29+#REF!+#REF!+#REF!+#REF!+#REF!+#REF!+#REF!) -> #REF! | C29: =SUM(ENERO!C29+FEBRERO!C29+MARZO!C29+ABRIL!C29+MAYO!C29+#REF!+#REF!+#REF!+#REF!+#REF!+#REF!+#REF!) -> #REF! | D29: =SUM(ENERO!D29+FEBRERO!D29+MARZO!D29+ABRIL!D29+MAYO!D29+#REF!+#REF!+#REF!+#REF!+#REF!+#REF!+#REF!) -> #REF! | E29: =SUM(ENERO!E29+FEBRERO!E29+MARZO!E29+ABRIL!E29+MAYO!E29+#REF!+#REF!+#REF!+#REF!+#REF!+#REF!+#REF!) -> #REF! | F29: =SUM(ENERO!F29+FEBRERO!F29+MARZO!F29+ABRIL!F29+MAYO!F29+#REF!+#REF!+#REF!+#REF!+#REF!+#REF!+#REF!) -> #REF! | G29: =SUM(ENERO!G29+FEBRERO!G29+MARZO!G29+ABRIL!G29+MAYO!G29+#REF!+#REF!+#REF!+#REF!+#REF!+#REF!+#REF!) -> #REF! | H29: =SUM(B29:G29) -> #REF! | J29: TUBERCULOSIS | K29: =SUM(ENERO!K29+FEBRERO!K29+MARZO!K29+ABRIL!K29+MAYO!K29+#REF!+#REF!+#REF!+#REF!+#REF!+#REF!+#REF!) -> #REF! | L29: =SUM(ENERO!L29+FEBRERO!L29+MARZO!L29+ABRIL!L29+MAYO!L29+#REF!+#REF!+#REF!+#REF!+#REF!+#REF!+#REF!) -> #REF! | M29: =SUM(ENERO!M29+FEBRERO!M29+MARZO!M29+ABRIL!M29+MAYO!M29+#REF!+#REF!+#REF!+#REF!+#REF!+#REF!+#REF!) -> #REF! | N29: =SUM(ENERO!N29+FEBRERO!N29+MARZO!N29+ABRIL!N29+MAYO!N29+#REF!+#REF!+#REF!+#REF!+#REF!+#REF!+#REF!) -> #REF! | O29: =SUM(ENERO!O29+FEBRERO!O29+MARZO!O29+ABRIL!O29+MAYO!O29+#REF!+#REF!+#REF!+#REF!+#REF!+#REF!+#REF!) -> #REF! | P29: =SUM(ENERO!P29+FEBRERO!P29+MARZO!P29+ABRIL!P29+MAYO!P29+#REF!+#REF!+#REF!+#REF!+#REF!+#REF!+#REF!) -> #REF! | Q29: =SUM(K29:P29) -> #REF!
A30: TGO | B30: =SUM(ENERO!B30+FEBRERO!B30+MARZO!B30+ABRIL!B30+MAYO!B30+#REF!+#REF!+#REF!+#REF!+#REF!+#REF!+#REF!) -> #REF! | C30: =SUM(ENERO!C30+FEBRERO!C30+MARZO!C30+ABRIL!C30+MAYO!C30+#REF!+#REF!+#REF!+#REF!+#REF!+#REF!+#REF!) -> #REF! | D30: =SUM(ENERO!D30+FEBRERO!D30+MARZO!D30+ABRIL!D30+MAYO!D30+#REF!+#REF!+#REF!+#REF!+#REF!+#REF!+#REF!) -> #REF! | E30: =SUM(ENERO!E30+FEBRERO!E30+MARZO!E30+ABRIL!E30+MAYO!E30+#REF!+#REF!+#REF!+#REF!+#REF!+#REF!+#REF!) -> #REF! | F30: =SUM(ENERO!F30+FEBRERO!F30+MARZO!F30+ABRIL!F30+MAYO!F30+#REF!+#REF!+#REF!+#REF!+#REF!+#REF!+#REF!) -> #REF! | G30: =SUM(ENERO!G30+FEBRERO!G30+MARZO!G30+ABRIL!G30+MAYO!G30+#REF!+#REF!+#REF!+#REF!+#REF!+#REF!+#REF!) -> #REF! | H30: =SUM(B30:G30) -> #REF! | J30: LEISHMANIA | K30: =SUM(ENERO!K30+FEBRERO!K30+MARZO!K30+ABRIL!K30+MAYO!K30+#REF!+#REF!+#REF!+#REF!+#REF!+#REF!+#REF!) -> #REF! | L30: =SUM(ENERO!L30+FEBRERO!L30+MARZO!L30+ABRIL!L30+MAYO!L30+#REF!+#REF!+#REF!+#REF!+#REF!+#REF!+#REF!) -> #REF! | M30: =SUM(ENERO!M30+FEBRERO!M30+MARZO!M30+ABRIL!M30+MAYO!M30+#REF!+#REF!+#REF!+#REF!+#REF!+#REF!+#REF!) -> #REF! | N30: =SUM(ENERO!N30+FEBRERO!N30+MARZO!N30+ABRIL!N30+MAYO!N30+#REF!+#REF!+#REF!+#REF!+#REF!+#REF!+#REF!) -> #REF! | O30: =SUM(ENERO!O30+FEBRERO!O30+MARZO!O30+ABRIL!O30+MAYO!O30+#REF!+#REF!+#REF!+#REF!+#REF!+#REF!+#REF!) -> #REF! | P30: =SUM(ENERO!P30+FEBRERO!P30+MARZO!P30+ABRIL!P30+MAYO!P30+#REF!+#REF!+#REF!+#REF!+#REF!+#REF!+#REF!) -> #REF! | Q30: =SUM(K30:P30) -> #REF!
A31: TGP | B31: =SUM(ENERO!B31+FEBRERO!B31+MARZO!B31+ABRIL!B31+MAYO!B31+#REF!+#REF!+#REF!+#REF!+#REF!+#REF!+#REF!) -> #REF! | C31: =SUM(ENERO!C31+FEBRERO!C31+MARZO!C31+ABRIL!C31+MAYO!C31+#REF!+#REF!+#REF!+#REF!+#REF!+#REF!+#REF!) -> #REF! | D31: =SUM(ENERO!D31+FEBRERO!D31+MARZO!D31+ABRIL!D31+MAYO!D31+#REF!+#REF!+#REF!+#REF!+#REF!+#REF!+#REF!) -> #REF! | E31: =SUM(ENERO!E31+FEBRERO!E31+MARZO!E31+ABRIL!E31+MAYO!E31+#REF!+#REF!+#REF!+#REF!+#REF!+#REF!+#REF!) -> #REF! | F31: =SUM(ENERO!F31+FEBRERO!F31+MARZO!F31+ABRIL!F31+MAYO!F31+#REF!+#REF!+#REF!+#REF!+#REF!+#REF!+#REF!) -> #REF! | G31: =SUM(ENERO!G31+FEBRERO!G31+MARZO!G31+ABRIL!G31+MAYO!G31+#REF!+#REF!+#REF!+#REF!+#REF!+#REF!+#REF!) -> #REF! | H31: =SUM(B31:G31) -> #REF! | J31: PROGRAMA LEPRAE | K31: =SUM(ENERO!K31+FEBRERO!K31+MARZO!K31+ABRIL!K31+MAYO!K31+#REF!+#REF!+#REF!+#REF!+#REF!+#REF!+#REF!) -> #REF! | L31: =SUM(ENERO!L31+FEBRERO!L31+MARZO!L31+ABRIL!L31+MAYO!L31+#REF!+#REF!+#REF!+#REF!+#REF!+#REF!+#REF!) -> #REF! | M31: =SUM(ENERO!M31+FEBRERO!M31+MARZO!M31+ABRIL!M31+MAYO!M31+#REF!+#REF!+#REF!+#REF!+#REF!+#REF!+#REF!) -> #REF! | N31: =SUM(ENERO!N31+FEBRERO!N31+MARZO!N31+ABRIL!N31+MAYO!N31+#REF!+#REF!+#REF!+#REF!+#REF!+#REF!+#REF!) -> #REF! | O31: =SUM(ENERO!O31+FEBRERO!O31+MARZO!O31+ABRIL!O31+MAYO!O31+#REF!+#REF!+#REF!+#REF!+#REF!+#REF!+#REF!) -> #REF! | P31: =SUM(ENERO!P31+FEBRERO!P31+MARZO!P31+ABRIL!P31+MAYO!P31+#REF!+#REF!+#REF!+#REF!+#REF!+#REF!+#REF!) -> #REF! | Q31: =SUM(K31:P31) -> #REF!
A32: GGTP | B32: =SUM(ENERO!B32+FEBRERO!B32+MARZO!B32+ABRIL!B32+MAYO!B32+#REF!+#REF!+#REF!+#REF!+#REF!+#REF!+#REF!) -> #REF! | C32: =SUM(ENERO!C32+FEBRERO!C32+MARZO!C32+ABRIL!C32+MAYO!C32+#REF!+#REF!+#REF!+#REF!+#REF!+#REF!+#REF!) -> #REF! | D32: =SUM(ENERO!D32+FEBRERO!D32+MARZO!D32+ABRIL!D32+MAYO!D32+#REF!+#REF!+#REF!+#REF!+#REF!+#REF!+#REF!) -> #REF! | E32: =SUM(ENERO!E32+FEBRERO!E32+MARZO!E32+ABRIL!E32+MAYO!E32+#REF!+#REF!+#REF!+#REF!+#REF!+#REF!+#REF!) -> #REF! | F32: =SUM(ENERO!F32+FEBRERO!F32+MARZO!F32+ABRIL!F32+MAYO!F32+#REF!+#REF!+#REF!+#REF!+#REF!+#REF!+#REF!) -> #REF! | G32: =SUM(ENERO!G32+FEBRERO!G32+MARZO!G32+ABRIL!G32+MAYO!G32+#REF!+#REF!+#REF!+#REF!+#REF!+#REF!+#REF!) -> #REF! | H32: =SUM(B32:G32) -> #REF! | J32: MALARIA | K32: =SUM(ENERO!K32+FEBRERO!K32+MARZO!K32+ABRIL!K32+MAYO!K32+#REF!+#REF!+#REF!+#REF!+#REF!+#REF!+#REF!) -> #REF! | L32: =SUM(ENERO!L32+FEBRERO!L32+MARZO!L32+ABRIL!L32+MAYO!L32+#REF!+#REF!+#REF!+#REF!+#REF!+#REF!+#REF!) -> #REF! | M32: =SUM(ENERO!M32+FEBRERO!M32+MARZO!M32+ABRIL!M32+MAYO!M32+#REF!+#REF!+#REF!+#REF!+#REF!+#REF!+#REF!) -> #REF! | N32: =SUM(ENERO!N32+FEBRERO!N32+MARZO!N32+ABRIL!N32+MAYO!N32+#REF!+#REF!+#REF!+#REF!+#REF!+#REF!+#REF!) -> #REF! | O32: =SUM(ENERO!O32+FEBRERO!O32+MARZO!O32+ABRIL!O32+MAYO!O32+#REF!+#REF!+#REF!+#REF!+#REF!+#REF!+#REF!) -> #REF! | P32: =SUM(ENERO!P32+FEBRERO!P32+MARZO!P32+ABRIL!P32+MAYO!P32+#REF!+#REF!+#REF!+#REF!+#REF!+#REF!+#REF!) -> #REF! | Q32: =SUM(K32:P32) -> #REF!
