Workbook

Sheet ENERO
A4: Establecimiento de Salud informante: | B4: HOSPITAL REGIONAL DE LORETO | K4: Mes: | L4: ENERO
A6: Código Renaes: | B6: 3 | K6: Año: | L6: 2025
A9: PATOLOGÍA CLÍNICA | B9: TOTAL | J9: ANATOMÍA PATOLÓGICA | K9: TOTAL
B10: Hospitaliz | C10: Emergenc | D10: C. Externa | E10: Privado | F10: Convenio | G10: Insolvencia | H10: TOTAL | K10: Hospitaliz | L10: Emergenc | M10: C. Externa | N10: Privado | O10: Convenio | P10: Insolvencia | Q10: TOTAL
A11: TOTAL DE EXAMENES LABORATORIO | B11: =B12+B51+B69+B82+B95 -> 15115 | C11: =C12+C51+C69+C82+C95 -> 18132 | D11: =D12+D51+D69+D82+D95 -> 13395 | E11: =E12+E51+E69+E82+E95 -> 1085 | F11: =F12+F51+F69+F82+F95 -> 512 | G11: =G12+G51+G69+G82+G95 -> 0 | H11: =SUM(B11:G11) -> 48239 | J11: TOTAL EXAMENES ANATOMIA PATOLOGICA | K11: =SUM(K12:K23) -> 322 | L11: =SUM(L12:L23) -> 0 | M11: =SUM(M12:M23) -> 691 | N11: =SUM(N12:N23) -> 4 | O11: =SUM(O12:O23) -> 0 | P11: =SUM(P12:P23) -> 0 | Q11: =SUM(K11:P11) -> 1017
A12: TOTAL EXAMENES BIOQUÍMICOS | B12: =SUM(B13:B50) -> 8489 | C12: =SUM(C13:C50) -> 11118 | D12: =SUM(D13:D50) -> 7826 | E12: =SUM(E13:E50) -> 621 | F12: =SUM(F13:F50) -> 318 | G12: =SUM(G13:G50) -> 0 | H12: =SUM(B12:G12) -> 28372 | J12: TOTAL EXAMENES CITOLÓGICOS (PAP) | K12: 0 | L12: 0 | M12: 10 | N12: 1 | O12: 0 | P12: 0 | Q12: =SUM(K12:P12) -> 11
A13: ACIDO URICO | B13: 1 | C13: 0 | D13: 3 | E13: 7 | F13: 4 | G13: 0 | H13: =SUM(B13:G13) -> 15 | J13: TOTAL BAAF | K13: 0 | L13: 0 | M13: 10 | N13: 0 | O13: 0 | P13: 0 | Q13: =SUM(K13:P13) -> 10
A14: CALCIO | B14: 37 | C14: 1 | D14: 40 | E14: 3 | F14: 1 | G14: 0 | H14: =SUM(B14:G14) -> 82 | J14: TOTAL EXAMENES HISTOPATOLÓGICOS (Biopsia) | K14: 2 | L14: 0 | M14: 20 | N14: 2 | O14: 0 | P14: 0 | Q14: =SUM(K14:P14) -> 24
A15: AMILASA | B15: 18 | C15: 134 | D15: 12 | E15: 6 | F15: 0 | G15: 0 | H15: =SUM(B15:G15) -> 170 | J15: TOTAL PIEZA QUIRURGICA (HISTOLOGIA) | K15: 54 | L15: 0 | M15: 30 | N15: 1 | O15: 0 | P15: 0 | Q15: =SUM(K15:P15) -> 85
A16: GLUCOSA | B16: 750 | C16: 1554 | D16: 860 | E16: 63 | F16: 39 | G16: 0 | H16: =SUM(B16:G16) -> 3266 | J16: TOTAL CITOLOGIA ESPECIAL | K16: 0 | L16: 0 | M16: 5 | N16: 0 | O16: 0 | P16: 0 | Q16: =SUM(K16:P16) -> 5
A17: GLUCOSA POST PRANDIAL | B17: 0 | C17: 0 | D17: 10 | E17: 0 | F17: 1 | G17: 0 | H17: =SUM(B17:G17) -> 11 | J17: TOTAL DE TEJIDOS INCLUIDOS | K17: 86 | L17: 0 | M17: 200 | N17: 0 | O17: 0 | P17: 0 | Q17: =SUM(K17:P17) -> 286
A18: FOSFORO | B18: 18 | C18: 1 | D18: 19 | E18: 2 | F18: 0 | G18: 0 | H18: =SUM(B18:G18) -> 40 | J18: TOTAL DE CORTES DE TEJIDOS | K18: 90 | L18: 0 | M18: 200 | N18: 0 | O18: 0 | P18: 0 | Q18: =SUM(K18:P18) -> 290
A19: HEMOGLOBINA GLICOSILADA | B19: 97 | C19: 11 | D19: 177 | E19: 11 | F19: 14 | G19: 0 | H19: =SUM(B19:G19) -> 310 | J19: TOTAL DE LÁMINAS MONTADAS | K19: 90 | L19: 0 | M19: 200 | N19: 0 | O19: 0 | P19: 0 | Q19: =SUM(K19:P19) -> 290
A20: TOLERANCIA A LA GLUCOSA | B20: 0 | C20: 0 | D20: 10 | E20: 4 | F20: 2 | G20: 0 | H20: =SUM(B20:G20) -> 16 | J20: TOTAL DE HISTOQUIMICA | K20: 0 | L20: 0 | M20: 16 | N20: 0 | O20: 0 | P20: 0 | Q20: =SUM(K20:P20) -> 16
A21: CREATININA | B21: 806 | C21: 1589 | D21: 810 | E21: 63 | F21: 39 | G21: 0 | H21: =SUM(B21:G21) -> 3307 | J21: TOTAL DE INMUNOHISTOQUIMICA
A22: DEPURACION DE CREATININA | B22: 8 | C22: 0 | D22: 7 | E22: 0 | F22: 2 | G22: 0 | H22: =SUM(B22:G22) -> 17 | J22: TOTAL AUTOPSIA MÉDICO LEGAL | K22: 0 | L22: 0 | M22: 0 | N22: 0 | O22: 0 | P22: 0 | Q22: =SUM(K22:P22) -> 0
A23: MICROALBUMINURIA | J23: TOTAL AUTOPSIA CLÍNICA | K23: 0 | L23: 0 | M23: 0 | N23: 0 | O23: 0 | P23: 0 | Q23: =SUM(K23:P23) -> 0
A24: UREA | B24: 827 | C24: 1587 | D24: 792 | E24: 58 | F24: 39 | G24: 0 | H24: =SUM(B24:G24) -> 3303
A25: PROTEINURIA 24 HORAS | B25: 60 | C25: 8 | D25: 81 | E25: 7 | F25: 2 | G25: 0 | H25: =SUM(B25:G25) -> 158
A26: BILIRRUBINA TOTAL | B26: 608 | C26: 500 | D26: 302 | E26: 26 | F26: 10 | G26: 0 | H26: =SUM(B26:G26) -> 1446 | J26: PROGRAMAS / METAXENICAS | K26: TOTAL
A27: BILIRRUBINA DIRECTA | B27: 608 | C27: 500 | D27: 302 | E27: 26 | F27: 10 | G27: 0 | H27: =SUM(B27:G27) -> 1446 | K27: Hospitaliz | L27: Emergenc | M27: C. Externa | N27: Privado | O27: Convenio | P27: Insolvencia | Q27: TOTAL
A28: PROTEINAS TOTAL | B28: 563 | C28: 547 | D28: 380 | E28: 31 | F28: 13 | G28: 0 | H28: =SUM(B28:G28) -> 1534 | J28: TOTAL DE EXAMENES | K28: =SUM(K29:K37) -> 172 | L28: =SUM(L29:L37) -> 491 | M28: =SUM(M29:M37) -> 274 | N28: =SUM(N29:N37) -> 0 | O28: =SUM(O29:O37) -> 0 | P28: =SUM(P29:P37) -> 0 | Q28: =SUM(K28:P28) -> 937
A29: ALBUMINA | B29: 560 | C29: 539 | D29: 375 | E29: 8 | F29: 0 | G29: 0 | H29: =SUM(B29:G29) -> 1482 | J29: TUBERCULOSIS | K29: 168 | L29: 41 | M29: 126 | N29: 0 | O29: 0 | P29: 0 | Q29: =SUM(K29:P29) -> 335
A30: TGO | B30: 593 | C30: 606 | D30: 586 | E30: 44 | F30: 20 | G30: 0 | H30: =SUM(B30:G30) -> 1849 | J30: LEISHMANIA | K30: 0 | L30: 0 | M30: 0 | N30: 0 | O30: 0 | P30: 0 | Q30: =SUM(K30:P30) -> 0
A31: TGP | B31: 593 | C31: 606 | D31: 580 | E31: 43 | F31: 20 | G31: 0 | H31: =SUM(B31:G31) -> 1842 | J31: PROGRAMA LEPRAE | K31: 0 | L31: 0 | M31: 20 | N31: 0 | O31: 0 | P31: 0 | Q31: =SUM(K31:P31) -> 20
A32: GGTP | B32: 0 | C32: 0 | D32: 2 | E32: 3 | F32: 1 | G32: 0 | H32: =SUM(B32:G32) -> 6 | J32: MALARIA | K32: 0 | L32: 274 | M32: 65 | N32: 0 | O32: 0 | P32: 0 | Q32: =SUM(K32:P32) -> 339
A33: LACTATO DESHIDROGENASA (DHL) | B33: 244 | C33: 179 | D33: 73 | E33: 3 | F33: 2 | G33: 0 | H33: =SUM(B33:G33) -> 501 | J33: METAXENICAS (REFERENCIAL) | K33: 0 | L33: 0 | M33: 40 | N33: 0 | O33: 0 | P33: 0 | Q33: =SUM(K33:P33) -> 40
A34: PROTEINA C REACTIVA (CUANTITATIVO) | B34: 887 | C34: 1210 | D34: 710 | E34: 40 | F34: 6 | G34: 0 | H34: =SUM(B34:G34) -> 2853 | J34: CULTIVO DE TB (REFERENCIAL) | K34: 0 | L34: 0 | M34: 22 | N34: 0 | O34: 0 | P34: 0 | Q34: =SUM(K34:P34) -> 22
A35: FOSFATASA ALCALINA | B35: 419 | C35: 363 | D35: 310 | E35: 24 | F35: 9 | G35: 0 | H35: =SUM(B35:G35) -> 1125 | J35: PRUEBA RAPIDA DE DENGUE | K35: 1 | L35: 124 | M35: 1 | N35: 0 | O35: 0 | P35: 0 | Q35: =SUM(K35:P35) -> 126
A36: CPK TOTAL | B36: 0 | C36: 0 | D36: 0 | E36: 0 | F36: 0 | G36: 0 | H36: =SUM(B36:G36) -> 0 | J36: PRUEBA RÁPIDA DE LEPTOSPIRA | K36: 3 | L36: 17 | M36: 0 | N36: 0 | O36: 0 | P36: 0 | Q36: =SUM(K36:P36) -> 20
A37: CPK MB | B37: 5 | C37: 17 | D37: 2 | E37: 1 | F37: 0 | G37: 0 | H37: =SUM(B37:G37) -> 25 | J37: PRUEBA RAPIDA DE COVID + INFLUENZA | K37: 0 | L37: 35 | M37: 0 | N37: 0 | O37: 0 | P37: 0 | Q37: =SUM(K37:P37) -> 35
A38: COLESTEROL | B38: 190 | C38: 10 | D38: 356 | E38: 37 | F38: 17 | G38: 0 | H38: =SUM(B38:G38) -> 610
A39: TRIGLICERIDOS | B39: 193 | C39: 8 | D39: 359 | E39: 38 | F39: 18 | G39: 0 | H39: =SUM(B39:G39) -> 616 | J39: BANCO DE SANGRE | K39: TOTAL
A40: HDLc | B40: 122 | C40: 3 | D40: 225 | E40: 20 | F40: 16 | G40: 0 | H40: =SUM(B40:G40) -> 386 | K40: Hospitaliz | L40: Emergenc | M40: C. Externa | N40: Privado | O40: Convenio | P40: Insolvencia | Q40: TOTAL
A41: LDLc | B41: 123 | C41: 3 | D41: 237 | E41: 21 | F41: 16 | G41: 0 | H41: =SUM(B41:G41) -> 400 | J41: TOTAL DE UNIDADES ENTREGADAS | K41: =SUM(K42:K49) -> 530 | L41: =SUM(L42:L49) -> 172 | M41: =SUM(M42:M49) -> 57 | N41: =SUM(N42:N49) -> 10 | O41: =SUM(O42:O49) -> 0 | P41: =SUM(P42:P49) -> 0 | Q41: =SUM(K41:P41) -> 769
A42: ASO | B42: 5 | C42: 0 | D42: 4 | E42: 0 | F42: 0 | G42: 0 | H42: =SUM(B42:G42) -> 9 | J42: SANGRE TOTAL | K42: 0 | L42: 0 | M42: 0 | N42: 0 | O42: 0 | P42: 0 | Q42: =SUM(K42:P42) -> 0
A43: FACTOR REUMATOIDEO | B43: 7 | C43: 0 | D43: 56 | E43: 6 | F43: 0 | G43: 0 | H43: =SUM(B43:G43) -> 69 | J43: GLOBULOS ROJOS | K43: 158 | L43: 50 | M43: 19 | N43: 5 | O43: 0 | P43: 0 | Q43: =SUM(K43:P43) -> 232
A44: HIERRO | B44: 7 | C44: 0 | D44: 10 | E44: 1 | F44: 0 | G44: 0 | H44: =SUM(B44:G44) -> 18 | J44: PLASMA FRESCO CONGELADO | K44: 11 | L44: 1 | M44: 0 | N44: 0 | O44: 0 | P44: 0 | Q44: =SUM(K44:P44) -> 12
A45: LIPASA | B45: 30 | C45: 120 | D45: 18 | E45: 9 | F45: 0 | G45: 0 | H45: =SUM(B45:G45) -> 177 | J45: CRIOPRECIPITADO | K45: 0 | L45: 0 | M45: 0 | N45: 0 | O45: 0 | P45: 0 | Q45: =SUM(K45:P45) -> 0
A46: TRANSFERRINA | B46: 4 | C46: 1 | D46: 4 | E46: 0 | F46: 0 | G46: 0 | H46: =SUM(B46:G46) -> 9 | J46: PLAQUETAS | K46: 21 | L46: 0 | M46: 0 | N46: 0 | O46: 0 | P46: 0 | Q46: =SUM(K46:P46) -> 21
...

Sheet FEBRERO
A4: Establecimiento de Salud informante: | B4: HOSPITAL REGIONAL DE LORETO | K4: Mes: | L4: FEBRERO
A6: Código Renaes: | B6: 3 | K6: Año: | L6: 2025
A9: PATOLOGÍA CLÍNICA | B9: TOTAL | J9: ANATOMÍA PATOLÓGICA | K9: TOTAL
B10: Hospitaliz | C10: Emergenc | D10: C. Externa | E10: Privado | F10: Convenio | G10: Insolvencia | H10: TOTAL | K10: Hospitaliz | L10: Emergenc | M10: C. Externa | N10: Privado | O10: Convenio | P10: Insolvencia | Q10: TOTAL
A11: TOTAL DE EXAMENES LABORATORIO | B11: =B12+B51+B69+B82+B95 -> 15088 | C11: =C12+C51+C69+C82+C95 -> 17316 | D11: =D12+D51+D69+D82+D95 -> 12251 | E11: =E12+E51+E69+E82+E95 -> 813 | F11: =F12+F51+F69+F82+F95 -> 515 | G11: =G12+G51+G69+G82+G95 -> 49 | H11: =SUM(B11:G11) -> 46032 | J11: TOTAL EXAMENES ANATOMIA PATOLOGICA | K11: =SUM(K12:K23) -> 265 | L11: =SUM(L12:L23) -> 0 | M11: =SUM(M12:M23) -> 737 | N11: =SUM(N12:N23) -> 9 | O11: =SUM(O12:O23) -> 0 | P11: =SUM(P12:P23) -> 0 | Q11: =SUM(K11:P11) -> 1011
A12: TOTAL EXAMENES BIOQUÍMICOS | B12: =SUM(B13:B50) -> 8323 | C12: =SUM(C13:C50) -> 11060 | D12: =SUM(D13:D50) -> 7051 | E12: =SUM(E13:E50) -> 514 | F12: =SUM(F13:F50) -> 318 | G12: =SUM(G13:G50) -> 49 | H12: =SUM(B12:G12) -> 27315 | J12: TOTAL EXAMENES CITOLÓGICOS (PAP) | K12: 0 | L12: 0 | M12: 44 | N12: 9 | O12: 0 | P12: 0 | Q12: =SUM(K12:P12) -> 53
A13: ACIDO URICO | B13: 30 | C13: 2 | D13: 55 | E13: 8 | F13: 4 | G13: 0 | H13: =SUM(B13:G13) -> 99 | J13: TOTAL BAAF | K13: 0 | L13: 0 | M13: 7 | N13: 0 | O13: 0 | P13: 0 | Q13: =SUM(K13:P13) -> 7
A14: CALCIO | B14: 51 | C14: 10 | D14: 73 | E14: 3 | F14: 1 | G14: 0 | H14: =SUM(B14:G14) -> 138 | J14: TOTAL EXAMENES HISTOPATOLÓGICOS (Biopsia) | K14: 2 | L14: 0 | M14: 42 | N14: 0 | O14: 0 | P14: 0 | Q14: =SUM(K14:P14) -> 44
A15: AMILASA | B15: 40 | C15: 130 | D15: 16 | E15: 2 | F15: 0 | G15: 0 | H15: =SUM(B15:G15) -> 188 | J15: TOTAL PIEZA QUIRURGICA (HISTOLOGIA) | K15: 45 | L15: 0 | M15: 27 | N15: 0 | O15: 0 | P15: 0 | Q15: =SUM(K15:P15) -> 72
A16: GLUCOSA | B16: 642 | C16: 1498 | D16: 790 | E16: 66 | F16: 39 | G16: 8 | H16: =SUM(B16:G16) -> 3043 | J16: TOTAL CITOLOGIA ESPECIAL | K16: 0 | L16: 0 | M16: 5 | N16: 0 | O16: 0 | P16: 0 | Q16: =SUM(K16:P16) -> 5
A17: GLUCOSA POST PRANDIAL | B17: 0 | C17: 0 | D17: 15 | E17: 1 | F17: 1 | G17: 0 | H17: =SUM(B17:G17) -> 17 | J17: TOTAL DE TEJIDOS INCLUIDOS | K17: 70 | L17: 0 | M17: 200 | N17: 0 | O17: 0 | P17: 0 | Q17: =SUM(K17:P17) -> 270
A18: FOSFORO | B18: 32 | C18: 5 | D18: 56 | E18: 1 | F18: 0 | G18: 0 | H18: =SUM(B18:G18) -> 94 | J18: TOTAL DE CORTES DE TEJIDOS | K18: 74 | L18: 0 | M18: 200 | N18: 0 | O18: 0 | P18: 0 | Q18: =SUM(K18:P18) -> 274
A19: HEMOGLOBINA GLICOSILADA | B19: 87 | C19: 17 | D19: 106 | E19: 11 | F19: 14 | G19: 0 | H19: =SUM(B19:G19) -> 235 | J19: TOTAL DE LÁMINAS MONTADAS | K19: 74 | L19: 0 | M19: 200 | N19: 0 | O19: 0 | P19: 0 | Q19: =SUM(K19:P19) -> 274
A20: TOLERANCIA A LA GLUCOSA | B20: 1 | C20: 0 | D20: 7 | E20: 2 | F20: 2 | G20: 0 | H20: =SUM(B20:G20) -> 12 | J20: TOTAL DE HISTOQUIMICA | K20: 0 | L20: 0 | M20: 12 | N20: 0 | O20: 0 | P20: 0 | Q20: =SUM(K20:P20) -> 12
A21: CREATININA | B21: 780 | C21: 1523 | D21: 749 | E21: 63 | F21: 39 | G21: 8 | H21: =SUM(B21:G21) -> 3162 | J21: TOTAL DE INMUNOHISTOQUIMICA
A22: DEPURACION DE CREATININA | B22: 7 | C22: 0 | D22: 14 | E22: 1 | F22: 2 | G22: 0 | H22: =SUM(B22:G22) -> 24 | J22: TOTAL AUTOPSIA MÉDICO LEGAL | K22: 0 | L22: 0 | M22: 0 | N22: 0 | O22: 0 | P22: 0 | Q22: =SUM(K22:P22) -> 0
A23: MICROALBUMINURIA | H23: =SUM(B23:G23) -> 0 | J23: TOTAL AUTOPSIA CLÍNICA | K23: 0 | L23: 0 | M23: 0 | N23: 0 | O23: 0 | P23: 0 | Q23: =SUM(K23:P23) -> 0
A24: UREA | B24: 757 | C24: 1520 | D24: 750 | E24: 59 | F24: 39 | G24: 8 | H24: =SUM(B24:G24) -> 3133
A25: PROTEINURIA 24 HORAS | B25: 0 | C25: 0 | D25: 0 | E25: 0 | F25: 2 | G25: 0 | H25: =SUM(B25:G25) -> 2
A26: BILIRRUBINA TOTAL | B26: 578 | C26: 536 | D26: 331 | E26: 14 | F26: 8 | G26: 0 | H26: =SUM(B26:G26) -> 1467 | J26: PROGRAMAS / METAXENICAS | K26: TOTAL
A27: BILIRRUBINA DIRECTA | B27: 571 | C27: 536 | D27: 331 | E27: 20 | F27: 8 | G27: 0 | H27: =SUM(B27:G27) -> 1466 | K27: Hospitaliz | L27: Emergenc | M27: Programa | N27: Privado | O27: Convenio | P27: Insolvencia | Q27: TOTAL
A28: PROTEINAS TOTAL | B28: 582 | C28: 575 | D28: 397 | E28: 28 | F28: 13 | G28: 0 | H28: =SUM(B28:G28) -> 1595 | J28: TOTAL DE EXAMENES | K28: =SUM(K29:K37) -> 220 | L28: =SUM(L29:L37) -> 433 | M28: =SUM(M29:M37) -> 197 | N28: =SUM(N29:N37) -> 0 | O28: =SUM(O29:O37) -> 0 | P28: =SUM(P29:P37) -> 0 | Q28: =SUM(K28:P28) -> 850
A29: ALBUMINA | B29: 588 | C29: 575 | D29: 398 | E29: 8 | F29: 0 | G29: 0 | H29: =SUM(B29:G29) -> 1569 | J29: TUBERCULOSIS | K29: 139 | L29: 12 | M29: 134 | N29: 0 | O29: 0 | P29: 0 | Q29: =SUM(K29:P29) -> 285
A30: TGO | B30: 621 | C30: 632 | D30: 480 | E30: 44 | F30: 22 | G30: 0 | H30: =SUM(B30:G30) -> 1799 | J30: LEISHMANIA | K30: 0 | L30: 0 | M30: 0 | N30: 0 | O30: 0 | P30: 0 | Q30: =SUM(K30:P30) -> 0
A31: TGP | B31: 621 | C31: 632 | D31: 481 | E31: 44 | F31: 22 | G31: 0 | H31: =SUM(B31:G31) -> 1800 | J31: PROGRAMA LEPRAE | K31: 0 | L31: 0 | M31: 30 | N31: 0 | O31: 0 | P31: 0 | Q31: =SUM(K31:P31) -> 30
A32: GGTP | B32: 0 | C32: 1 | D32: 3 | E32: 0 | F32: 1 | G32: 0 | H32: =SUM(B32:G32) -> 5 | J32: MALARIA | K32: 59 | L32: 247 | M32: 21 | N32: 0 | O32: 0 | P32: 0 | Q32: =SUM(K32:P32) -> 327
A33: LACTATO DESHIDROGENASA (DHL) | B33: 194 | C33: 181 | D33: 58 | E33: 0 | F33: 2 | G33: 0 | H33: =SUM(B33:G33) -> 435 | J33: METAXENICAS (REFERENCIAL) | K33: 0 | L33: 0 | M33: 0 | N33: 0 | O33: 0 | P33: 0 | Q33: =SUM(K33:P33) -> 0
A34: PROTEINA C REACTIVA (CUANTITATIVO) | B34: 823 | C34: 1141 | D34: 124 | E34: 50 | F34: 6 | G34: 0 | H34: =SUM(B34:G34) -> 2144 | J34: CULTIVO DE TB (REFERENCIAL) | K34: 0 | L34: 0 | M34: 12 | N34: 0 | O34: 0 | P34: 0 | Q34: =SUM(K34:P34) -> 12
A35: FOSFATASA ALCALINA | B35: 525 | C35: 304 | D35: 305 | E35: 11 | F35: 9 | G35: 0 | H35: =SUM(B35:G35) -> 1154 | J35: PRUEBA RAPIDA DE DENGUE | K35: 16 | L35: 107 | M35: 0 | N35: 0 | O35: 0 | P35: 0 | Q35: =SUM(K35:P35) -> 123
A36: CPK TOTAL | B36: 0 | C36: 0 | D36: 0 | E36: 0 | F36: 0 | G36: 0 | H36: =SUM(B36:G36) -> 0 | J36: PRUEBA RAPIDA DE LEPTOSPIRA | K36: 6 | L36: 39 | M36: 0 | N36: 0 | O36: 0 | P36: 0 | Q36: =SUM(K36:P36) -> 45
A37: CPK MB | B37: 0 | C37: 3 | D37: 0 | E37: 0 | F37: 0 | G37: 0 | H37: =SUM(B37:G37) -> 3 | J37: PRUEBA RAPIDA DE COVID + INFLUENZA | K37: 0 | L37: 28 | M37: 0 | N37: 0 | O37: 0 | P37: 0 | Q37: =SUM(K37:P37) -> 28
A38: COLESTEROL | B38: 180 | C38: 13 | D38: 265 | E38: 23 | F38: 17 | G38: 5 | H38: =SUM(B38:G38) -> 503
A39: TRIGLICERIDOS | B39: 180 | C39: 13 | D39: 160 | E39: 23 | F39: 18 | G39: 5 | H39: =SUM(B39:G39) -> 399 | J39: BANCO DE SANGRE | K39: TOTAL
A40: HDLc | B40: 125 | C40: 8 | D40: 140 | E40: 10 | F40: 16 | G40: 8 | H40: =SUM(B40:G40) -> 307 | K40: Hospitaliz | L40: Emergenc | M40: C. Externa | N40: Privado | O40: Convenio | P40: Insolvencia | Q40: TOTAL
A41: LDLc | B41: 125 | C41: 8 | D41: 146 | E41: 10 | F41: 16 | G41: 7 | H41: =SUM(B41:G41) -> 312 | J41: TOTAL DE UNIDADES ENTREGADAS | K41: =SUM(K42:K49) -> 780 | L41: =SUM(L42:L49) -> 245 | M41: =SUM(M42:M49) -> 42 | N41: =SUM(N42:N49) -> 0 | O41: =SUM(O42:O49) -> 0 | P41: =SUM(P42:P49) -> 0 | Q41: =SUM(K41:P41) -> 1067
A42: ASO | B42: 7 | C42: 5 | D42: 4 | E42: 0 | F42: 0 | G42: 0 | H42: =SUM(B42:G42) -> 16 | J42: SANGRE TOTAL | K42: 0 | L42: 0 | M42: 0 | N42: 0 | O42: 0 | P42: 0 | Q42: =SUM(K42:P42) -> 0
A43: FACTOR REUMATOIDEO | B43: 8 | C43: 4 | D43: 55 | E43: 5 | F43: 0 | G43: 0 | H43: =SUM(B43:G43) -> 72 | J43: GLOBULOS ROJOS | K43: 199 | L43: 81 | M43: 12 | N43: 0 | O43: 0 | P43: 0 | Q43: =SUM(K43:P43) -> 292
A44: HIERRO | B44: 34 | D44: 54 | E44: 1 | F44: 0 | G44: 0 | H44: =SUM(B44:G44) -> 89 | J44: PLASMA FRESCO CONGELADO | K44: 42 | L44: 8 | M44: 0 | N44: 0 | O44: 0 | P44: 0 | Q44: =SUM(K44:P44) -> 50
A45: LIPASA | B45: 49 | C45: 101 | D45: 27 | E45: 3 | F45: 0 | G45: 0 | H45: =SUM(B45:G45) -> 180 | J45: CRIOPRECIPITADO | K45: 41 | L45: 5 | M45: 0 | N45: 0 | O45: 0 | P45: 0 | Q45: =SUM(K45:P45) -> 46
A46: TRANSFERRINA | B46: 35 | C46: 1 | D46: 47 | E46: 0 | F46: 0 | G46: 0 | H46: =SUM(B46:G46) -> 83 | J46: PLAQUETAS | K46: 28 | L46: 0 | M46: 0 | N46: 0 | O46: 0 | P46: 0 | Q46: =SUM(K46:P46) -> 28
...

Sheet MARZO
A4: Establecimiento de Salud informante: | B4: HOSPITAL REGIONAL DE LORETO | K4: Mes: | L4: MARZO
A6: Código Renaes: | B6: 3 | K6: Año: | L6: 2025
A9: PATOLOGÍA CLÍNICA | B9: TOTAL | J9: ANATOMÍA PATOLÓGICA | K9: TOTAL
B10: Hospitaliz | C10: Emergenc | D10: C. Externa | E10: Privado | F10: Convenio | G10: Insolvencia | H10: TOTAL | K10: Hospitaliz | L10: Emergenc | M10: C. Externa | N10: Privado | O10: Convenio | P10: Insolvencia | Q10: TOTAL
A11: TOTAL DE EXAMENES LABORATORIO | B11: =B12+B51+B69+B82+B95 -> 15039 | C11: =C12+C51+C69+C82+C95 -> 17147 | D11: =D12+D51+D69+D82+D95 -> 14878 | E11: =E12+E51+E69+E82+E95 -> 786 | F11: =F12+F51+F69+F82+F95 -> 551 | G11: =G12+G51+G69+G82+G95 -> 20 | H11: =SUM(B11:G11) -> 48421 | J11: TOTAL EXAMENES ANATOMIA PATOLOGICA | K11: =SUM(K12:K23) -> 1037 | L11: =SUM(L12:L23) -> 0 | M11: =SUM(M12:M23) -> 422 | N11: =SUM(N12:N23) -> 7 | O11: =SUM(O12:O23) -> 1 | P11: =SUM(P12:P23) -> 0 | Q11: =SUM(K11:P11) -> 1467
A12: TOTAL EXAMENES BIOQUÍMICOS | B12: =SUM(B13:B50) -> 8844 | C12: =SUM(C13:C50) -> 10835 | D12: =SUM(D13:D50) -> 8499 | E12: =SUM(E13:E50) -> 509 | F12: =SUM(F13:F50) -> 351 | G12: =SUM(G13:G50) -> 20 | H12: =SUM(B12:G12) -> 29058 | J12: TOTAL EXAMENES CITOLÓGICOS (PAP) | K12: 0 | L12: 0 | M12: 45 | N12: 6 | O12: 0 | P12: 0 | Q12: =SUM(K12:P12) -> 51
A13: ACIDO URICO | B13: 31 | C13: 2 | D13: 69 | E13: 0 | F13: 3 | G13: 4 | H13: =SUM(B13:G13) -> 109 | J13: TOTAL BAAF | K13: 4 | L13: 0 | M13: 3 | N13: 0 | O13: 0 | P13: 0 | Q13: =SUM(K13:P13) -> 7
A14: CALCIO | B14: 30 | C14: 1 | D14: 39 | E14: 5 | F14: 1 | G14: 0 | H14: =SUM(B14:G14) -> 76 | J14: TOTAL EXAMENES HISTOPATOLÓGICOS (Biopsia) | K14: 3 | L14: 0 | M14: 46 | N14: 0 | O14: 1 | P14: 0 | Q14: =SUM(K14:P14) -> 50
A15: AMILASA | B15: 10 | C15: 116 | D15: 31 | E15: 2 | F15: 0 | G15: 2 | H15: =SUM(B15:G15) -> 161 | J15: TOTAL PIEZA QUIRURGICA (HISTOLOGIA) | K15: 81 | L15: 0 | M15: 26 | N15: 1 | O15: 0 | P15: 0 | Q15: =SUM(K15:P15) -> 108
A16: GLUCOSA | B16: 780 | C16: 1566 | D16: 960 | E16: 72 | F16: 35 | G16: 3 | H16: =SUM(B16:G16) -> 3416 | J16: TOTAL CITOLOGIA ESPECIAL | K16: 0 | L16: 0 | M16: 2 | N16: 0 | O16: 0 | P16: 0 | Q16: =SUM(K16:P16) -> 2
A17: GLUCOSA POST PRANDIAL | B17: 0 | C17: 0 | D17: 12 | E17: 0 | F17: 1 | G17: 0 | H17: =SUM(B17:G17) -> 13 | J17: TOTAL DE TEJIDOS INCLUIDOS | K17: 313 | L17: 0 | M17: 100 | N17: 0 | O17: 0 | P17: 0 | Q17: =SUM(K17:P17) -> 413
A18: FOSFORO | B18: 18 | C18: 0 | D18: 23 | E18: 0 | F18: 0 | G18: 0 | H18: =SUM(B18:G18) -> 41 | J18: TOTAL DE CORTES DE TEJIDOS | K18: 315 | L18: 0 | M18: 100 | N18: 0 | O18: 0 | P18: 0 | Q18: =SUM(K18:P18) -> 415
A19: HEMOGLOBINA GLICOSILADA | B19: 102 | C19: 62 | D19: 210 | E19: 9 | F19: 11 | G19: 0 | H19: =SUM(B19:G19) -> 394 | J19: TOTAL DE LÁMINAS MONTADAS | K19: 315 | L19: 0 | M19: 100 | N19: 0 | O19: 0 | P19: 0 | Q19: =SUM(K19:P19) -> 415
A20: TOLERANCIA A LA GLUCOSA | B20: 2 | C20: 1 | D20: 33 | E20: 1 | F20: 1 | G20: 0 | H20: =SUM(B20:G20) -> 38 | J20: TOTAL DE HISTOQUIMICA | K20: 6 | L20: 0 | M20: 0 | N20: 0 | O20: 0 | P20: 0 | Q20: =SUM(K20:P20) -> 6
A21: CREATININA | B21: 801 | C21: 1554 | D21: 980 | E21: 68 | F21: 40 | G21: 0 | H21: =SUM(B21:G21) -> 3443 | J21: TOTAL DE INMUNOHISTOQUIMICA
A22: DEPURACION DE CREATININA | B22: 2 | C22: 0 | D22: 5 | E22: 0 | F22: 0 | G22: 0 | H22: =SUM(B22:G22) -> 7 | J22: TOTAL AUTOPSIA MÉDICO LEGAL | K22: 0 | L22: 0 | M22: 0 | N22: 0 | O22: 0 | P22: 0 | Q22: =SUM(K22:P22) -> 0
J23: TOTAL AUTOPSIA CLÍNICA | K23: 0 | L23: 0 | M23: 0 | N23: 0 | O23: 0 | P23: 0 | Q23: =SUM(K23:P23) -> 0
A24: UREA | B24: 860 | C24: 1552 | D24: 954 | E24: 66 | F24: 40 | G24: 0 | H24: =SUM(B24:G24) -> 3472
A25: PROTEINURIA 24 HORAS | B25: 8 | C25: 0 | D25: 15 | E25: 0 | F25: 0 | G25: 0 | H25: =SUM(B25:G25) -> 23
A26: BILIRRUBINA TOTAL | B26: 621 | C26: 470 | D26: 405 | E26: 13 | F26: 17 | G26: 0 | H26: =SUM(B26:G26) -> 1526 | J26: PROGRAMAS / METAXENICAS | K26: TOTAL
A27: BILIRRUBINA DIRECTA | B27: 618 | C27: 470 | D27: 401 | E27: 13 | F27: 17 | G27: 0 | H27: =SUM(B27:G27) -> 1519 | K27: Hospitaliz | L27: Emergenc | M27: Programa | N27: Privado | O27: Convenio | P27: Insolvencia | Q27: TOTAL
A28: PROTEINAS TOTAL | B28: 558 | C28: 451 | D28: 481 | E28: 14 | F28: 18 | G28: 0 | H28: =SUM(B28:G28) -> 1522 | J28: TOTAL DE EXAMENES | K28: =SUM(K29:K37) -> 161 | L28: =SUM(L29:L37) -> 495 | M28: =SUM(M29:M37) -> 207 | N28: =SUM(N29:N37) -> 3 | O28: =SUM(O29:O37) -> 0 | P28: =SUM(P29:P37) -> 0 | Q28: =SUM(K28:P28) -> 866
A29: ALBUMINA | B29: 545 | C29: 458 | D29: 475 | E29: 6 | F29: 18 | G29: 0 | H29: =SUM(B29:G29) -> 1502 | J29: TUBERCULOSIS | K29: 114 | L29: 27 | M29: 125 | N29: 0 | O29: 0 | P29: 0 | Q29: =SUM(K29:P29) -> 266
A30: TGO | B30: 615 | C30: 538 | D30: 672 | E30: 33 | F30: 27 | G30: 0 | H30: =SUM(B30:G30) -> 1885 | J30: LEISHMANIA | K30: 0 | L30: 0 | M30: 4 | N30: 0 | O30: 0 | P30: 0 | Q30: =SUM(K30:P30) -> 4
A31: TGP | B31: 612 | C31: 538 | D31: 672 | E31: 32 | F31: 27 | G31: 0 | H31: =SUM(B31:G31) -> 1881 | J31: PROGRAMA LEPRAE | K31: 0 | L31: 0 | M31: 6 | N31: 0 | O31: 0 | P31: 0 | Q31: =SUM(K31:P31) -> 6
A32: GGTP | B32: 0 | C32: 2 | D32: 2 | E32: 1 | F32: 0 | G32: 0 | H32: =SUM(B32:G32) -> 5 | J32: MALARIA | K32: 35 | L32: 367 | M32: 40 | N32: 0 | O32: 0 | P32: 0 | Q32: =SUM(K32:P32) -> 442
A33: LACTATO DESHIDROGENASA (DHL) | B33: 147 | C33: 115 | D33: 65 | E33: 5 | F33: 3 | G33: 0 | H33: =SUM(B33:G33) -> 335 | J33: METAXENICAS (REFERENCIAL) | K33: 0 | L33: 27 | M33: 0 | N33: 0 | O33: 0 | P33: 0 | Q33: =SUM(K33:P33) -> 27
A34: PROTEINA C REACTIVA (CUANTITATIVO) | B34: 787 | C34: 1297 | D34: 148 | E34: 40 | F34: 8 | G34: 0 | H34: =SUM(B34:G34) -> 2280 | J34: CULTIVO DE TB (REFERENCIAL) | K34: 0 | L34: 0 | M34: 28 | N34: 0 | O34: 0 | P34: 0 | Q34: =SUM(K34:P34) -> 28
A35: FOSFATASA ALCALINA | B35: 478 | C35: 314 | D35: 367 | E35: 9 | F35: 17 | G35: 0 | H35: =SUM(B35:G35) -> 1185 | J35: PRUEBA RAPIDA DE DENGUE | K35: 0 | L35: 0 | M35: 0 | N35: 0 | O35: 0 | P35: 0 | Q35: =SUM(K35:P35) -> 0
A36: CPK TOTAL | B36: 0 | C36: 0 | D36: 0 | E36: 0 | F36: 0 | G36: 0 | H36: =SUM(B36:G36) -> 0 | J36: PRUEBA RAPIDA DE LEPTOSPIRA | K36: 12 | L36: 51 | M36: 4 | N36: 3 | O36: 0 | P36: 0 | Q36: =SUM(K36:P36) -> 70
A37: CPK MB | B37: 0 | C37: 4 | D37: 0 | E37: 0 | F37: 0 | G37: 0 | H37: =SUM(B37:G37) -> 4 | J37: PRUEBA RAPIDA DE COVID + INFLUENZA | K37: 0 | L37: 23 | M37: 0 | N37: 0 | O37: 0 | P37: 0 | Q37: =SUM(K37:P37) -> 23
A38: COLESTEROL | B38: 131 | C38: 18 | D38: 420 | E38: 28 | F38: 17 | G38: 3 | H38: =SUM(B38:G38) -> 617
A39: TRIGLICERIDOS | B39: 135 | C39: 18 | D39: 421 | E39: 27 | F39: 17 | G39: 0 | H39: =SUM(B39:G39) -> 618 | J39: BANCO DE SANGRE | K39: TOTAL
A40: HDLc | B40: 269 | C40: 2 | D40: 113 | E40: 20 | F40: 14 | G40: 4 | H40: =SUM(B40:G40) -> 422 | K40: Hospitaliz | L40: Emergenc | M40: C. Externa | N40: Privado | O40: Convenio | P40: Insolvencia | Q40: TOTAL
A41: LDLc | B41: 110 | C41: 2 | D41: 279 | E41: 20 | F41: 14 | G41: 4 | H41: =SUM(B41:G41) -> 429 | J41: TOTAL DE UNIDADES ENTREGADAS | K41: =SUM(K42:K49) -> 671 | L41: =SUM(L42:L49) -> 146 | M41: =SUM(M42:M49) -> 0 | N41: =SUM(N42:N49) -> 0 | O41: =SUM(O42:O49) -> 5 | P41: =SUM(P42:P49) -> 0 | Q41: =SUM(K41:P41) -> 822
A42: ASO | B42: 4 | C42: 0 | D42: 7 | E42: 0 | F42: 0 | G42: 0 | H42: =SUM(B42:G42) -> 11 | J42: SANGRE TOTAL | K42: 0 | L42: 0 | M42: 0 | N42: 0 | O42: 0 | P42: 0 | Q42: =SUM(K42:P42) -> 0
A43: FACTOR REUMATOIDEO | B43: 6 | C43: 2 | D43: 11 | E43: 2 | F43: 1 | G43: 0 | H43: =SUM(B43:G43) -> 22 | J43: GLOBULOS ROJOS | K43: 186 | L43: 56 | M43: 0 | N43: 0 | O43: 2 | P43: 0 | Q43: =SUM(K43:P43) -> 244
A44: HIERRO | B44: 26 | C44: 1 | D44: 21 | E44: 0 | F44: 1 | G44: 0 | H44: =SUM(B44:G44) -> 49 | J44: PLASMA FRESCO CONGELADO | K44: 17 | L44: 0 | M44: 0 | N44: 0 | O44: 0 | P44: 0 | Q44: =SUM(K44:P44) -> 17
A45: LIPASA | B45: 16 | C45: 94 | D45: 29 | E45: 1 | F45: 0 | G45: 0 | H45: =SUM(B45:G45) -> 140 | J45: CRIOPRECIPITADO | K45: 5 | L45: 0 | M45: 0 | N45: 0 | O45: 0 | P45: 0 | Q45: =SUM(K45:P45) -> 5
A46: TRANSFERRINA | B46: 18 | C46: 1 | D46: 9 | E46: 0 | F46: 1 | G46: 0 | H46: =SUM(B46:G46) -> 29 | J46: PLAQUETAS | K46: 44 | L46: 1 | M46: 0 | N46: 0 | O46: 0 | P46: 0 | Q46: =SUM(K46:P46) -> 45
...

Sheet ABRIL
A4: Establecimiento de Salud informante: | B4: HOSPITAL REGIONAL DE LORETO | K4: Mes: | L4: ABRIL
A6: Código Renaes: | B6: 3 | K6: Año: | L6: 2025
A9: PATOLOGÍA CLÍNICA | B9: TOTAL | J9: ANATOMÍA PATOLÓGICA | K9: TOTAL
B10: Hospitaliz | C10: Emergenc | D10: C. Externa | E10: Privado | F10: Convenio | G10: Insolvencia | H10: TOTAL | K10: Hospitaliz | L10: Emergenc | M10: C. Externa | N10: Privado | O10: Convenio | P10: Insolvencia | Q10: TOTAL
A11: TOTAL DE EXAMENES LABORATORIO | B11: =B12+B51+B69+B82+B95 -> 13221 | C11: =C12+C51+C69+C82+C95 -> 18027 | D11: =D12+D51+D69+D82+D95 -> 13422 | E11: =E12+E51+E69+E82+E95 -> 775 | F11: =F12+F51+F69+F82+F95 -> 581 | G11: =G12+G51+G69+G82+G95 -> 105 | H11: =SUM(B11:G11) -> 46131 | J11: TOTAL EXAMENES ANATOMIA PATOLOGICA | K11: =SUM(K12:K23) -> 971 | L11: =SUM(L12:L23) -> 0 | M11: =SUM(M12:M23) -> 1048 | N11: =SUM(N12:N23) -> 8 | O11: =SUM(O12:O23) -> 1 | P11: =SUM(P12:P23) -> 0 | Q11: =SUM(K11:P11) -> 2028
A12: TOTAL EXAMENES BIOQUÍMICOS | B12: =SUM(B13:B50) -> 8887 | C12: =SUM(C13:C50) -> 11331 | D12: =SUM(D13:D50) -> 7985 | E12: =SUM(E13:E50) -> 481 | F12: =SUM(F13:F50) -> 401 | G12: =SUM(G13:G50) -> 68 | H12: =SUM(B12:G12) -> 29153 | J12: TOTAL EXAMENES CITOLÓGICOS (PAP) | K12: 1 | L12: 0 | M12: 24 | N12: 3 | O12: 0 | P12: 0 | Q12: =SUM(K12:P12) -> 28
A13: ACIDO URICO | B13: 30 | C13: 7 | D13: 100 | E13: 2 | F13: 7 | G13: 1 | H13: =SUM(B13:G13) -> 147 | J13: TOTAL BAAF | K13: 0 | L13: 0 | M13: 5 | N13: 0 | O13: 0 | P13: 0 | Q13: =SUM(K13:P13) -> 5
A14: CALCIO | B14: 36 | C14: 2 | D14: 77 | E14: 2 | F14: 6 | G14: 0 | H14: =SUM(B14:G14) -> 123 | J14: TOTAL EXAMENES HISTOPATOLÓGICOS (Biopsia) | K14: 3 | L14: 0 | M14: 69 | N14: 4 | O14: 1 | P14: 0 | Q14: =SUM(K14:P14) -> 77
A15: AMILASA | B15: 86 | C15: 104 | D15: 26 | E15: 1 | F15: 0 | G15: 0 | H15: =SUM(B15:G15) -> 217 | J15: TOTAL PIEZA QUIRURGICA (HISTOLOGIA) | K15: 54 | L15: 0 | M15: 35 | N15: 1 | O15: 0 | P15: 0 | Q15: =SUM(K15:P15) -> 90
A16: GLUCOSA | B16: 760 | C16: 1586 | D16: 840 | E16: 72 | F16: 43 | G16: 17 | H16: =SUM(B16:G16) -> 3318 | J16: TOTAL CITOLOGIA ESPECIAL | K16: 5 | L16: 0 | M16: 0 | N16: 0 | O16: 0 | P16: 0 | Q16: =SUM(K16:P16) -> 5
A17: GLUCOSA POST PRANDIAL | B17: 0 | C17: 0 | D17: 10 | E17: 0 | F17: 0 | G17: 0 | H17: =SUM(B17:G17) -> 10 | J17: TOTAL DE TEJIDOS INCLUIDOS | K17: 300 | L17: 0 | M17: 305 | N17: 0 | O17: 0 | P17: 0 | Q17: =SUM(K17:P17) -> 605
A18: FOSFORO | B18: 19 | C18: 2 | D18: 66 | E18: 2 | F18: 5 | G18: 0 | H18: =SUM(B18:G18) -> 94 | J18: TOTAL DE CORTES DE TEJIDOS | K18: 300 | L18: 0 | M18: 305 | N18: 0 | O18: 0 | P18: 0 | Q18: =SUM(K18:P18) -> 605
A19: HEMOGLOBINA GLICOSILADA | B19: 90 | C19: 29 | D19: 166 | E19: 12 | F19: 13 | G19: 0 | H19: =SUM(B19:G19) -> 310 | J19: TOTAL DE LÁMINAS MONTADAS | K19: 300 | L19: 0 | M19: 305 | N19: 0 | O19: 0 | P19: 0 | Q19: =SUM(K19:P19) -> 605
A20: TOLERANCIA A LA GLUCOSA | B20: 2 | C20: 0 | D20: 25 | E20: 0 | F20: 0 | G20: 0 | H20: =SUM(B20:G20) -> 27 | J20: TOTAL DE HISTOQUIMICA | K20: 8 | L20: 0 | M20: 0 | N20: 0 | O20: 0 | P20: 0 | Q20: =SUM(K20:P20) -> 8
A21: CREATININA | B21: 812 | C21: 1573 | D21: 901 | E21: 63 | F21: 48 | G21: 1 | H21: =SUM(B21:G21) -> 3398 | J21: TOTAL DE INMUNOHISTOQUIMICA
A22: DEPURACION DE CREATININA | B22: 1 | C22: 0 | D22: 4 | E22: 1 | F22: 0 | G22: 0 | H22: =SUM(B22:G22) -> 6 | J22: TOTAL AUTOPSIA MÉDICO LEGAL | K22: 0 | L22: 0 | M22: 0 | N22: 0 | O22: 0 | P22: 0 | Q22: =SUM(K22:P22) -> 0
A23: MICROALBUMINURIA | B23: 2 | C23: 0 | D23: 23 | E23: 0 | F23: 4 | G23: 0 | H23: =SUM(B23:G23) -> 29 | J23: TOTAL AUTOPSIA CLÍNICA | K23: 0 | L23: 0 | M23: 0 | N23: 0 | O23: 0 | P23: 0 | Q23: =SUM(K23:P23) -> 0
A24: UREA | B24: 810 | C24: 1571 | D24: 884 | E24: 58 | F24: 43 | G24: 2 | H24: =SUM(B24:G24) -> 3368
A25: PROTEINURIA 24 HORAS | B25: 19 | C25: 7 | D25: 42 | E25: 0 | F25: 3 | G25: 0 | H25: =SUM(B25:G25) -> 71
A26: BILIRRUBINA TOTAL | B26: 555 | C26: 572 | D26: 412 | E26: 18 | F26: 11 | G26: 1 | H26: =SUM(B26:G26) -> 1569 | J26: PROGRAMAS / METAXENICAS | K26: TOTAL
A27: BILIRRUBINA DIRECTA | B27: 555 | C27: 572 | D27: 412 | E27: 18 | F27: 11 | G27: 1 | H27: =SUM(B27:G27) -> 1569 | K27: Hospitaliz | L27: Emergenc | M27: Programa | N27: Privado | O27: Convenio | P27: Insolvencia | Q27: TOTAL
A28: PROTEINAS TOTAL | B28: 601 | C28: 621 | D28: 459 | E28: 20 | F28: 20 | G28: 3 | H28: =SUM(B28:G28) -> 1724 | J28: TOTAL DE EXAMENES | K28: =SUM(K29:K37) -> 177 | L28: =SUM(L29:L37) -> 558 | M28: =SUM(M29:M37) -> 362 | N28: =SUM(N29:N37) -> 0 | O28: =SUM(O29:O37) -> 0 | P28: =SUM(P29:P37) -> 0 | Q28: =SUM(K28:P28) -> 1097
A29: ALBUMINA | B29: 605 | C29: 621 | D29: 458 | E29: 10 | F29: 20 | G29: 3 | H29: =SUM(B29:G29) -> 1717 | J29: TUBERCULOSIS | K29: 117 | L29: 4 | M29: 103 | N29: 0 | O29: 0 | P29: 0 | Q29: =SUM(K29:P29) -> 224
A30: TGO | B30: 639 | C30: 651 | D30: 626 | E30: 31 | F30: 32 | G30: 2 | H30: =SUM(B30:G30) -> 1981 | J30: LEISHMANIA | K30: 0 | L30: 0 | M30: 1 | N30: 0 | O30: 0 | P30: 0 | Q30: =SUM(K30:P30) -> 1
A31: TGP | B31: 639 | C31: 651 | D31: 625 | E31: 31 | F31: 32 | G31: 2 | H31: =SUM(B31:G31) -> 1980 | J31: PROGRAMA LEPRAE | K31: 0 | L31: 0 | M31: 30 | N31: 0 | O31: 0 | P31: 0 | Q31: =SUM(K31:P31) -> 30
A32: GGTP | B32: 0 | C32: 0 | D32: 1 | E32: 0 | F32: 0 | G32: 0 | H32: =SUM(B32:G32) -> 1 | J32: MALARIA | K32: 42 | L32: 375 | M32: 34 | N32: 0 | O32: 0 | P32: 0 | Q32: =SUM(K32:P32) -> 451
A33: LACTATO DESHIDROGENASA (DHL) | B33: 263 | C33: 157 | D33: 58 | E33: 0 | F33: 0 | G33: 0 | H33: =SUM(B33:G33) -> 478 | J33: METAXENICAS (REFERENCIAL) | K33: 0 | L33: 0 | M33: 167 | N33: 0 | O33: 0 | P33: 0 | Q33: =SUM(K33:P33) -> 167
A34: PROTEINA C REACTIVA (CUANTITATIVO) | B34: 812 | C34: 1265 | D34: 151 | E34: 38 | F34: 11 | G34: 2 | H34: =SUM(B34:G34) -> 2279 | J34: CULTIVO DE TB (REFERENCIAL) | K34: 0 | L34: 0 | M34: 19 | N34: 0 | O34: 0 | P34: 0 | Q34: =SUM(K34:P34) -> 19
A35: FOSFATASA ALCALINA | B35: 493 | C35: 0 | D35: 353 | E35: 14 | F35: 8 | G35: 1 | H35: =SUM(B35:G35) -> 869 | J35: PRUEBA RAPIDA DE DENGUE | K35: 0 | L35: 174 | M35: 0 | N35: 0 | O35: 0 | P35: 0 | Q35: =SUM(K35:P35) -> 174
A36: CPK TOTAL | B36: 0 | C36: 0 | D36: 0 | E36: 0 | F36: 0 | G36: 0 | H36: =SUM(B36:G36) -> 0 | J36: PRUEBA RAPIDA DE LEPTOSPIRA | K36: 18 | L36: 5 | M36: 8 | N36: 0 | O36: 0 | P36: 0 | Q36: =SUM(K36:P36) -> 31
A37: CPK MB | B37: 29 | C37: 21 | D37: 2 | E37: 0 | F37: 2 | G37: 0 | H37: =SUM(B37:G37) -> 54 | J37: PRUEBA RAPIDA DE COVID | K37: 0 | L37: 0 | M37: 0 | N37: 0 | O37: 0 | P37: 0 | Q37: =SUM(K37:P37) -> 0
A38: COLESTEROL | B38: 106 | C38: 36 | D38: 316 | E38: 22 | F38: 26 | G38: 15 | H38: =SUM(B38:G38) -> 521
A39: TRIGLICERIDOS | B39: 107 | C39: 38 | D39: 320 | E39: 25 | F39: 26 | G39: 15 | H39: =SUM(B39:G39) -> 531 | J39: BANCO DE SANGRE | K39: TOTAL
A40: HDLc | B40: 72 | C40: 5 | D40: 186 | E40: 11 | F40: 8 | G40: 1 | H40: =SUM(B40:G40) -> 283 | K40: Hospitaliz | L40: Emergenc | M40: C. Externa | N40: Privado | O40: Convenio | P40: Insolvencia | Q40: TOTAL
A41: LDLc | B41: 73 | C41: 5 | D41: 194 | E41: 11 | F41: 8 | G41: 1 | H41: =SUM(B41:G41) -> 292 | J41: TOTAL DE UNIDADES ENTREGADAS | K41: =SUM(K42:K49) -> 596 | L41: =SUM(L42:L49) -> 299 | M41: =SUM(M42:M49) -> 0 | N41: =SUM(N42:N49) -> 4 | O41: =SUM(O42:O49) -> 2 | P41: =SUM(P42:P49) -> 0 | Q41: =SUM(K41:P41) -> 901
A42: ASO | B42: 3 | C42: 0 | D42: 4 | E42: 0 | F42: 0 | G42: 0 | H42: =SUM(B42:G42) -> 7 | J42: SANGRE TOTAL | K42: 0 | L42: 0 | M42: 0 | N42: 0 | O42: 0 | P42: 0 | Q42: =SUM(K42:P42) -> 0
A43: FACTOR REUMATOIDEO | B43: 11 | C43: 0 | D43: 52 | E43: 2 | F43: 2 | G43: 0 | H43: =SUM(B43:G43) -> 67 | J43: GLOBULOS ROJOS | K43: 153 | L43: 89 | M43: 0 | N43: 2 | O43: 1 | P43: 0 | Q43: =SUM(K43:P43) -> 245
A44: HIERRO | B44: 19 | C44: 0 | D44: 14 | E44: 0 | F44: 2 | G44: 0 | H44: =SUM(B44:G44) -> 35 | J44: PLASMA FRESCO CONGELADO | K44: 6 | L44: 8 | M44: 0 | N44: 0 | O44: 0 | P44: 0 | Q44: =SUM(K44:P44) -> 14
A45: LIPASA | B45: 75 | C45: 93 | D45: 29 | E45: 1 | F45: 0 | G45: 0 | H45: =SUM(B45:G45) -> 198 | J45: CRIOPRECIPITADO | K45: 4 | L45: 0 | M45: 0 | N45: 0 | O45: 0 | P45: 0 | Q45: =SUM(K45:P45) -> 4
A46: TRANSFERRINA | B46: 23 | C46: 0 | D46: 8 | E46: 0 | F46: 1 | G46: 0 | H46: =SUM(B46:G46) -> 32 | J46: PLAQUETAS | K46: 5 | L46: 4 | M46: 0 | N46: 0 | O46: 0 | P46: 0 | Q46: =SUM(K46:P46) -> 9
...

Sheet MAYO
A4: Establecimiento de Salud informante: | B4: HOSPITAL REGIONAL DE LORETO | K4: Mes: | L4: MAYO
A6: Código Renaes: | B6: 3 | K6: Año: | L6: 2025
A9: PATOLOGÍA CLÍNICA | B9: TOTAL | J9: ANATOMÍA PATOLÓGICA | K9: TOTAL
B10: Hospitaliz | C10: Emergenc | D10: C. Externa | E10: Privado | F10: Convenio | G10: Insolvencia | H10: TOTAL | K10: Hospitaliz | L10: Emergenc | M10: C. Externa | N10: Privado | O10: Convenio | P10: Insolvencia | Q10: TOTAL
A11: TOTAL DE EXAMENES LABORATORIO | B11: =B12+B51+B69+B82+B95 -> 13313 | C11: =C12+C51+C69+C82+C95 -> 17733 | D11: =D12+D51+D69+D82+D95 -> 13544 | E11: =E12+E51+E69+E82+E95 -> 760 | F11: =F12+F51+F69+F82+F95 -> 525 | G11: =G12+G51+G69+G82+G95 -> 7 | H11: =SUM(B11:G11) -> 45882 | J11: TOTAL EXAMENES ANATOMIA PATOLOGICA | K11: =SUM(K12:K23) -> 664 | L11: =SUM(L12:L23) -> 0 | M11: =SUM(M12:M23) -> 879 | N11: =SUM(N12:N23) -> 4 | O11: =SUM(O12:O23) -> 1 | P11: =SUM(P12:P23) -> 0 | Q11: =SUM(K11:P11) -> 1548
A12: TOTAL EXAMENES BIOQUÍMICOS | B12: =SUM(B13:B50) -> 8810 | C12: =SUM(C13:C50) -> 11473 | D12: =SUM(D13:D50) -> 8363 | E12: =SUM(E13:E50) -> 466 | F12: =SUM(F13:F50) -> 372 | G12: =SUM(G13:G50) -> 0 | H12: =SUM(B12:G12) -> 29484 | J12: TOTAL EXAMENES CITOLÓGICOS (PAP) | K12: 0 | L12: 0 | M12: 41 | N12: 3 | O12: 0 | P12: 0 | Q12: =SUM(K12:P12) -> 44
A13: ACIDO URICO | B13: 31 | C13: 0 | D13: 58 | E13: 2 | F13: 4 | G13: 0 | H13: =SUM(B13:G13) -> 95 | J13: TOTAL BAAF | K13: 0 | L13: 0 | M13: 5 | N13: 0 | O13: 0 | P13: 0 | Q13: =SUM(K13:P13) -> 5
A14: CALCIO | B14: 41 | C14: 1 | D14: 26 | E14: 1 | F14: 2 | G14: 0 | H14: =SUM(B14:G14) -> 71 | J14: TOTAL EXAMENES HISTOPATOLÓGICOS (Biopsia) | K14: 11 | L14: 0 | M14: 61 | N14: 1 | O14: 1 | P14: 0 | Q14: =SUM(K14:P14) -> 74
A15: AMILASA | B15: 65 | C15: 129 | D15: 15 | E15: 6 | F15: 1 | G15: 0 | H15: =SUM(B15:G15) -> 216 | J15: TOTAL PIEZA QUIRURGICA (HISTOLOGIA) | K15: 48 | L15: 0 | M15: 41 | N15: 0 | O15: 0 | P15: 0 | Q15: =SUM(K15:P15) -> 89
A16: GLUCOSA | B16: 733 | C16: 1572 | D16: 911 | E16: 66 | F16: 36 | G16: 0 | H16: =SUM(B16:G16) -> 3318 | J16: TOTAL CITOLOGIA ESPECIAL | K16: 5 | L16: 0 | M16: 0 | N16: 0 | O16: 0 | P16: 0 | Q16: =SUM(K16:P16) -> 5
A17: GLUCOSA POST PRANDIAL | B17: 0 | C17: 0 | D17: 13 | E17: 0 | F17: 1 | G17: 0 | H17: =SUM(B17:G17) -> 14 | J17: TOTAL DE TEJIDOS INCLUIDOS | K17: 200 | L17: 0 | M17: 239 | N17: 0 | O17: 0 | P17: 0 | Q17: =SUM(K17:P17) -> 439
A18: FOSFORO | B18: 23 | C18: 0 | D18: 19 | E18: 0 | F18: 1 | G18: 0 | H18: =SUM(B18:G18) -> 43 | J18: TOTAL DE CORTES DE TEJIDOS | K18: 200 | L18: 0 | M18: 243 | N18: 0 | O18: 0 | P18: 0 | Q18: =SUM(K18:P18) -> 443
A19: HEMOGLOBINA GLICOSILADA | B19: 97 | C19: 43 | D19: 195 | E19: 8 | F19: 7 | G19: 0 | H19: =SUM(B19:G19) -> 350 | J19: TOTAL DE LÁMINAS MONTADAS | K19: 200 | L19: 0 | M19: 243 | N19: 0 | O19: 0 | P19: 0 | Q19: =SUM(K19:P19) -> 443
A20: TOLERANCIA A LA GLUCOSA | B20: 0 | C20: 0 | D20: 31 | E20: 2 | F20: 4 | G20: 0 | H20: =SUM(B20:G20) -> 37 | J20: TOTAL DE HISTOQUIMICA | K20: 0 | L20: 0 | M20: 6 | N20: 0 | O20: 0 | P20: 0 | Q20: =SUM(K20:P20) -> 6
A21: CREATININA | B21: 918 | C21: 1598 | D21: 912 | E21: 62 | F21: 40 | G21: 0 | H21: =SUM(B21:G21) -> 3530
A22: DEPURACION DE CREATININA | B22: 1 | C22: 0 | D22: 15 | E22: 0 | F22: 1 | G22: 0 | H22: =SUM(B22:G22) -> 17 | J22: TOTAL AUTOPSIA MÉDICO LEGAL | K22: 0 | L22: 0 | M22: 0 | N22: 0 | O22: 0 | P22: 0 | Q22: =SUM(K22:P22) -> 0
A23: MICROALBUMINURIA | B23: 0 | C23: 0 | D23: 48 | E23: 0 | F23: 1 | G23: 0 | H23: =SUM(B23:G23) -> 49 | J23: TOTAL AUTOPSIA CLÍNICA | K23: 0 | L23: 0 | M23: 0 | N23: 0 | O23: 0 | P23: 0 | Q23: =SUM(K23:P23) -> 0
A24: UREA | B24: 918 | C24: 1600 | D24: 908 | E24: 61 | F24: 40 | G24: 0 | H24: =SUM(B24:G24) -> 3527
A25: PROTEINURIA 24 HORAS | B25: 28 | C25: 1 | D25: 45 | E25: 0 | F25: 1 | G25: 0 | H25: =SUM(B25:G25) -> 75
A26: BILIRRUBINA TOTAL | B26: 591 | C26: 540 | D26: 410 | E26: 15 | F26: 19 | G26: 0 | H26: =SUM(B26:G26) -> 1575 | J26: PROGRAMAS / METAXENICAS | K26: TOTAL
A27: BILIRRUBINA DIRECTA | B27: 591 | C27: 540 | D27: 410 | E27: 15 | F27: 19 | G27: 0 | H27: =SUM(B27:G27) -> 1575 | K27: Hospitaliz | L27: Emergenc | M27: Programa | N27: Privado | O27: Convenio | P27: Insolvencia | Q27: TOTAL
A28: PROTEINAS TOTAL | B28: 632 | C28: 600 | D28: 486 | E28: 23 | F28: 24 | G28: 0 | H28: =SUM(B28:G28) -> 1765 | J28: TOTAL DE EXAMENES | K28: =SUM(K29:K37) -> 89 | L28: =SUM(L29:L37) -> 409 | M28: =SUM(M29:M37) -> 340 | N28: =SUM(N29:N37) -> 0 | O28: =SUM(O29:O37) -> 0 | P28: =SUM(P29:P37) -> 0 | Q28: =SUM(K28:P28) -> 838
A29: ALBUMINA | B29: 633 | C29: 600 | D29: 486 | E29: 8 | F29: 24 | G29: 0 | H29: =SUM(B29:G29) -> 1751 | J29: TUBERCULOSIS | K29: 73 | L29: 23 | M29: 57 | N29: 0 | O29: 0 | P29: 0 | Q29: =SUM(K29:P29) -> 153
A30: TGO | B30: 561 | C30: 599 | D30: 633 | E30: 34 | F30: 31 | G30: 0 | H30: =SUM(B30:G30) -> 1858 | J30: LEISHMANIA | K30: 1 | L30: 0 | M30: 1 | N30: 0 | O30: 0 | P30: 0 | Q30: =SUM(K30:P30) -> 2
A31: TGP | B31: 561 | C31: 599 | D31: 633 | E31: 34 | F31: 31 | G31: 0 | H31: =SUM(B31:G31) -> 1858 | J31: PROGRAMA LEPRAE | K31: 0 | L31: 0 | M31: 12 | N31: 0 | O31: 0 | P31: 0 | Q31: =SUM(K31:P31) -> 12
A32: GGTP | B32: 0 | C32: 1 | D32: 4 | E32: 0 | F32: 2 | G32: 0 | H32: =SUM(B32:G32) -> 7 | J32: MALARIA | K32: 15 | L32: 275 | M32: 30 | N32: 0 | O32: 0 | P32: 0 | Q32: =SUM(K32:P32) -> 320
A33: LACTATO DESHIDROGENASA (DHL) | B33: 276 | C33: 154 | D33: 80 | E33: 0 | F33: 6 | G33: 0 | H33: =SUM(B33:G33) -> 516 | J33: METAXENICAS (REFERENCIAL) | K33: 0 | L33: 0 | M33: 203 | N33: 0 | O33: 0 | P33: 0 | Q33: =SUM(K33:P33) -> 203
A34: PROTEINA C REACTIVA (CUANTITATIVO) | B34: 606 | C34: 911 | D34: 149 | E34: 33 | F34: 5 | G34: 0 | H34: =SUM(B34:G34) -> 1704 | J34: CULTIVO DE TB (REFERENCIAL) | K34: 0 | L34: 0 | M34: 35 | N34: 0 | O34: 0 | P34: 0 | Q34: =SUM(K34:P34) -> 35
A35: FOSFATASA ALCALINA | B35: 410 | C35: 334 | D35: 380 | E35: 16 | F35: 15 | G35: 0 | H35: =SUM(B35:G35) -> 1155 | J35: PRUEBA RAPIDA DE DENGUE | K35: 0 | L35: 109 | N35: 0 | O35: 0 | P35: 0 | Q35: =SUM(K35:P35) -> 109
A36: CPK TOTAL | B36: 0 | C36: 0 | D36: 0 | E36: 0 | F36: 0 | G36: 0 | H36: =SUM(B36:G36) -> 0 | J36: PRUEBA RAPIDA DE LEPTOSPIRA | K36: 0 | L36: 2 | M36: 2 | N36: 0 | O36: 0 | P36: 0 | Q36: =SUM(K36:P36) -> 4
A37: CPK MB | B37: 27 | C37: 23 | D37: 5 | E37: 0 | F37: 0 | G37: 0 | H37: =SUM(B37:G37) -> 55 | J37: PRUEBA RAPIDA DE COVID | K37: 0 | L37: 0 | M37: 0 | N37: 0 | O37: 0 | P37: 0 | Q37: =SUM(K37:P37) -> 0
A38: COLESTEROL | B38: 111 | C38: 51 | D38: 331 | E38: 17 | F38: 15 | G38: 0 | H38: =SUM(B38:G38) -> 525
A39: TRIGLICERIDOS | B39: 118 | C39: 50 | D39: 333 | E39: 17 | F39: 6 | G39: 0 | H39: =SUM(B39:G39) -> 524 | J39: BANCO DE SANGRE | K39: TOTAL
A40: HDLc | B40: 68 | C40: 0 | D40: 239 | E40: 8 | F40: 11 | G40: 0 | H40: =SUM(B40:G40) -> 326 | K40: Hospitaliz | L40: Emergenc | M40: C. Externa | N40: Privado | O40: Convenio | P40: Insolvencia | Q40: TOTAL
A41: LDLc | B41: 68 | C41: 0 | D41: 251 | E41: 7 | F41: 11 | G41: 0 | H41: =SUM(B41:G41) -> 337 | J41: TOTAL DE UNIDADES ENTREGADAS | K41: =SUM(K42:K49) -> 882 | L41: =SUM(L42:L49) -> 306 | M41: =SUM(M42:M49) -> 0 | N41: =SUM(N42:N49) -> 3 | O41: =SUM(O42:O49) -> 0 | P41: =SUM(P42:P49) -> 0 | Q41: =SUM(K41:P41) -> 1191
A42: ASO | B42: 6 | C42: 0 | D42: 3 | E42: 0 | F42: 0 | G42: 0 | H42: =SUM(B42:G42) -> 9 | J42: SANGRE TOTAL | K42: 0 | L42: 0 | M42: 0 | N42: 0 | O42: 0 | P42: 0 | Q42: =SUM(K42:P42) -> 0
A43: FACTOR REUMATOIDEO | B43: 12 | C43: 3 | D43: 34 | E43: 1 | F43: 1 | G43: 0 | H43: =SUM(B43:G43) -> 51 | J43: GLOBULOS ROJOS | K43: 212 | L43: 89 | M43: 0 | N43: 1 | O43: 0 | P43: 0 | Q43: =SUM(K43:P43) -> 302
A44: HIERRO | B44: 22 | C44: 0 | D44: 53 | E44: 0 | F44: 2 | G44: 0 | H44: =SUM(B44:G44) -> 77 | J44: PLASMA FRESCO CONGELADO | K44: 32 | L44: 4 | M44: 0 | N44: 0 | O44: 0 | P44: 0 | Q44: =SUM(K44:P44) -> 36
A45: LIPASA | B45: 73 | C45: 127 | D45: 21 | E45: 4 | F45: 1 | G45: 0 | H45: =SUM(B45:G45) -> 226 | J45: CRIOPRECIPITADO | K45: 14 | L45: 0 | M45: 0 | N45: 0 | O45: 0 | P45: 0 | Q45: =SUM(K45:P45) -> 14
A46: TRANSFERRINA | B46: 16 | C46: 0 | D46: 47 | E46: 0 | F46: 1 | G46: 0 | H46: =SUM(B46:G46) -> 64 | J46: PLAQUETAS | K46: 74 | L46: 5 | M46: 0 | N46: 0 | O46: 0 | P46: 0 | Q46: =SUM(K46:P46) -> 79
...

Sheet JUN
A4: Establecimiento de Salud informante: | B4: HOSPITAL REGIONAL DE LORETO | K4: Mes: | L4: JUNIO
A6: Código Renaes: | B6: 3 | K6: Año: | L6: 2025
A9: PATOLOGÍA CLÍNICA | B9: TOTAL | J9: ANATOMÍA PATOLÓGICA | K9: TOTAL
B10: Hospitaliz | C10: Emergenc | D10: C. Externa | E10: Privado | F10: Convenio | G10: Insolvencia | H10: TOTAL | K10: Hospitaliz | L10: Emergenc | M10: C. Externa | N10: Privado | O10: Convenio | P10: Insolvencia | Q10: TOTAL
A11: TOTAL DE EXAMENES LABORATORIO | B11: =B12+B51+B69+B82+B95 -> 12318 | C11: =C12+C51+C69+C82+C95 -> 18362 | D11: =D12+D51+D69+D82+D95 -> 13863 | E11: =E12+E51+E69+E82+E95 -> 803 | F11: =F12+F51+F69+F82+F95 -> 544 | G11: =G12+G51+G69+G82+G95 -> 34 | H11: =SUM(B11:G11) -> 45924 | J11: TOTAL EXAMENES ANATOMIA PATOLOGICA | K11: =SUM(K12:K23) -> 657 | L11: =SUM(L12:L23) -> 0 | M11: =SUM(M12:M23) -> 1183 | N11: =SUM(N12:N23) -> 3 | O11: =SUM(O12:O23) -> 6 | P11: =SUM(P12:P23) -> 0 | Q11: =SUM(K11:P11) -> 1849
A12: TOTAL EXAMENES BIOQUÍMICOS | B12: =SUM(B13:B50) -> 8256 | C12: =SUM(C13:C50) -> 11594 | D12: =SUM(D13:D50) -> 7750 | E12: =SUM(E13:E50) -> 481 | F12: =SUM(F13:F50) -> 386 | G12: =SUM(G13:G50) -> 31 | H12: =SUM(B12:G12) -> 28498 | J12: TOTAL EXAMENES CITOLÓGICOS (PAP) | K12: 0 | L12: 0 | M12: 26 | N12: 1 | O12: 0 | P12: 0 | Q12: =SUM(K12:P12) -> 27
A13: ACIDO URICO | B13: 18 | C13: 1 | D13: 52 | E13: 1 | F13: 0 | G13: 0 | H13: =SUM(B13:G13) -> 72 | J13: TOTAL BAAF | K13: 0 | L13: 0 | M13: 1 | N13: 0 | O13: 0 | P13: 0 | Q13: =SUM(K13:P13) -> 1
A14: CALCIO | B14: 30 | C14: 2 | D14: 80 | E14: 1 | F14: 0 | G14: 0 | H14: =SUM(B14:G14) -> 113 | J14: TOTAL EXAMENES HISTOPATOLÓGICOS (Biopsia) | K14: 1 | L14: 0 | M14: 70 | N14: 2 | O14: 6 | P14: 0 | Q14: =SUM(K14:P14) -> 79
A15: AMILASA | B15: 61 | C15: 129 | D15: 17 | E15: 4 | F15: 0 | G15: 0 | H15: =SUM(B15:G15) -> 211 | J15: TOTAL PIEZA QUIRURGICA (HISTOLOGIA) | K15: 46 | L15: 0 | M15: 36 | N15: 0 | O15: 0 | P15: 0 | Q15: =SUM(K15:P15) -> 82
A16: GLUCOSA | B16: 762 | C16: 1572 | D16: 868 | E16: 75 | F16: 60 | G16: 3 | H16: =SUM(B16:G16) -> 3340 | J16: TOTAL CITOLOGIA ESPECIAL | K16: 10 | L16: 0 | M16: 0 | N16: 0 | O16: 0 | P16: 0 | Q16: =SUM(K16:P16) -> 10
A17: GLUCOSA POST PRANDIAL | B17: 0 | C17: 0 | D17: 8 | E17: 2 | F17: 0 | G17: 0 | H17: =SUM(B17:G17) -> 10 | J17: TOTAL DE TEJIDOS INCLUIDOS | K17: 200 | L17: 0 | M17: 338 | N17: 0 | O17: 0 | P17: 0 | Q17: =SUM(K17:P17) -> 538
A18: FOSFORO | B18: 4 | C18: 0 | D18: 55 | E18: 0 | F18: 0 | G18: 0 | H18: =SUM(B18:G18) -> 59 | J18: TOTAL DE CORTES DE TEJIDOS | K18: 200 | L18: 0 | M18: 348 | N18: 0 | O18: 0 | P18: 0 | Q18: =SUM(K18:P18) -> 548
A19: HEMOGLOBINA GLICOSILADA | B19: 93 | C19: 35 | D19: 175 | E19: 10 | F19: 14 | G19: 0 | H19: =SUM(B19:G19) -> 327 | J19: TOTAL DE LÁMINAS MONTADAS | K19: 200 | L19: 0 | M19: 348 | N19: 0 | O19: 0 | P19: 0 | Q19: =SUM(K19:P19) -> 548
A20: TOLERANCIA A LA GLUCOSA | B20: 0 | C20: 0 | D20: 26 | E20: 0 | F20: 0 | G20: 2 | H20: =SUM(B20:G20) -> 28 | J20: TOTAL DE HISTOQUIMICA | K20: 0 | L20: 0 | M20: 4 | N20: 0 | O20: 0 | P20: 0 | Q20: =SUM(K20:P20) -> 4
A21: CREATININA | B21: 758 | C21: 1598 | D21: 845 | E21: 73 | F21: 46 | G21: 1 | H21: =SUM(B21:G21) -> 3321 | J21: TOTAL DE INMUNOHISTOQUIMICA | K21: 0 | L21: 0 | M21: 12 | N21: 0 | O21: 0 | P21: 0 | Q21: =SUM(K21:P21) -> 12
A22: DEPURACION DE CREATININA | B22: 1 | C22: 0 | D22: 6 | E22: 0 | F22: 0 | G22: 0 | H22: =SUM(B22:G22) -> 7 | J22: TOTAL AUTOPSIA MÉDICO LEGAL | K22: 0 | L22: 0 | M22: 0 | N22: 0 | O22: 0 | P22: 0 | Q22: =SUM(K22:P22) -> 0
A23: MICROALBUMINURIA | B23: 2 | C23: 0 | D23: 26 | E23: 0 | F23: 10 | G23: 0 | H23: =SUM(B23:G23) -> 38 | J23: TOTAL AUTOPSIA CLÍNICA | K23: 0 | L23: 0 | M23: 0 | N23: 0 | O23: 0 | P23: 0 | Q23: =SUM(K23:P23) -> 0
A24: UREA | B24: 795 | C24: 1600 | D24: 849 | E24: 70 | F24: 15 | G24: 1 | H24: =SUM(B24:G24) -> 3330
A25: PROTEINURIA 24 HORAS | B25: 23 | C25: 4 | D25: 27 | E25: 0 | F25: 3 | G25: 0 | H25: =SUM(B25:G25) -> 57
A26: BILIRRUBINA TOTAL | B26: 574 | C26: 540 | D26: 441 | E26: 16 | F26: 8 | G26: 2 | H26: =SUM(B26:G26) -> 1581 | J26: PROGRAMAS / METAXENICAS | K26: TOTAL
A27: BILIRRUBINA DIRECTA | B27: 574 | C27: 540 | D27: 441 | E27: 16 | F27: 8 | G27: 2 | H27: =SUM(B27:G27) -> 1581 | K27: Hospitaliz | L27: Emergenc | M27: Programa | N27: Privado | O27: Convenio | P27: Insolvencia | Q27: TOTAL
A28: PROTEINAS TOTAL | B28: 544 | C28: 600 | D28: 440 | E28: 8 | F28: 11 | G28: 3 | H28: =SUM(B28:G28) -> 1606 | J28: TOTAL DE EXAMENES | K28: =SUM(K29:K37) -> 97 | L28: =SUM(L29:L37) -> 380 | M28: =SUM(M29:M37) -> 122 | N28: =SUM(N29:N37) -> 0 | O28: =SUM(O29:O37) -> 0 | P28: =SUM(P29:P37) -> 0 | Q28: =SUM(K28:P28) -> 599
A29: ALBUMINA | B29: 524 | C29: 600 | D29: 440 | E29: 8 | F29: 11 | G29: 3 | H29: =SUM(B29:G29) -> 1586 | J29: TUBERCULOSIS | K29: 89 | L29: 7 | M29: 95 | N29: 0 | O29: 0 | P29: 0 | Q29: =SUM(K29:P29) -> 191
A30: TGO | B30: 536 | C30: 599 | D30: 600 | E30: 34 | F30: 51 | G30: 3 | H30: =SUM(B30:G30) -> 1823 | J30: LEISHMANIA | K30: 0 | L30: 0 | M30: 1 | N30: 0 | O30: 0 | P30: 0 | Q30: =SUM(K30:P30) -> 1
A31: TGP | B31: 536 | C31: 599 | D31: 600 | E31: 34 | F31: 51 | G31: 3 | H31: =SUM(B31:G31) -> 1823 | J31: PROGRAMA LEPRAE | K31: 0 | L31: 0 | M31: 0 | N31: 0 | O31: 0 | P31: 0 | Q31: =SUM(K31:P31) -> 0
A32: GGTP | B32: 15 | C32: 0 | D32: 12 | E32: 0 | F32: 0 | G32: 0 | H32: =SUM(B32:G32) -> 27 | J32: MALARIA | K32: 6 | L32: 202 | M32: 26 | N32: 0 | O32: 0 | P32: 0 | Q32: =SUM(K32:P32) -> 234
A33: LACTATO DESHIDROGENASA (DHL) | B33: 260 | C33: 154 | D33: 58 | E33: 1 | F33: 1 | G33: 0 | H33: =SUM(B33:G33) -> 474 | J33: METAXENICAS (REFERENCIAL) | K33: 0 | L33: 97 | M33: 0 | N33: 0 | O33: 0 | P33: 0 | Q33: =SUM(K33:P33) -> 97
A34: PROTEINA C REACTIVA (CUANTITATIVO) | B34: 694 | C34: 911 | D34: 95 | E34: 29 | F34: 2 | G34: 2 | H34: =SUM(B34:G34) -> 1733 | J34: CULTIVO DE TB (REFERENCIAL) | K34: 0 | L34: 19 | M34: 0 | N34: 0 | O34: 0 | P34: 0 | Q34: =SUM(K34:P34) -> 19
A35: FOSFATASA ALCALINA | B35: 380 | C35: 334 | D35: 375 | E35: 13 | F35: 4 | G35: 0 | H35: =SUM(B35:G35) -> 1106 | J35: PRUEBA RAPIDA DE DENGUE | K35: 1 | L35: 55 | M35: 0 | N35: 0 | O35: 0 | P35: 0 | Q35: =SUM(K35:P35) -> 56
A36: CPK TOTAL | B36: 0 | C36: 0 | D36: 0 | E36: 0 | F36: 0 | G36: 0 | H36: =SUM(B36:G36) -> 0 | J36: PRUEBA RAPIDA DE LEPTOSPIRA | K36: 1 | L36: 0 | M36: 0 | N36: 0 | O36: 0 | P36: 0 | Q36: =SUM(K36:P36) -> 1
A37: CPK MB | B37: 20 | C37: 16 | D37: 0 | E37: 0 | F37: 0 | G37: 0 | H37: =SUM(B37:G37) -> 36 | J37: PRUEBA RAPIDA DE COVID | K37: 0 | L37: 0 | M37: 0 | N37: 0 | O37: 0 | P37: 0 | Q37: =SUM(K37:P37) -> 0
A38: COLESTEROL | B38: 133 | C38: 85 | D38: 289 | E38: 21 | F38: 43 | G38: 2 | H38: =SUM(B38:G38) -> 573
A39: TRIGLICERIDOS | B39: 133 | C39: 85 | D39: 286 | E39: 21 | F39: 46 | G39: 3 | H39: =SUM(B39:G39) -> 574 | J39: BANCO DE SANGRE | K39: TOTAL
A40: HDLc | B40: 76 | C40: 43 | D40: 218 | E40: 14 | F40: 1 | G40: 0 | H40: =SUM(B40:G40) -> 352 | K40: Hospitaliz | L40: Emergenc | M40: C. Externa | N40: Privado | O40: Convenio | P40: Insolvencia | Q40: TOTAL
A41: LDLc | B41: 76 | C41: 43 | D41: 218 | E41: 14 | F41: 1 | G41: 0 | H41: =SUM(B41:G41) -> 352 | J41: TOTAL DE UNIDADES ENTREGADAS | K41: =SUM(K42:K49) -> 725 | L41: =SUM(L42:L49) -> 177 | M41: =SUM(M42:M49) -> 0 | N41: =SUM(N42:N49) -> 0 | O41: =SUM(O42:O49) -> 2 | P41: =SUM(P42:P49) -> 0 | Q41: =SUM(K41:P41) -> 904
A42: ASO | B42: 6 | C42: 0 | D42: 3 | E42: 0 | F42: 0 | G42: 0 | H42: =SUM(B42:G42) -> 9 | J42: SANGRE TOTAL | K42: 1 | L42: 0 | M42: 0 | N42: 0 | O42: 0 | P42: 0 | Q42: =SUM(K42:P42) -> 1
A43: FACTOR REUMATOIDEO | B43: 17 | C43: 0 | D43: 40 | E43: 1 | F43: 0 | G43: 0 | H43: =SUM(B43:G43) -> 58 | J43: GLOBULOS ROJOS | K43: 177 | L43: 63 | M43: 0 | N43: 0 | O43: 1 | P43: 0 | Q43: =SUM(K43:P43) -> 241
A44: HIERRO | B44: 15 | C44: 0 | D44: 10 | E44: 0 | F44: 0 | G44: 0 | H44: =SUM(B44:G44) -> 25 | J44: PLASMA FRESCO CONGELADO | K44: 17 | L44: 4 | M44: 0 | N44: 0 | O44: 0 | P44: 0 | Q44: =SUM(K44:P44) -> 21
A45: LIPASA | B45: 59 | C45: 127 | D45: 19 | E45: 3 | F45: 0 | G45: 0 | H45: =SUM(B45:G45) -> 208 | J45: CRIOPRECIPITADO | K45: 2 | L45: 2 | M45: 0 | N45: 0 | O45: 0 | P45: 0 | Q45: =SUM(K45:P45) -> 4
A46: TRANSFERRINA | B46: 9 | C46: 0 | D46: 2 | E46: 0 | F46: 0 | G46: 0 | H46: =SUM(B46:G46) -> 11 | J46: PLAQUETAS | K46: 34 | L46: 4 | M46: 0 | N46: 0 | O46: 0 | P46: 0 | Q46: =SUM(K46:P46) -> 38
...

Sheet JUL
A4: Establecimiento de Salud informante: | B4: HOSPITAL REGIONAL DE LORETO | K4: Mes: | L4: JULIO
A6: Código Renaes: | B6: 3 | K6: Año: | L6: 2025
A9: PATOLOGÍA CLÍNICA | B9: TOTAL | J9: ANATOMÍA PATOLÓGICA | K9: TOTAL
B10: Hospitaliz | C10: Emergenc | D10: C. Externa | E10: Privado | F10: Convenio | G10: Insolvencia | H10: TOTAL | K10: Hospitaliz | L10: Emergenc | M10: C. Externa | N10: Privado | O10: Convenio | P10: Insolvencia | Q10: TOTAL
A11: TOTAL DE EXAMENES LABORATORIO | B11: =B12+B51+B69+B82+B95 -> 11572 | C11: =C12+C51+C69+C82+C95 -> 19834 | D11: =D12+D51+D69+D82+D95 -> 15677 | E11: =E12+E51+E69+E82+E95 -> 895 | F11: =F12+F51+F69+F82+F95 -> 67 | G11: =G12+G51+G69+G82+G95 -> 64 | H11: =SUM(B11:G11) -> 48109 | J11: TOTAL EXAMENES ANATOMIA PATOLOGICA | K11: =SUM(K12:K23) -> 1036 | L11: =SUM(L12:L23) -> 1 | M11: =SUM(M12:M23) -> 669 | N11: =SUM(N12:N23) -> 4 | O11: =SUM(O12:O23) -> 4 | P11: =SUM(P12:P23) -> 2 | Q11: =SUM(K11:P11) -> 1716
A12: TOTAL EXAMENES BIOQUÍMICOS | B12: =SUM(B13:B50) -> 8536 | C12: =SUM(C13:C50) -> 13112 | D12: =SUM(D13:D50) -> 9311 | E12: =SUM(E13:E50) -> 500 | F12: =SUM(F13:F50) -> 0 | G12: =SUM(G13:G50) -> 49 | H12: =SUM(B12:G12) -> 31508 | J12: TOTAL EXAMENES CITOLÓGICOS (PAP) | K12: 0 | L12: 0 | M12: 36 | N12: 2 | O12: 0 | P12: 2 | Q12: =SUM(K12:P12) -> 40
A13: ACIDO URICO | B13: 19 | C13: 10 | D13: 77 | E13: 3 | F13: 0 | G13: 1 | H13: =SUM(B13:G13) -> 110 | J13: TOTAL BAAF | K13: 0 | L13: 0 | M13: 1 | N13: 0 | O13: 0 | P13: 0 | Q13: =SUM(K13:P13) -> 1
A14: CALCIO | B14: 58 | C14: 0 | D14: 46 | E14: 2 | F14: 0 | G14: 0 | H14: =SUM(B14:G14) -> 106 | J14: TOTAL EXAMENES HISTOPATOLÓGICOS (Biopsia) | K14: 91 | L14: 0 | M14: 30 | N14: 2 | O14: 4 | P14: 0 | Q14: =SUM(K14:P14) -> 127
A15: AMILASA | B15: 50 | C15: 149 | D15: 266 | E15: 3 | F15: 0 | G15: 0 | H15: =SUM(B15:G15) -> 468 | J15: TOTAL PIEZA QUIRURGICA (HISTOLOGIA) | K15: 64 | L15: 0 | M15: 0 | N15: 0 | O15: 0 | P15: 0 | Q15: =SUM(K15:P15) -> 64
A16: GLUCOSA | B16: 741 | C16: 1661 | D16: 1037 | E16: 71 | F16: 0 | G16: 9 | H16: =SUM(B16:G16) -> 3519 | J16: TOTAL CITOLOGIA ESPECIAL | K16: 6 | L16: 1 | M16: 0 | N16: 0 | O16: 0 | P16: 0 | Q16: =SUM(K16:P16) -> 7
A17: GLUCOSA POST PRANDIAL | B17: 0 | C17: 0 | D17: 5 | E17: 0 | F17: 0 | G17: 0 | H17: =SUM(B17:G17) -> 5 | J17: TOTAL DE TEJIDOS INCLUIDOS | K17: 289 | L17: 0 | M17: 200 | N17: 0 | O17: 0 | P17: 0 | Q17: =SUM(K17:P17) -> 489
A18: FOSFORO | B18: 18 | C18: 0 | D18: 18 | E18: 1 | F18: 0 | G18: 0 | H18: =SUM(B18:G18) -> 37 | J18: TOTAL DE CORTES DE TEJIDOS | K18: 292 | L18: 0 | M18: 200 | N18: 0 | O18: 0 | P18: 0 | Q18: =SUM(K18:P18) -> 492
A19: HEMOGLOBINA GLICOSILADA | B19: 101 | C19: 40 | D19: 221 | E19: 10 | F19: 0 | G19: 1 | H19: =SUM(B19:G19) -> 373 | J19: TOTAL DE LÁMINAS MONTADAS | K19: 292 | L19: 0 | M19: 200 | N19: 0 | O19: 0 | P19: 0 | Q19: =SUM(K19:P19) -> 492
A20: TOLERANCIA A LA GLUCOSA | B20: 1 | C20: 0 | D20: 18 | E20: 1 | F20: 0 | G20: 2 | H20: =SUM(B20:G20) -> 22 | J20: TOTAL DE HISTOQUIMICA | K20: 2 | L20: 0 | M20: 2 | N20: 0 | O20: 0 | P20: 0 | Q20: =SUM(K20:P20) -> 4
A21: CREATININA | B21: 802 | C21: 1596 | D21: 1036 | E21: 72 | F21: 0 | G21: 7 | H21: =SUM(B21:G21) -> 3513 | J21: TOTAL DE INMUNOHISTOQUIMICA | K21: 0 | L21: 0 | M21: 0 | N21: 0 | O21: 0 | P21: 0 | Q21: =SUM(K21:P21) -> 0
A22: DEPURACION DE CREATININA | B22: 0 | C22: 0 | D22: 7 | E22: 0 | F22: 0 | G22: 0 | H22: =SUM(B22:G22) -> 7 | J22: TOTAL AUTOPSIA MÉDICO LEGAL | K22: 0 | L22: 0 | M22: 0 | N22: 0 | O22: 0 | P22: 0 | Q22: =SUM(K22:P22) -> 0
A23: MICROALBUMINURIA | B23: 0 | C23: 0 | D23: 18 | E23: 0 | F23: 0 | G23: 1 | H23: =SUM(B23:G23) -> 19 | J23: TOTAL AUTOPSIA CLÍNICA | K23: 0 | L23: 0 | M23: 0 | N23: 0 | O23: 0 | P23: 0 | Q23: =SUM(K23:P23) -> 0
A24: UREA | B24: 798 | C24: 1596 | D24: 1023 | E24: 71 | F24: 0 | G24: 7 | H24: =SUM(B24:G24) -> 3495
A25: PROTEINURIA 24 HORAS | B25: 6 | C25: 4 | D25: 23 | E25: 0 | F25: 0 | G25: 0 | H25: =SUM(B25:G25) -> 33
A26: BILIRRUBINA TOTAL | B26: 661 | C26: 622 | D26: 484 | E26: 13 | F26: 0 | G26: 0 | H26: =SUM(B26:G26) -> 1780 | J26: PROGRAMAS / METAXENICAS | K26: TOTAL
A27: BILIRRUBINA DIRECTA | B27: 661 | C27: 622 | D27: 484 | E27: 13 | F27: 0 | G27: 0 | H27: =SUM(B27:G27) -> 1780 | K27: Hospitaliz | L27: Emergenc | M27: Programa | N27: Privado | O27: Convenio | P27: Insolvencia | Q27: TOTAL
A28: PROTEINAS TOTAL | B28: 527 | C28: 652 | D28: 551 | E28: 15 | F28: 0 | G28: 0 | H28: =SUM(B28:G28) -> 1745 | J28: TOTAL DE EXAMENES | K28: =SUM(K29:K37) -> 98 | L28: =SUM(L29:L37) -> 269 | M28: =SUM(M29:M37) -> 197 | N28: =SUM(N29:N37) -> 0 | O28: =SUM(O29:O37) -> 0 | P28: =SUM(P29:P37) -> 0 | Q28: =SUM(K28:P28) -> 564
A29: ALBUMINA | B29: 534 | C29: 652 | D29: 544 | E29: 6 | F29: 0 | G29: 0 | H29: =SUM(B29:G29) -> 1736 | J29: TUBERCULOSIS | K29: 64 | L29: 2 | M29: 72 | N29: 0 | O29: 0 | P29: 0 | Q29: =SUM(K29:P29) -> 138
A30: TGO | B30: 536 | C30: 703 | D30: 684 | E30: 40 | F30: 0 | G30: 4 | H30: =SUM(B30:G30) -> 1967 | J30: LEISHMANIA | K30: 0 | L30: 0 | M30: 1 | N30: 0 | O30: 0 | P30: 0 | Q30: =SUM(K30:P30) -> 1
A31: TGP | B31: 538 | C31: 709 | D31: 683 | E31: 40 | F31: 0 | G31: 4 | H31: =SUM(B31:G31) -> 1974 | J31: PROGRAMA LEPRAE | K31: 0 | L31: 0 | M31: 0 | N31: 0 | O31: 0 | P31: 0 | Q31: =SUM(K31:P31) -> 0
A32: GGTP | B32: 60 | D32: 10 | E32: 0 | F32: 0 | G32: 0 | H32: =SUM(B32:G32) -> 70 | J32: MALARIA | K32: 22 | L32: 202 | M32: 28 | N32: 0 | O32: 0 | P32: 0 | Q32: =SUM(K32:P32) -> 252
A33: LACTATO DESHIDROGENASA (DHL) | B33: 181 | C33: 117 | D33: 69 | E33: 3 | F33: 0 | G33: 0 | H33: =SUM(B33:G33) -> 370 | J33: METAXENICAS (REFERENCIAL) | K33: 0 | L33: 0 | M33: 86 | N33: 0 | O33: 0 | P33: 0 | Q33: =SUM(K33:P33) -> 86
A34: PROTEINA C REACTIVA (CUANTITATIVO) | B34: 812 | C34: 1351 | D34: 153 | E34: 30 | F34: 0 | G34: 1 | H34: =SUM(B34:G34) -> 2347 | J34: CULTIVO DE TB (REFERENCIAL) | K34: 0 | L34: 0 | M34: 10 | N34: 0 | O34: 0 | P34: 0 | Q34: =SUM(K34:P34) -> 10
A35: FOSFATASA ALCALINA | B35: 409 | C35: 429 | D35: 442 | E35: 12 | F35: 0 | G35: 1 | H35: =SUM(B35:G35) -> 1293 | J35: PRUEBA RAPIDA DE DENGUE | K35: 4 | L35: 50 | M35: 0 | N35: 0 | O35: 0 | P35: 0 | Q35: =SUM(K35:P35) -> 54
A36: CPK TOTAL | B36: 0 | C36: 0 | D36: 0 | E36: 0 | F36: 0 | G36: 0 | H36: =SUM(B36:G36) -> 0 | J36: PRUEBA RAPIDA DE LEPTOSPIRA | K36: 8 | L36: 15 | M36: 0 | N36: 0 | O36: 0 | P36: 0 | Q36: =SUM(K36:P36) -> 23
A37: CPK MB | B37: 6 | C37: 13 | D37: 3 | E37: 0 | F37: 0 | G37: 0 | H37: =SUM(B37:G37) -> 22 | J37: PRUEBA RAPIDA DE COVID | K37: 0 | L37: 0 | M37: 0 | N37: 0 | O37: 0 | P37: 0 | Q37: =SUM(K37:P37) -> 0
A38: COLESTEROL | B38: 127 | C38: 108 | D38: 341 | E38: 27 | F38: 0 | G38: 4 | H38: =SUM(B38:G38) -> 607
A39: TRIGLICERIDOS | B39: 127 | C39: 107 | D39: 343 | E39: 29 | F39: 0 | G39: 5 | H39: =SUM(B39:G39) -> 611 | J39: BANCO DE SANGRE | K39: TOTAL
A40: HDLc | B40: 87 | C40: 9 | D40: 238 | E40: 11 | F40: 0 | G40: 1 | H40: =SUM(B40:G40) -> 346 | K40: Hospitaliz | L40: Emergenc | M40: C. Externa | N40: Privado | O40: Convenio | P40: Insolvencia | Q40: TOTAL
A41: LDLc | B41: 87 | C41: 9 | D41: 238 | E41: 11 | F41: 0 | G41: 1 | H41: =SUM(B41:G41) -> 346 | J41: TOTAL DE UNIDADES ENTREGADAS | K41: =SUM(K42:K49) -> 705 | L41: =SUM(L42:L49) -> 279 | M41: =SUM(M42:M49) -> 7 | N41: =SUM(N42:N49) -> 4 | O41: =SUM(O42:O49) -> 0 | P41: =SUM(P42:P49) -> 0 | Q41: =SUM(K41:P41) -> 995
A42: ASO | B42: 3 | C42: 0 | D42: 3 | E42: 1 | F42: 0 | G42: 0 | H42: =SUM(B42:G42) -> 7 | J42: SANGRE TOTAL | K42: 0 | L42: 0 | M42: 0 | N42: 0 | O42: 0 | P42: 0 | Q42: =SUM(K42:P42) -> 0
A43: FACTOR REUMATOIDEO | B43: 14 | C43: 1 | D43: 53 | E43: 1 | F43: 0 | G43: 0 | H43: =SUM(B43:G43) -> 69 | J43: GLOBULOS ROJOS | K43: 197 | L43: 84 | M43: 2 | N43: 1 | O43: 0 | P43: 0 | Q43: =SUM(K43:P43) -> 284
A44: HIERRO | B44: 29 | C44: 0 | D44: 14 | E44: 0 | F44: 0 | G44: 0 | H44: =SUM(B44:G44) -> 43 | J44: PLASMA FRESCO CONGELADO | K44: 1 | L44: 1 | M44: 0 | N44: 0 | O44: 0 | P44: 0 | Q44: =SUM(K44:P44) -> 2
A45: LIPASA | B45: 47 | C45: 136 | D45: 28 | E45: 1 | F45: 0 | G45: 0 | H45: =SUM(B45:G45) -> 212 | J45: CRIOPRECIPITADO | K45: 11 | L45: 0 | M45: 0 | N45: 0 | O45: 0 | P45: 0 | Q45: =SUM(K45:P45) -> 11
A46: TRANSFERRINA | B46: 35 | C46: 0 | D46: 5 | E46: 0 | F46: 0 | G46: 0 | H46: =SUM(B46:G46) -> 40 | J46: PLAQUETAS | K46: 33 | L46: 4 | M46: 0 | N46: 0 | O46: 0 | P46: 0 | Q46: =SUM(K46:P46) -> 37
...

Sheet AGO
A4: Establecimiento de Salud informante: | B4: HOSPITAL REGIONAL DE LORETO | K4: Mes: | L4: AGOSTO
A6: Código Renaes: | B6: 3 | K6: Año: | L6: 2025
A9: PATOLOGÍA CLÍNICA | B9: TOTAL | J9: ANATOMÍA PATOLÓGICA | K9: TOTAL
B10: Hospitaliz | C10: Emergenc | D10: C. Externa | E10: Privado | F10: Convenio | G10: Insolvencia | H10: TOTAL | K10: Hospitaliz | L10: Emergenc | M10: C. Externa | N10: Privado | O10: Convenio | P10: Insolvencia | Q10: TOTAL
A11: TOTAL DE EXAMENES LABORATORIO | B11: =B12+B51+B69+B82+B95 -> 12248 | C11: =C12+C51+C69+C82+C95 -> 19208 | D11: =D12+D51+D69+D82+D95 -> 14521 | E11: =E12+E51+E69+E82+E95 -> 586 | F11: =F12+F51+F69+F82+F95 -> 608 | G11: =G12+G51+G69+G82+G95 -> 103 | H11: =SUM(B11:G11) -> 47274 | J11: TOTAL EXAMENES ANATOMIA PATOLOGICA | K11: =SUM(K12:K23) -> 804 | L11: =SUM(L12:L23) -> 0 | M11: =SUM(M12:M23) -> 868 | N11: =SUM(N12:N23) -> 7 | O11: =SUM(O12:O23) -> 2 | P11: =SUM(P12:P23) -> 0 | Q11: =SUM(K11:P11) -> 1681
A12: TOTAL EXAMENES BIOQUÍMICOS | B12: =SUM(B13:B50) -> 7654 | C12: =SUM(C13:C50) -> 12087 | D12: =SUM(D13:D50) -> 8596 | E12: =SUM(E13:E50) -> 347 | F12: =SUM(F13:F50) -> 412 | G12: =SUM(G13:G50) -> 34 | H12: =SUM(B12:G12) -> 29130 | J12: TOTAL EXAMENES CITOLÓGICOS (PAP) | K12: 1 | L12: 0 | M12: 36 | N12: 4 | O12: 0 | P12: 0 | Q12: =SUM(K12:P12) -> 41
A13: ACIDO URICO | B13: 43 | C13: 2 | D13: 83 | E13: 1 | F13: 9 | G13: 0 | H13: =SUM(B13:G13) -> 138 | J13: TOTAL BAAF | K13: 0 | L13: 0 | M13: 2 | N13: 0 | O13: 0 | P13: 0 | Q13: =SUM(K13:P13) -> 2
A14: CALCIO | B14: 46 | C14: 34 | D14: 49 | E14: 5 | F14: 5 | G14: 0 | H14: =SUM(B14:G14) -> 139 | J14: TOTAL EXAMENES HISTOPATOLÓGICOS (Biopsia) | K14: 3 | L14: 0 | M14: 91 | N14: 3 | O14: 2 | P14: 0 | Q14: =SUM(K14:P14) -> 99
